<?xml version="1.0" ?>
<!-- =================================================================================== -->
<!-- |    This document was autogenerated by xacro from dropbear_simplified_gz.urdf.xacro | -->
<!-- |    EDITING THIS FILE BY HAND IS NOT RECOMMENDED                                 | -->
<!-- =================================================================================== -->
<robot name="humanoid">
  <material name="silver_default">
    <color rgba="0.700 0.700 0.700 1.000"/>
  </material>
  <material name="opaque727161">
    <color rgba="0.2823529411764706 0.2784313725490196 0.23921568627450981 1.0"/>
  </material>
  <material name="opaque2550255">
    <color rgba="1.0 0.0 1.0 1.0"/>
  </material>
  <!-- Waist Material Color -->
  <material name="opaque245245245">
    <color rgba="0.9607843137254902 0.9607843137254902 0.9607843137254902 1.0"/>
  </material>
  <material name="opaque20400">
    <color rgba="0.8 0.0 0.0 1.0"/>
  </material>
  <material name="opaque2551530">
    <color rgba="1.0 0.6 0.0 1.0"/>
  </material>
  <!-- Leg Materials -->
  <material name="opaque22122113">
    <color rgba="0.8666666666666667 0.8666666666666667 0.050980392156862744 1.0"/>
  </material>
  <material name="opaque191191191">
    <color rgba="0.7490196078431373 0.7490196078431373 0.7490196078431373 1.0"/>
  </material>
  <material name="opaque252525">
    <color rgba="0.09803921568627451 0.09803921568627451 0.09803921568627451 1.0"/>
  </material>
  <material name="opaque0125168">
    <color rgba="0.0 0.49019607843137253 0.6588235294117647 1.0"/>
  </material>
  <material name="opaque2552550">
    <color rgba="1.0 1.0 0.0 1.0"/>
  </material>
  <material name="opaque13110895">
    <color rgba="0.5137254901960784 0.4235294117647059 0.37254901960784315 1.0"/>
  </material>
  <material name="powder_coat_green">
    <color rgba="0.26666666666666666 0.5882352941176471 0.2823529411764706 0.0"/>
  </material>
  <!-- Hand Materials -->
  <material name="opaque808080">
    <color rgba="0.3137254901960784 0.3137254901960784 0.3137254901960784 1.0"/>
  </material>
  <!-- Head Materials -->
  <material name="opaque25514347">
    <color rgba="1.0 0.5607843137254902 0.1843137254901961 1.0"/>
  </material>
  <!-- World Link -->
  <link name="world"/>
  <link name="torso">
    <inertial>
      <origin rpy="0 0 0" xyz="-0.03675640917673825 0.10469671997794947 0.060052559811593326"/>
      <mass value="3.2595669741313733"/>
      <inertia ixx="0.075048" ixy="0.004011" ixz="3.6e-05" iyy="0.064931" iyz="0.00017" izz="0.077575"/>
    </inertial>
    <visual>
      <origin rpy="0 0 0" xyz="0 0 0"/>
      <geometry>
        <mesh filename="package://dropbear_simplified_urdf/meshes/torso/base_link.stl" scale="0.001 0.001 0.001"/>
      </geometry>
      <material name="opaque727161"/>
    </visual>
    <collision>
      <origin rpy="0 0 0" xyz="0 0 0"/>
      <geometry>
        <mesh filename="package://dropbear_simplified_urdf/meshes/torso/base_link.stl" scale="0.001 0.001 0.001"/>
      </geometry>
    </collision>
  </link>
  <link name="battery">
    <inertial>
      <origin rpy="0 0 0" xyz="-0.014703908327839686 -0.0843541120647618 0.0899587845320941"/>
      <mass value="7.637162903287981"/>
      <inertia ixx="0.079683" ixy="-0.006221" ixz="3e-06" iyy="0.047453" iyz="1e-06" izz="0.063603"/>
    </inertial>
    <visual>
      <origin rpy="0 0 0" xyz="-0.011029 -0.026628 0.030271"/>
      <geometry>
        <mesh filename="package://dropbear_simplified_urdf/meshes/torso/HumanoidBatteryAssembly_Copy_v2_1.stl" scale="0.001 0.001 0.001"/>
      </geometry>
      <material name="opaque191191191"/>
    </visual>
    <collision>
      <origin rpy="0 0 0" xyz="-0.011029 -0.026628 0.030271"/>
      <geometry>
        <mesh filename="package://dropbear_simplified_urdf/meshes/torso/HumanoidBatteryAssembly_Copy_v2_1.stl" scale="0.001 0.001 0.001"/>
      </geometry>
    </collision>
  </link>
  <joint name="torso_battery_torso_connection" type="fixed">
    <origin rpy="0 0 0" xyz="0.011029 0.026628 -0.030271"/>
    <parent link="torso"/>
    <child link="battery"/>
  </joint>
  <!-- base_link to world joint -->
  <joint name="base_link_world_joint" type="fixed">
    <origin rpy="1.5707965 0.0 0.0" xyz="0.0 0.0 1.5"/>
    <parent link="world"/>
    <child link="torso"/>
  </joint>
  <link name="head_center-bracket2_1">
    <inertial>
      <origin rpy="0 0 0" xyz="3.8346437243874654e-05 0.028284627969764248 -0.09750810940579985"/>
      <mass value="0.9900409412989982"/>
      <inertia ixx="0.003998" ixy="0.0" ixz="2e-06" iyy="0.00721" iyz="2e-06" izz="0.004001"/>
    </inertial>
    <visual>
      <origin rpy="0 0 0" xyz="-0.283942 0.18654 -0.126791"/>
      <geometry>
        <mesh filename="package://dropbear_simplified_urdf/meshes/head/center-bracket2_1.stl" scale="0.001 0.001 0.001"/>
      </geometry>
      <material name="opaque22122113"/>
    </visual>
    <collision>
      <origin rpy="0 0 0" xyz="-0.283942 0.18654 -0.126791"/>
      <geometry>
        <mesh filename="package://dropbear_simplified_urdf/meshes/head/center-bracket2_1.stl" scale="0.001 0.001 0.001"/>
      </geometry>
    </collision>
  </link>
  <link name="head_5mm-ujoint-base__5__1">
    <inertial>
      <origin rpy="0 0 0" xyz="-3.06424356499857e-07 -0.0018028909754423672 -4.006902962760961e-07"/>
      <mass value="0.0019034168312865901"/>
      <inertia ixx="75.91e-09" ixy="0.0" ixz="-7.0e-09" iyy="71.51e-09" iyz="0.0" izz="82.56e-09"/>
    </inertial>
    <visual>
      <origin rpy="0 0 0" xyz="-0.308942 0.12754 -0.129291"/>
      <geometry>
        <mesh filename="package://dropbear_simplified_urdf/meshes/head/5mm-ujoint-base__5__1.stl" scale="0.001 0.001 0.001"/>
      </geometry>
      <material name="opaque191191191"/>
    </visual>
    <collision>
      <origin rpy="0 0 0" xyz="-0.308942 0.12754 -0.129291"/>
      <geometry>
        <mesh filename="package://dropbear_simplified_urdf/meshes/head/5mm-ujoint-base__5__1.stl" scale="0.001 0.001 0.001"/>
      </geometry>
    </collision>
  </link>
  <link name="head_5mm-ujoint-base__2__1">
    <inertial>
      <origin rpy="0 0 0" xyz="-2.8817588032525876e-07 -0.001802890975445226 -4.730412566378295e-07"/>
      <mass value="0.0019034168312865901"/>
      <inertia ixx="75.91e-09" ixy="0.0" ixz="-7.0e-09" iyy="71.51e-09" iyz="0.0" izz="82.56e-09"/>
    </inertial>
    <visual>
      <origin rpy="0 0 0" xyz="-0.258942 0.12754 -0.129291"/>
      <geometry>
        <mesh filename="package://dropbear_simplified_urdf/meshes/head/5mm-ujoint-base__2__1.stl" scale="0.001 0.001 0.001"/>
      </geometry>
      <material name="opaque191191191"/>
    </visual>
    <collision>
      <origin rpy="0 0 0" xyz="-0.258942 0.12754 -0.129291"/>
      <geometry>
        <mesh filename="package://dropbear_simplified_urdf/meshes/head/5mm-ujoint-base__2__1.stl" scale="0.001 0.001 0.001"/>
      </geometry>
    </collision>
  </link>
  <link name="head_5mm-ujoint-base__1__1">
    <inertial>
      <origin rpy="0 0 0" xyz="2.425383274773374e-07 -0.0018028909754462807 1.629635675003691e-07"/>
      <mass value="0.0019034168312865901"/>
      <inertia ixx="71.61e-09" ixy="0.0" ixz="1.427e-09" iyy="71.51e-09" iyz="0.0" izz="86.86e-09"/>
    </inertial>
    <visual>
      <origin rpy="0 0 0" xyz="-0.383044 0.12754 -0.000941"/>
      <geometry>
        <mesh filename="package://dropbear_simplified_urdf/meshes/head/5mm-ujoint-base__1__1.stl" scale="0.001 0.001 0.001"/>
      </geometry>
      <material name="opaque191191191"/>
    </visual>
    <collision>
      <origin rpy="0 0 0" xyz="-0.383044 0.12754 -0.000941"/>
      <geometry>
        <mesh filename="package://dropbear_simplified_urdf/meshes/head/5mm-ujoint-base__1__1.stl" scale="0.001 0.001 0.001"/>
      </geometry>
    </collision>
  </link>
  <link name="head_5mm-ujoint-base_1">
    <inertial>
      <origin rpy="0 0 0" xyz="2.168950684611204e-07 -0.0018028909754433942 -5.184531954444127e-08"/>
      <mass value="0.0019034168312865901"/>
      <inertia ixx="75.91e-09" ixy="0.0" ixz="-7.0e-09" iyy="71.51e-09" iyz="0.0" izz="82.56e-09"/>
    </inertial>
    <visual>
      <origin rpy="0 0 0" xyz="-0.358044 0.12754 0.04236"/>
      <geometry>
        <mesh filename="package://dropbear_simplified_urdf/meshes/head/5mm-ujoint-base_1.stl" scale="0.001 0.001 0.001"/>
      </geometry>
      <material name="opaque191191191"/>
    </visual>
    <collision>
      <origin rpy="0 0 0" xyz="-0.358044 0.12754 0.04236"/>
      <geometry>
        <mesh filename="package://dropbear_simplified_urdf/meshes/head/5mm-ujoint-base_1.stl" scale="0.001 0.001 0.001"/>
      </geometry>
    </collision>
  </link>
  <link name="head_5mm-ujoint-base__3__1">
    <inertial>
      <origin rpy="0 0 0" xyz="1.9223092723175128e-07 -0.0018028909754772282 -3.93148458163739e-08"/>
      <mass value="0.0019034168312865901"/>
      <inertia ixx="75.91e-09" ixy="0.0" ixz="-7.0e-09" iyy="71.51e-09" iyz="0.0" izz="82.56e-09"/>
    </inertial>
    <visual>
      <origin rpy="0 0 0" xyz="-0.209839 0.12754 0.04236"/>
      <geometry>
        <mesh filename="package://dropbear_simplified_urdf/meshes/head/5mm-ujoint-base__3__1.stl" scale="0.001 0.001 0.001"/>
      </geometry>
      <material name="opaque191191191"/>
    </visual>
    <collision>
      <origin rpy="0 0 0" xyz="-0.209839 0.12754 0.04236"/>
      <geometry>
        <mesh filename="package://dropbear_simplified_urdf/meshes/head/5mm-ujoint-base__3__1.stl" scale="0.001 0.001 0.001"/>
      </geometry>
    </collision>
  </link>
  <link name="head_5mm-ujoint-base__4__1">
    <inertial>
      <origin rpy="0 0 0" xyz="1.6798179230947952e-07 -0.0018028909754432276 1.620475144446928e-07"/>
      <mass value="0.0019034168312865901"/>
      <inertia ixx="71.61e-09" ixy="0.0" ixz="1.427e-09" iyy="71.51e-09" iyz="0.0" izz="86.86e-09"/>
    </inertial>
    <visual>
      <origin rpy="0 0 0" xyz="-0.184839 0.12754 -0.000941"/>
      <geometry>
        <mesh filename="package://dropbear_simplified_urdf/meshes/head/5mm-ujoint-base__4__1.stl" scale="0.001 0.001 0.001"/>
      </geometry>
      <material name="opaque191191191"/>
    </visual>
    <collision>
      <origin rpy="0 0 0" xyz="-0.184839 0.12754 -0.000941"/>
      <geometry>
        <mesh filename="package://dropbear_simplified_urdf/meshes/head/5mm-ujoint-base__4__1.stl" scale="0.001 0.001 0.001"/>
      </geometry>
    </collision>
  </link>
  <link name="head_u-joint-center__6__1">
    <inertial>
      <origin rpy="0 0 0" xyz="-0.004226364224141799 -3.831484210459202e-08 -0.002671317839583104"/>
      <mass value="0.0009727380393185158"/>
      <inertia ixx="14.27e-09" ixy="2.27e-10" ixz="-3.25e-10" iyy="19.21e-09" iyz="-1.34e-09" izz="16.13e-09"/>
    </inertial>
    <visual>
      <origin rpy="0 0 0" xyz="-0.313168 0.11854 -0.131962"/>
      <geometry>
        <mesh filename="package://dropbear_simplified_urdf/meshes/head/u-joint-center__6__1.stl" scale="0.001 0.001 0.001"/>
      </geometry>
      <material name="opaque191191191"/>
    </visual>
    <collision>
      <origin rpy="0 0 0" xyz="-0.313168 0.11854 -0.131962"/>
      <geometry>
        <mesh filename="package://dropbear_simplified_urdf/meshes/head/u-joint-center__6__1.stl" scale="0.001 0.001 0.001"/>
      </geometry>
    </collision>
  </link>
  <link name="head_leadscrew__4___1">
    <inertial>
      <origin rpy="0 0 0" xyz="0.008090913802082988 0.05478640097420695 -0.015967801610564242"/>
      <mass value="0.041870324726393286"/>
      <inertia ixx="3.6e-05" ixy="-7e-06" ixz="3e-06" iyy="8e-06" iyz="1.3e-05" izz="3.2e-05"/>
    </inertial>
    <visual>
      <origin rpy="0 0 0" xyz="-0.312784 0.122047 -0.123213"/>
      <geometry>
        <mesh filename="package://dropbear_simplified_urdf/meshes/head/leadscrew__4___1.stl" scale="0.001 0.001 0.001"/>
      </geometry>
      <material name="opaque191191191"/>
    </visual>
    <collision>
      <origin rpy="0 0 0" xyz="-0.312784 0.122047 -0.123213"/>
      <geometry>
        <mesh filename="package://dropbear_simplified_urdf/meshes/head/leadscrew__4___1.stl" scale="0.001 0.001 0.001"/>
      </geometry>
    </collision>
  </link>
  <link name="head_screw-reciever_1">
    <inertial>
      <origin rpy="0 0 0" xyz="0.007426461752526592 0.03190986660772625 -0.013718757939493342"/>
      <mass value="0.04298268184364639"/>
      <inertia ixx="5.2e-05" ixy="-1e-05" ixz="4e-06" iyy="1.2e-05" iyz="1.8e-05" izz="4.7e-05"/>
    </inertial>
    <visual>
      <origin rpy="0 0 0" xyz="-0.310823 0.110454 -0.125815"/>
      <geometry>
        <mesh filename="package://dropbear_simplified_urdf/meshes/head/screw-reciever_1.stl" scale="0.001 0.001 0.001"/>
      </geometry>
      <material name="opaque25514347"/>
    </visual>
    <collision>
      <origin rpy="0 0 0" xyz="-0.310823 0.110454 -0.125815"/>
      <geometry>
        <mesh filename="package://dropbear_simplified_urdf/meshes/head/screw-reciever_1.stl" scale="0.001 0.001 0.001"/>
      </geometry>
    </collision>
  </link>
  <link name="head_u-joint-center__1__1">
    <inertial>
      <origin rpy="0 0 0" xyz="-0.0049303029733915316 1.0162823491088879e-07 -0.0008343581172669257"/>
      <mass value="0.0009727380393185158"/>
      <inertia ixx="14.27e-09" ixy="2.27e-10" ixz="-3.25e-10" iyy="19.21e-09" iyz="-1.34e-09" izz="16.13e-09"/>
    </inertial>
    <visual>
      <origin rpy="0 0 0" xyz="-0.263872 0.11854 -0.130125"/>
      <geometry>
        <mesh filename="package://dropbear_simplified_urdf/meshes/head/u-joint-center__1__1.stl" scale="0.001 0.001 0.001"/>
      </geometry>
      <material name="opaque191191191"/>
    </visual>
    <collision>
      <origin rpy="0 0 0" xyz="-0.263872 0.11854 -0.130125"/>
      <geometry>
        <mesh filename="package://dropbear_simplified_urdf/meshes/head/u-joint-center__1__1.stl" scale="0.001 0.001 0.001"/>
      </geometry>
    </collision>
  </link>
  <link name="head_leadscrew__5___1__1">
    <inertial>
      <origin rpy="0 0 0" xyz="-0.010697780740818036 0.0484324768709017 -0.02935746116647918"/>
      <mass value="0.04187032472639328"/>
      <inertia ixx="3.6e-05" ixy="7e-06" ixz="-3e-06" iyy="8e-06" iyz="1.3e-05" izz="3.2e-05"/>
    </inertial>
    <visual>
      <origin rpy="0 0 0" xyz="-0.257696 0.115673 -0.136655"/>
      <geometry>
        <mesh filename="package://dropbear_simplified_urdf/meshes/head/leadscrew__5___1__1.stl" scale="0.001 0.001 0.001"/>
      </geometry>
      <material name="opaque191191191"/>
    </visual>
    <collision>
      <origin rpy="0 0 0" xyz="-0.257696 0.115673 -0.136655"/>
      <geometry>
        <mesh filename="package://dropbear_simplified_urdf/meshes/head/leadscrew__5___1__1.stl" scale="0.001 0.001 0.001"/>
      </geometry>
    </collision>
  </link>
  <link name="head_screw-reciever__4__1">
    <inertial>
      <origin rpy="0 0 0" xyz="-0.0074348154663718136 0.03193576048858819 -0.013691785153830918"/>
      <mass value="0.042982681843648216"/>
      <inertia ixx="5.2e-05" ixy="1e-05" ixz="-4e-06" iyy="1.2e-05" iyz="1.8e-05" izz="4.7e-05"/>
    </inertial>
    <visual>
      <origin rpy="0 0 0" xyz="-0.257058 0.110451 -0.125823"/>
      <geometry>
        <mesh filename="package://dropbear_simplified_urdf/meshes/head/screw-reciever__4__1.stl" scale="0.001 0.001 0.001"/>
      </geometry>
      <material name="opaque25514347"/>
    </visual>
    <collision>
      <origin rpy="0 0 0" xyz="-0.257058 0.110451 -0.125823"/>
      <geometry>
        <mesh filename="package://dropbear_simplified_urdf/meshes/head/screw-reciever__4__1.stl" scale="0.001 0.001 0.001"/>
      </geometry>
    </collision>
  </link>
  <link name="head_u-joint-center__3__1">
    <inertial>
      <origin rpy="0 0 0" xyz="-0.004978762007825044 -4.937069579546982e-08 0.00046206432615511966"/>
      <mass value="0.0009727380393185158"/>
      <inertia ixx="14.27e-09" ixy="2.27e-10" ixz="-3.25e-10" iyy="19.21e-09" iyz="-1.34e-09" izz="16.13e-09"/>
    </inertial>
    <visual>
      <origin rpy="0 0 0" xyz="-0.388023 0.11854 -0.000479"/>
      <geometry>
        <mesh filename="package://dropbear_simplified_urdf/meshes/head/u-joint-center__3__1.stl" scale="0.001 0.001 0.001"/>
      </geometry>
      <material name="opaque191191191"/>
    </visual>
    <collision>
      <origin rpy="0 0 0" xyz="-0.388023 0.11854 -0.000479"/>
      <geometry>
        <mesh filename="package://dropbear_simplified_urdf/meshes/head/u-joint-center__3__1.stl" scale="0.001 0.001 0.001"/>
      </geometry>
    </collision>
  </link>
  <link name="head_leadscrew__1___1__1">
    <inertial>
      <origin rpy="0 0 0" xyz="-0.012356712790251911 0.048365296241757866 0.028810741379527917"/>
      <mass value="0.04187032472639327"/>
      <inertia ixx="3.6e-05" ixy="8e-06" ixz="3e-06" iyy="8e-06" iyz="-1.2e-05" izz="3.2e-05"/>
    </inertial>
    <visual>
      <origin rpy="0 0 0" xyz="-0.382356 0.115621 0.006475"/>
      <geometry>
        <mesh filename="package://dropbear_simplified_urdf/meshes/head/leadscrew__1___1__1.stl" scale="0.001 0.001 0.001"/>
      </geometry>
      <material name="opaque191191191"/>
    </visual>
    <collision>
      <origin rpy="0 0 0" xyz="-0.382356 0.115621 0.006475"/>
      <geometry>
        <mesh filename="package://dropbear_simplified_urdf/meshes/head/leadscrew__1___1__1.stl" scale="0.001 0.001 0.001"/>
      </geometry>
    </collision>
  </link>
  <link name="head_screw-reciever__1__1">
    <inertial>
      <origin rpy="0 0 0" xyz="-0.008120661984091504 0.03192691679860454 0.013318601322868981"/>
      <mass value="0.04298268184364818"/>
      <inertia ixx="5.2e-05" ixy="1.1e-05" ixz="4e-06" iyy="1.2e-05" iyz="-1.8e-05" izz="4.7e-05"/>
    </inertial>
    <visual>
      <origin rpy="0 0 0" xyz="-0.380987 0.110454 -0.004315"/>
      <geometry>
        <mesh filename="package://dropbear_simplified_urdf/meshes/head/screw-reciever__1__1.stl" scale="0.001 0.001 0.001"/>
      </geometry>
      <material name="opaque25514347"/>
    </visual>
    <collision>
      <origin rpy="0 0 0" xyz="-0.380987 0.110454 -0.004315"/>
      <geometry>
        <mesh filename="package://dropbear_simplified_urdf/meshes/head/screw-reciever__1__1.stl" scale="0.001 0.001 0.001"/>
      </geometry>
    </collision>
  </link>
  <link name="head_u-joint-center__2__1">
    <inertial>
      <origin rpy="0 0 0" xyz="0.0018403789193226494 -4.1457359517549364e-08 0.004648879074007656"/>
      <mass value="0.0009727380393185158"/>
      <inertia ixx="14.27e-09" ixy="2.27e-10" ixz="-3.25e-10" iyy="19.21e-09" iyz="-1.34e-09" izz="16.13e-09"/>
    </inertial>
    <visual>
      <origin rpy="0 0 0" xyz="-0.356204 0.11854 0.047009"/>
      <geometry>
        <mesh filename="package://dropbear_simplified_urdf/meshes/head/u-joint-center__2__1.stl" scale="0.001 0.001 0.001"/>
      </geometry>
      <material name="opaque191191191"/>
    </visual>
    <collision>
      <origin rpy="0 0 0" xyz="-0.356204 0.11854 0.047009"/>
      <geometry>
        <mesh filename="package://dropbear_simplified_urdf/meshes/head/u-joint-center__2__1.stl" scale="0.001 0.001 0.001"/>
      </geometry>
    </collision>
  </link>
  <link name="head_leadscrew__0__1">
    <inertial>
      <origin rpy="0 0 0" xyz="-0.031857275970217425 0.047916784457887496 0.0033276778975500285"/>
      <mass value="0.04187032472639328"/>
      <inertia ixx="3e-05" ixy="1.5e-05" ixz="0.0" iyy="8e-06" iyz="0.0" izz="3.7e-05"/>
    </inertial>
    <visual>
      <origin rpy="0 0 0" xyz="-0.364802 0.115197 0.045036"/>
      <geometry>
        <mesh filename="package://dropbear_simplified_urdf/meshes/head/leadscrew__0__1.stl" scale="0.001 0.001 0.001"/>
      </geometry>
      <material name="opaque191191191"/>
    </visual>
    <collision>
      <origin rpy="0 0 0" xyz="-0.364802 0.115197 0.045036"/>
      <geometry>
        <mesh filename="package://dropbear_simplified_urdf/meshes/head/leadscrew__0__1.stl" scale="0.001 0.001 0.001"/>
      </geometry>
    </collision>
  </link>
  <link name="head_screw-reciever__2__1">
    <inertial>
      <origin rpy="0 0 0" xyz="-0.01561212278275853 0.03188457435312017 0.00040503058741351433"/>
      <mass value="0.042982681843648195"/>
      <inertia ixx="4.4e-05" ixy="2.1e-05" ixz="0.0" iyy="1.2e-05" iyz="-1e-06" izz="5.4e-05"/>
    </inertial>
    <visual>
      <origin rpy="0 0 0" xyz="-0.354087 0.110458 0.042257"/>
      <geometry>
        <mesh filename="package://dropbear_simplified_urdf/meshes/head/screw-reciever__2__1.stl" scale="0.001 0.001 0.001"/>
      </geometry>
      <material name="opaque25514347"/>
    </visual>
    <collision>
      <origin rpy="0 0 0" xyz="-0.354087 0.110458 0.042257"/>
      <geometry>
        <mesh filename="package://dropbear_simplified_urdf/meshes/head/screw-reciever__2__1.stl" scale="0.001 0.001 0.001"/>
      </geometry>
    </collision>
  </link>
  <link name="head_u-joint-center__4__1">
    <inertial>
      <origin rpy="0 0 0" xyz="0.004356124760737379 9.141860647654543e-08 -0.002455149691664195"/>
      <mass value="0.0009727380393185158"/>
      <inertia ixx="14.27e-09" ixy="2.27e-10" ixz="-3.25e-10" iyy="19.21e-09" iyz="-1.34e-09" izz="16.13e-09"/>
    </inertial>
    <visual>
      <origin rpy="0 0 0" xyz="-0.205483 0.11854 0.039905"/>
      <geometry>
        <mesh filename="package://dropbear_simplified_urdf/meshes/head/u-joint-center__4__1.stl" scale="0.001 0.001 0.001"/>
      </geometry>
      <material name="opaque191191191"/>
    </visual>
    <collision>
      <origin rpy="0 0 0" xyz="-0.205483 0.11854 0.039905"/>
      <geometry>
        <mesh filename="package://dropbear_simplified_urdf/meshes/head/u-joint-center__4__1.stl" scale="0.001 0.001 0.001"/>
      </geometry>
    </collision>
  </link>
  <link name="head_leadscrew__3___1__1">
    <inertial>
      <origin rpy="0 0 0" xyz="0.028842623507411347 0.04934271537953708 0.007439093732284317"/>
      <mass value="0.04187032472639327"/>
      <inertia ixx="3e-05" ixy="-1.5e-05" ixz="0.0" iyy="8e-06" iyz="0.0" izz="3.7e-05"/>
    </inertial>
    <visual>
      <origin rpy="0 0 0" xyz="-0.20603 0.116591 0.049119"/>
      <geometry>
        <mesh filename="package://dropbear_simplified_urdf/meshes/head/leadscrew__3___1__1.stl" scale="0.001 0.001 0.001"/>
      </geometry>
      <material name="opaque191191191"/>
    </visual>
    <collision>
      <origin rpy="0 0 0" xyz="-0.20603 0.116591 0.049119"/>
      <geometry>
        <mesh filename="package://dropbear_simplified_urdf/meshes/head/leadscrew__3___1__1.stl" scale="0.001 0.001 0.001"/>
      </geometry>
    </collision>
  </link>
  <link name="head_screw-reciever__3__1">
    <inertial>
      <origin rpy="0 0 0" xyz="0.015584715497152818 0.03193070525388275 0.0004236047800553547"/>
      <mass value="0.04298268184354137"/>
      <inertia ixx="4.5e-05" ixy="-2.1e-05" ixz="0.0" iyy="1.2e-05" iyz="-1e-06" izz="5.5e-05"/>
    </inertial>
    <visual>
      <origin rpy="0 0 0" xyz="-0.213786 0.110452 0.042253"/>
      <geometry>
        <mesh filename="package://dropbear_simplified_urdf/meshes/head/screw-reciever__3__1.stl" scale="0.001 0.001 0.001"/>
      </geometry>
      <material name="opaque25514347"/>
    </visual>
    <collision>
      <origin rpy="0 0 0" xyz="-0.213786 0.110452 0.042253"/>
      <geometry>
        <mesh filename="package://dropbear_simplified_urdf/meshes/head/screw-reciever__3__1.stl" scale="0.001 0.001 0.001"/>
      </geometry>
    </collision>
  </link>
  <link name="head_u-joint-center__5__1">
    <inertial>
      <origin rpy="0 0 0" xyz="0.004985175531100422 1.0243782577745719e-07 0.00038312367678919757"/>
      <mass value="0.0009727380393185158"/>
      <inertia ixx="14.27e-09" ixy="2.27e-10" ixz="-3.25e-10" iyy="19.21e-09" iyz="-1.34e-09" izz="16.13e-09"/>
    </inertial>
    <visual>
      <origin rpy="0 0 0" xyz="-0.179854 0.11854 -0.000558"/>
      <geometry>
        <mesh filename="package://dropbear_simplified_urdf/meshes/head/u-joint-center__5__1.stl" scale="0.001 0.001 0.001"/>
      </geometry>
      <material name="opaque191191191"/>
    </visual>
    <collision>
      <origin rpy="0 0 0" xyz="-0.179854 0.11854 -0.000558"/>
      <geometry>
        <mesh filename="package://dropbear_simplified_urdf/meshes/head/u-joint-center__5__1.stl" scale="0.001 0.001 0.001"/>
      </geometry>
    </collision>
  </link>
  <link name="head_leadscrew__2___1__1">
    <inertial>
      <origin rpy="0 0 0" xyz="0.012505547819126883 0.04834098253159427 0.028787508745766965"/>
      <mass value="0.041870324726393286"/>
      <inertia ixx="3.6e-05" ixy="-8e-06" ixz="-3e-06" iyy="8e-06" iyz="-1.2e-05" izz="3.2e-05"/>
    </inertial>
    <visual>
      <origin rpy="0 0 0" xyz="-0.18541 0.115595 0.006475"/>
      <geometry>
        <mesh filename="package://dropbear_simplified_urdf/meshes/head/leadscrew__2___1__1.stl" scale="0.001 0.001 0.001"/>
      </geometry>
      <material name="opaque191191191"/>
    </visual>
    <collision>
      <origin rpy="0 0 0" xyz="-0.18541 0.115595 0.006475"/>
      <geometry>
        <mesh filename="package://dropbear_simplified_urdf/meshes/head/leadscrew__2___1__1.stl" scale="0.001 0.001 0.001"/>
      </geometry>
    </collision>
  </link>
  <link name="head_screw-reciever__5__1">
    <inertial>
      <origin rpy="0 0 0" xyz="0.008061623594433992 0.03161751443189505 0.013175413237320646"/>
      <mass value="0.042818900146596034"/>
      <inertia ixx="5.1e-05" ixy="-1.1e-05" ixz="-4e-06" iyy="1.2e-05" iyz="-1.7e-05" izz="4.6e-05"/>
    </inertial>
    <visual>
      <origin rpy="0 0 0" xyz="-0.186901 0.110453 -0.004311"/>
      <geometry>
        <mesh filename="package://dropbear_simplified_urdf/meshes/head/screw-reciever__5__1.stl" scale="0.001 0.001 0.001"/>
      </geometry>
      <material name="opaque25514347"/>
    </visual>
    <collision>
      <origin rpy="0 0 0" xyz="-0.186901 0.110453 -0.004311"/>
      <geometry>
        <mesh filename="package://dropbear_simplified_urdf/meshes/head/screw-reciever__5__1.stl" scale="0.001 0.001 0.001"/>
      </geometry>
    </collision>
  </link>
  <link name="head_u-joint-center__8__1">
    <inertial>
      <origin rpy="0 0 0" xyz="-0.004714550703244946 0.0014502030420447346 0.000820321543006583"/>
      <mass value="0.0009727380393185158"/>
      <inertia ixx="14.27e-09" ixy="2.27e-10" ixz="-3.25e-10" iyy="19.21e-09" iyz="-1.34e-09" izz="16.13e-09"/>
    </inertial>
    <visual>
      <origin rpy="0 0 0" xyz="-0.34418 -0.011176 -0.072081"/>
      <geometry>
        <mesh filename="package://dropbear_simplified_urdf/meshes/head/u-joint-center__8__1.stl" scale="0.001 0.001 0.001"/>
      </geometry>
      <material name="opaque191191191"/>
    </visual>
    <collision>
      <origin rpy="0 0 0" xyz="-0.34418 -0.011176 -0.072081"/>
      <geometry>
        <mesh filename="package://dropbear_simplified_urdf/meshes/head/u-joint-center__8__1.stl" scale="0.001 0.001 0.001"/>
      </geometry>
    </collision>
  </link>
  <link name="head_10mm-ujoint-base__3__1">
    <inertial>
      <origin rpy="0 0 0" xyz="-0.0008631103535244322 0.0100927968035996 -0.004917803052373437"/>
      <mass value="0.0014232382644525146"/>
      <inertia ixx="65.84e-09" ixy="-3.0e-12" ixz="6.53e-09" iyy="63.94e-09" iyz="-2.0e-12" izz="73.94e-09"/>
    </inertial>
    <visual>
      <origin rpy="0 0 0" xyz="-0.340322 -0.012623 -0.077827"/>
      <geometry>
        <mesh filename="package://dropbear_simplified_urdf/meshes/head/10mm-ujoint-base__3__1.stl" scale="0.001 0.001 0.001"/>
      </geometry>
      <material name="opaque191191191"/>
    </visual>
    <collision>
      <origin rpy="0 0 0" xyz="-0.340322 -0.012623 -0.077827"/>
      <geometry>
        <mesh filename="package://dropbear_simplified_urdf/meshes/head/10mm-ujoint-base__3__1.stl" scale="0.001 0.001 0.001"/>
      </geometry>
    </collision>
  </link>
  <link name="head_Head_1">
    <inertial>
      <origin rpy="0 0 0" xyz="-0.05445785559977906 0.0791227204508759 -0.050633116327556904"/>
      <mass value="1.8674963122317672"/>
      <inertia ixx="0.011021" ixy="-7e-06" ixz="2e-05" iyy="0.011236" iyz="0.000445" izz="0.008366"/>
    </inertial>
    <visual>
      <origin rpy="0 0 0" xyz="-0.339454 -0.029626 -0.072915"/>
      <geometry>
        <mesh filename="package://dropbear_simplified_urdf/meshes/head/Head_1.stl" scale="0.001 0.001 0.001"/>
      </geometry>
      <material name="opaque191191191"/>
    </visual>
    <collision>
      <origin rpy="0 0 0" xyz="-0.339454 -0.029626 -0.072915"/>
      <geometry>
        <mesh filename="package://dropbear_simplified_urdf/meshes/head/Head_1.stl" scale="0.001 0.001 0.001"/>
      </geometry>
    </collision>
  </link>
  <link name="head_u-joint-center__7__1">
    <inertial>
      <origin rpy="0 0 0" xyz="-0.001164126831218526 -0.0021212943707097434 0.004375827543159155"/>
      <mass value="0.0009727380393185158"/>
      <inertia ixx="14.27e-09" ixy="2.27e-10" ixz="-3.25e-10" iyy="19.21e-09" iyz="-1.34e-09" izz="16.13e-09"/>
    </inertial>
    <visual>
      <origin rpy="0 0 0" xyz="-0.350841 -0.01476 -0.05129"/>
      <geometry>
        <mesh filename="package://dropbear_simplified_urdf/meshes/head/u-joint-center__7__1.stl" scale="0.001 0.001 0.001"/>
      </geometry>
      <material name="opaque191191191"/>
    </visual>
    <collision>
      <origin rpy="0 0 0" xyz="-0.350841 -0.01476 -0.05129"/>
      <geometry>
        <mesh filename="package://dropbear_simplified_urdf/meshes/head/u-joint-center__7__1.stl" scale="0.001 0.001 0.001"/>
      </geometry>
    </collision>
  </link>
  <link name="head_10mm-ujoint-base__2__1">
    <inertial>
      <origin rpy="0 0 0" xyz="-0.0048251103398560535 0.010093321294563556 -0.0012805299667578013"/>
      <mass value="0.0014232382644525146"/>
      <inertia ixx="65.84e-09" ixy="-3.0e-12" ixz="6.53e-09" iyy="63.94e-09" iyz="-2.0e-12" izz="73.94e-09"/>
    </inertial>
    <visual>
      <origin rpy="0 0 0" xyz="-0.354509 -0.012635 -0.056949"/>
      <geometry>
        <mesh filename="package://dropbear_simplified_urdf/meshes/head/10mm-ujoint-base__2__1.stl" scale="0.001 0.001 0.001"/>
      </geometry>
      <material name="opaque191191191"/>
    </visual>
    <collision>
      <origin rpy="0 0 0" xyz="-0.354509 -0.012635 -0.056949"/>
      <geometry>
        <mesh filename="package://dropbear_simplified_urdf/meshes/head/10mm-ujoint-base__2__1.stl" scale="0.001 0.001 0.001"/>
      </geometry>
    </collision>
  </link>
  <link name="head_u-joint-center__9__1">
    <inertial>
      <origin rpy="0 0 0" xyz="0.0023709258457064175 0.0011070871145714267 0.00426110181416265"/>
      <mass value="0.0009727380393185158"/>
      <inertia ixx="14.27e-09" ixy="2.27e-10" ixz="-3.25e-10" iyy="19.21e-09" iyz="-1.34e-09" izz="16.13e-09"/>
    </inertial>
    <visual>
      <origin rpy="0 0 0" xyz="-0.291472 -0.011469 0.044954"/>
      <geometry>
        <mesh filename="package://dropbear_simplified_urdf/meshes/head/u-joint-center__9__1.stl" scale="0.001 0.001 0.001"/>
      </geometry>
      <material name="opaque191191191"/>
    </visual>
    <collision>
      <origin rpy="0 0 0" xyz="-0.291472 -0.011469 0.044954"/>
      <geometry>
        <mesh filename="package://dropbear_simplified_urdf/meshes/head/u-joint-center__9__1.stl" scale="0.001 0.001 0.001"/>
      </geometry>
    </collision>
  </link>
  <link name="head_10mm-ujoint-base__1__1">
    <inertial>
      <origin rpy="0 0 0" xyz="-0.004374417577884759 0.010085622713966397 0.0024369614949263582"/>
      <mass value="0.0014232382644525146"/>
      <inertia ixx="65.84e-09" ixy="-3.0e-12" ixz="6.53e-09" iyy="63.94e-09" iyz="-2.0e-12" izz="73.94e-09"/>
    </inertial>
    <visual>
      <origin rpy="0 0 0" xyz="-0.298212 -0.01258 0.043124"/>
      <geometry>
        <mesh filename="package://dropbear_simplified_urdf/meshes/head/10mm-ujoint-base__1__1.stl" scale="0.001 0.001 0.001"/>
      </geometry>
      <material name="opaque191191191"/>
    </visual>
    <collision>
      <origin rpy="0 0 0" xyz="-0.298212 -0.01258 0.043124"/>
      <geometry>
        <mesh filename="package://dropbear_simplified_urdf/meshes/head/10mm-ujoint-base__1__1.stl" scale="0.001 0.001 0.001"/>
      </geometry>
    </collision>
  </link>
  <link name="head_u-joint-center_1">
    <inertial>
      <origin rpy="0 0 0" xyz="-0.002654534649389917 0.001241606002754329 0.004051810068480127"/>
      <mass value="0.0009727380393185158"/>
      <inertia ixx="14.27e-09" ixy="2.27e-10" ixz="-3.25e-10" iyy="19.21e-09" iyz="-1.34e-09" izz="16.13e-09"/>
    </inertial>
    <visual>
      <origin rpy="0 0 0" xyz="-0.276526 -0.011416 0.044672"/>
      <geometry>
        <mesh filename="package://dropbear_simplified_urdf/meshes/head/u-joint-center_1.stl" scale="0.001 0.001 0.001"/>
      </geometry>
      <material name="opaque191191191"/>
    </visual>
    <collision>
      <origin rpy="0 0 0" xyz="-0.276526 -0.011416 0.044672"/>
      <geometry>
        <mesh filename="package://dropbear_simplified_urdf/meshes/head/u-joint-center_1.stl" scale="0.001 0.001 0.001"/>
      </geometry>
    </collision>
  </link>
  <link name="head_10mm-ujoint-base_1">
    <inertial>
      <origin rpy="0 0 0" xyz="-0.00418094602180985 0.010091298212800023 -0.0027347789599892758"/>
      <mass value="0.0014232382644525146"/>
      <inertia ixx="65.84e-09" ixy="-3.0e-12" ixz="6.53e-09" iyy="63.94e-09" iyz="-2.0e-12" izz="73.94e-09"/>
    </inertial>
    <visual>
      <origin rpy="0 0 0" xyz="-0.278054 -0.012656 0.03788"/>
      <geometry>
        <mesh filename="package://dropbear_simplified_urdf/meshes/head/10mm-ujoint-base_1.stl" scale="0.001 0.001 0.001"/>
      </geometry>
      <material name="opaque191191191"/>
    </visual>
    <collision>
      <origin rpy="0 0 0" xyz="-0.278054 -0.012656 0.03788"/>
      <geometry>
        <mesh filename="package://dropbear_simplified_urdf/meshes/head/10mm-ujoint-base_1.stl" scale="0.001 0.001 0.001"/>
      </geometry>
    </collision>
  </link>
  <link name="head_u-joint-center__10__1">
    <inertial>
      <origin rpy="0 0 0" xyz="0.0010869079977688934 -0.0021109819465681343 0.004400401099097305"/>
      <mass value="0.0009727380393185158"/>
      <inertia ixx="14.27e-09" ixy="2.27e-10" ixz="-3.25e-10" iyy="19.21e-09" iyz="-1.34e-09" izz="16.13e-09"/>
    </inertial>
    <visual>
      <origin rpy="0 0 0" xyz="-0.2172 -0.014754 -0.051206"/>
      <geometry>
        <mesh filename="package://dropbear_simplified_urdf/meshes/head/u-joint-center__10__1.stl" scale="0.001 0.001 0.001"/>
      </geometry>
      <material name="opaque191191191"/>
    </visual>
    <collision>
      <origin rpy="0 0 0" xyz="-0.2172 -0.014754 -0.051206"/>
      <geometry>
        <mesh filename="package://dropbear_simplified_urdf/meshes/head/u-joint-center__10__1.stl" scale="0.001 0.001 0.001"/>
      </geometry>
    </collision>
  </link>
  <link name="head_10mm-ujoint-base__5__1">
    <inertial>
      <origin rpy="0 0 0" xyz="0.005217041197059458 0.00986470883503762 -0.0015102147129289062"/>
      <mass value="0.0014232382644525146"/>
      <inertia ixx="65.84e-09" ixy="-3.0e-12" ixz="6.53e-09" iyy="63.94e-09" iyz="-2.0e-12" izz="73.94e-09"/>
    </inertial>
    <visual>
      <origin rpy="0 0 0" xyz="-0.213462 -0.012858 -0.056901"/>
      <geometry>
        <mesh filename="package://dropbear_simplified_urdf/meshes/head/10mm-ujoint-base__5__1.stl" scale="0.001 0.001 0.001"/>
      </geometry>
      <material name="opaque191191191"/>
    </visual>
    <collision>
      <origin rpy="0 0 0" xyz="-0.213462 -0.012858 -0.056901"/>
      <geometry>
        <mesh filename="package://dropbear_simplified_urdf/meshes/head/10mm-ujoint-base__5__1.stl" scale="0.001 0.001 0.001"/>
      </geometry>
    </collision>
  </link>
  <link name="head_u-joint-center__11__1">
    <inertial>
      <origin rpy="0 0 0" xyz="-3.210636303846437e-06 -0.0019705200384065574 -0.004594639231801437"/>
      <mass value="0.0009727380393185158"/>
      <inertia ixx="14.27e-09" ixy="2.27e-10" ixz="-3.25e-10" iyy="19.21e-09" iyz="-1.34e-09" izz="16.13e-09"/>
    </inertial>
    <visual>
      <origin rpy="0 0 0" xyz="-0.228395 -0.014648 -0.07763"/>
      <geometry>
        <mesh filename="package://dropbear_simplified_urdf/meshes/head/u-joint-center__11__1.stl" scale="0.001 0.001 0.001"/>
      </geometry>
      <material name="opaque191191191"/>
    </visual>
    <collision>
      <origin rpy="0 0 0" xyz="-0.228395 -0.014648 -0.07763"/>
      <geometry>
        <mesh filename="package://dropbear_simplified_urdf/meshes/head/u-joint-center__11__1.stl" scale="0.001 0.001 0.001"/>
      </geometry>
    </collision>
  </link>
  <link name="head_10mm-ujoint-base__4__1">
    <inertial>
      <origin rpy="0 0 0" xyz="0.005005631071676758 0.010087151077690207 -4.07206132493898e-06"/>
      <mass value="0.0014232382644525146"/>
      <inertia ixx="65.84e-09" ixy="-3.0e-12" ixz="6.53e-09" iyy="63.94e-09" iyz="-2.0e-12" izz="73.94e-09"/>
    </inertial>
    <visual>
      <origin rpy="0 0 0" xyz="-0.223392 -0.01268 -0.073037"/>
      <geometry>
        <mesh filename="package://dropbear_simplified_urdf/meshes/head/10mm-ujoint-base__4__1.stl" scale="0.001 0.001 0.001"/>
      </geometry>
      <material name="opaque191191191"/>
    </visual>
    <collision>
      <origin rpy="0 0 0" xyz="-0.223392 -0.01268 -0.073037"/>
      <geometry>
        <mesh filename="package://dropbear_simplified_urdf/meshes/head/10mm-ujoint-base__4__1.stl" scale="0.001 0.001 0.001"/>
      </geometry>
    </collision>
  </link>
  <joint name="head_torso_connection" type="fixed">
    <origin rpy="0 1.5707965 0" xyz="0.078519 0.116226 0.059747"/>
    <parent link="torso"/>
    <child link="head_center-bracket2_1"/>
  </joint>
  <joint name="head_Revolute 2" type="continuous">
    <origin rpy="0 0 0" xyz="0.025 0.059 0.0025"/>
    <parent link="head_center-bracket2_1"/>
    <child link="head_5mm-ujoint-base__5__1"/>
    <axis xyz="0.0 1.0 0.0"/>
  </joint>
  <joint name="head_Revolute 3" type="continuous">
    <origin rpy="0 0 0" xyz="-0.025 0.059 0.0025"/>
    <parent link="head_center-bracket2_1"/>
    <child link="head_5mm-ujoint-base__2__1"/>
    <axis xyz="0.0 1.0 0.0"/>
  </joint>
  <joint name="head_Revolute 4" type="continuous">
    <origin rpy="0 0 0" xyz="0.099102 0.059 -0.12585"/>
    <parent link="head_center-bracket2_1"/>
    <child link="head_5mm-ujoint-base__1__1"/>
    <axis xyz="0.0 1.0 0.0"/>
  </joint>
  <joint name="head_Revolute 5" type="continuous">
    <origin rpy="0 0 0" xyz="0.074102 0.059 -0.169151"/>
    <parent link="head_center-bracket2_1"/>
    <child link="head_5mm-ujoint-base_1"/>
    <axis xyz="0.0 1.0 0.0"/>
  </joint>
  <joint name="head_Revolute 6" type="continuous">
    <origin rpy="0 0 0" xyz="-0.074103 0.059 -0.169151"/>
    <parent link="head_center-bracket2_1"/>
    <child link="head_5mm-ujoint-base__3__1"/>
    <axis xyz="0.0 1.0 0.0"/>
  </joint>
  <joint name="head_Revolute 7" type="continuous">
    <origin rpy="0 0 0" xyz="-0.099103 0.059 -0.12585"/>
    <parent link="head_center-bracket2_1"/>
    <child link="head_5mm-ujoint-base__4__1"/>
    <axis xyz="0.0 1.0 0.0"/>
  </joint>
  <joint name="head_Revolute 8" type="continuous">
    <origin rpy="0 0 0" xyz="0.004226 0.009 0.002671"/>
    <parent link="head_5mm-ujoint-base__5__1"/>
    <child link="head_u-joint-center__6__1"/>
    <axis xyz="-0.845262 0.0 -0.534352"/>
  </joint>
  <joint name="head_Revolute 9" type="continuous">
    <origin rpy="0 0 0" xyz="-0.000384 -0.003507 -0.008749"/>
    <parent link="head_u-joint-center__6__1"/>
    <child link="head_leadscrew__4___1"/>
    <axis xyz="0.480273 -0.438371 -0.759716"/>
  </joint>
  <joint name="head_Slider 10" type="prismatic">
    <origin rpy="0 0 0" xyz="-0.001961 0.011593 0.002602"/>
    <parent link="head_leadscrew__4___1"/>
    <child link="head_screw-reciever_1"/>
    <axis xyz="-0.209066 -0.898398 0.386228"/>
    <limit effort="100" lower="-0.075" upper="0.0" velocity="100"/>
  </joint>
  <joint name="head_Revolute 11" type="continuous">
    <origin rpy="0 0 0" xyz="0.00493 0.009 0.000834"/>
    <parent link="head_5mm-ujoint-base__2__1"/>
    <child link="head_u-joint-center__1__1"/>
    <axis xyz="-0.985983 0.0 -0.166846"/>
  </joint>
  <joint name="head_Revolute 12" type="continuous">
    <origin rpy="0 0 0" xyz="-0.006176 0.002867 0.00653"/>
    <parent link="head_u-joint-center__1__1"/>
    <child link="head_leadscrew__5___1__1"/>
    <axis xyz="-0.155764 0.358368 0.920494"/>
  </joint>
  <joint name="head_Slider 13" type="prismatic">
    <origin rpy="0 0 0" xyz="-0.000638 0.005222 -0.010832"/>
    <parent link="head_leadscrew__5___1__1"/>
    <child link="head_screw-reciever__4__1"/>
    <axis xyz="0.209246 -0.89875 0.385311"/>
    <limit effort="100" lower="-0.075" upper="0.0" velocity="100"/>
  </joint>
  <joint name="head_Revolute 14" type="continuous">
    <origin rpy="0 0 0" xyz="0.004979 0.009 -0.000462"/>
    <parent link="head_5mm-ujoint-base__1__1"/>
    <child link="head_u-joint-center__3__1"/>
    <axis xyz="-0.995725 0.0 0.092371"/>
  </joint>
  <joint name="head_Revolute 15" type="continuous">
    <origin rpy="0 0 0" xyz="-0.005667 0.002919 -0.006954"/>
    <parent link="head_u-joint-center__3__1"/>
    <child link="head_leadscrew__1___1__1"/>
    <axis xyz="-0.086002 0.364877 -0.927075"/>
  </joint>
  <joint name="head_Slider 16" type="prismatic">
    <origin rpy="0 0 0" xyz="-0.001369 0.005167 0.01079"/>
    <parent link="head_leadscrew__1___1__1"/>
    <child link="head_screw-reciever__1__1"/>
    <axis xyz="0.228543 -0.898484 -0.374825"/>
    <limit effort="100" lower="-0.075" upper="0.0" velocity="100"/>
  </joint>
  <joint name="head_Revolute 17" type="continuous">
    <origin rpy="0 0 0" xyz="-0.00184 0.009 -0.004649"/>
    <parent link="head_5mm-ujoint-base_1"/>
    <child link="head_u-joint-center__2__1"/>
    <axis xyz="0.368125 0.0 0.929776"/>
  </joint>
  <joint name="head_Revolute 18" type="continuous">
    <origin rpy="0 0 0" xyz="0.008598 0.003343 0.001973"/>
    <parent link="head_u-joint-center__2__1"/>
    <child link="head_leadscrew__0__1"/>
    <axis xyz="0.84471 0.417867 -0.334444"/>
  </joint>
  <joint name="head_Slider 19" type="prismatic">
    <origin rpy="0 0 0" xyz="-0.010715 0.004739 0.002779"/>
    <parent link="head_leadscrew__0__1"/>
    <child link="head_screw-reciever__2__1"/>
    <axis xyz="0.439735 -0.898055 -0.011418"/>
    <limit effort="100" lower="-0.075" upper="0.0" velocity="100"/>
  </joint>
  <joint name="head_Revolute 20" type="continuous">
    <origin rpy="0 0 0" xyz="-0.004356 0.009 0.002455"/>
    <parent link="head_5mm-ujoint-base__3__1"/>
    <child link="head_u-joint-center__4__1"/>
    <axis xyz="0.871168 0.0 -0.490985"/>
  </joint>
  <joint name="head_Revolute 21" type="continuous">
    <origin rpy="0 0 0" xyz="0.000547 0.001949 -0.009214"/>
    <parent link="head_u-joint-center__4__1"/>
    <child link="head_leadscrew__3___1__1"/>
    <axis xyz="-0.476193 0.243615 -0.844921"/>
  </joint>
  <joint name="head_Slider 22" type="prismatic">
    <origin rpy="0 0 0" xyz="0.007756 0.006139 0.006866"/>
    <parent link="head_leadscrew__3___1__1"/>
    <child link="head_screw-reciever__3__1"/>
    <axis xyz="-0.438578 -0.898614 -0.011916"/>
    <limit effort="100" lower="-0.075" upper="0.0" velocity="100"/>
  </joint>
  <joint name="head_Revolute 23" type="continuous">
    <origin rpy="0 0 0" xyz="-0.004985 0.009 -0.000383"/>
    <parent link="head_5mm-ujoint-base__4__1"/>
    <child link="head_u-joint-center__5__1"/>
    <axis xyz="0.997055 0.0 0.076689"/>
  </joint>
  <joint name="head_Revolute 24" type="continuous">
    <origin rpy="0 0 0" xyz="0.005556 0.002945 -0.007033"/>
    <parent link="head_u-joint-center__5__1"/>
    <child link="head_leadscrew__2___1__1"/>
    <axis xyz="0.071303 0.368125 -0.927038"/>
  </joint>
  <joint name="head_Slider 25" type="prismatic">
    <origin rpy="0 0 0" xyz="0.001491 0.005142 0.010786"/>
    <parent link="head_leadscrew__2___1__1"/>
    <child link="head_screw-reciever__5__1"/>
    <axis xyz="-0.229094 -0.898514 -0.374418"/>
    <limit effort="100" lower="-0.075" upper="0.0" velocity="100"/>
  </joint>
  <joint name="head_Revolute 26" type="continuous">
    <origin rpy="0 0 0" xyz="0.033357 0.12163 -0.053734"/>
    <parent link="head_screw-reciever_1"/>
    <child link="head_u-joint-center__8__1"/>
    <axis xyz="-0.942857 0.289971 0.164128"/>
  </joint>
  <joint name="head_Revolute 27" type="continuous">
    <origin rpy="0 0 0" xyz="-0.003858 0.001447 0.005746"/>
    <parent link="head_u-joint-center__8__1"/>
    <child link="head_10mm-ujoint-base__3__1"/>
    <axis xyz="0.1713 -0.000659 0.985219"/>
  </joint>
  <joint name="head_Rigid 28" type="fixed">
    <origin rpy="0 0 0" xyz="-0.000868 0.017003 -0.004912"/>
    <parent link="head_10mm-ujoint-base__3__1"/>
    <child link="head_Head_1"/>
  </joint>
  <joint name="head_Revolute 29" type="continuous">
    <origin rpy="0 0 0" xyz="-0.030146 0.125214 0.046975"/>
    <parent link="head_screw-reciever__1__1"/>
    <child link="head_u-joint-center__7__1"/>
    <axis xyz="-0.232746 -0.424277 0.87511"/>
  </joint>
  <joint name="head_Revolute 30" type="continuous">
    <origin rpy="0 0 0" xyz="0.003668 -0.002125 0.005659"/>
    <parent link="head_u-joint-center__7__1"/>
    <child link="head_10mm-ujoint-base__2__1"/>
    <axis xyz="0.966493 -0.000738 0.256693"/>
  </joint>
  <joint name="head_Revolute 32" type="continuous">
    <origin rpy="0 0 0" xyz="-0.062615 0.121927 -0.002697"/>
    <parent link="head_screw-reciever__2__1"/>
    <child link="head_u-joint-center__9__1"/>
    <axis xyz="0.474078 0.221298 0.852219"/>
  </joint>
  <joint name="head_Revolute 33" type="continuous">
    <origin rpy="0 0 0" xyz="0.00674 0.001111 0.00183"/>
    <parent link="head_u-joint-center__9__1"/>
    <child link="head_10mm-ujoint-base__1__1"/>
    <axis xyz="0.873803 0.000747 -0.486279"/>
  </joint>
  <joint name="head_Revolute 35" type="continuous">
    <origin rpy="0 0 0" xyz="0.06274 0.121868 -0.002419"/>
    <parent link="head_screw-reciever__3__1"/>
    <child link="head_u-joint-center_1"/>
    <axis xyz="-0.530813 0.248324 0.810292"/>
  </joint>
  <joint name="head_Revolute 36" type="continuous">
    <origin rpy="0 0 0" xyz="0.001528 0.00124 0.006792"/>
    <parent link="head_u-joint-center_1"/>
    <child link="head_10mm-ujoint-base_1"/>
    <axis xyz="0.836433 -0.000427 0.548069"/>
  </joint>
  <joint name="head_Revolute 38" type="continuous">
    <origin rpy="0 0 0" xyz="0.030299 0.125207 0.046895"/>
    <parent link="head_screw-reciever__5__1"/>
    <child link="head_u-joint-center__10__1"/>
    <axis xyz="0.2173 -0.422149 0.880097"/>
  </joint>
  <joint name="head_Revolute 39" type="continuous">
    <origin rpy="0 0 0" xyz="-0.003738 -0.001896 0.005695"/>
    <parent link="head_u-joint-center__10__1"/>
    <child link="head_10mm-ujoint-base__5__1"/>
    <axis xyz="-0.96494 0.043076 0.25891"/>
  </joint>
  <joint name="head_Revolute 41" type="continuous">
    <origin rpy="0 0 0" xyz="-0.028663 0.125099 -0.048193"/>
    <parent link="head_screw-reciever__4__1"/>
    <child link="head_u-joint-center__11__1"/>
    <axis xyz="-0.000586 -0.394148 -0.919047"/>
  </joint>
  <joint name="head_Revolute 42" type="continuous">
    <origin rpy="0 0 0" xyz="-0.005003 -0.001968 -0.004593"/>
    <parent link="head_u-joint-center__11__1"/>
    <child link="head_10mm-ujoint-base__4__1"/>
    <axis xyz="-1.0 0.000581 0.000388"/>
  </joint>
  <gazebo>
    <plugin filename="libgazebo_ros_api_plugin.so" name="gazebo_ros"/>
    <joint name="head_platform_Rigig_1__44__gz" type="fixed">
      <pose relative_to="head_Head_1">0.1165 0.0 -0.03791 0 0 0</pose>
      <parent>head_10mm-ujoint-base__5__1</parent>
      <child>head_Head_1</child>
      <dynamics>
        <damping>0.0</damping>
        <friction>0.0</friction>
      </dynamics>
    </joint>
    <joint name="head_platform_Rigid_2__45_gz" type="fixed">
      <pose relative_to="head_Head_1">0.1096 0.0 -0.01913 0 0 0</pose>
      <parent>head_10mm-ujoint-base__4__1</parent>
      <child>head_Head_1</child>
      <dynamics>
        <damping>0.0</damping>
        <friction>0.0</friction>
      </dynamics>
    </joint>
    <joint name="head_platform_Rigid_3__46_gz" type="fixed">
      <pose relative_to="head_Head_1">-0.01283 0.0 -0.01534 0 0 0</pose>
      <parent>head_10mm-ujoint-base__2__1</parent>
      <child>head_Head_1</child>
      <dynamics>
        <damping>0.0</damping>
        <friction>0.0</friction>
      </dynamics>
    </joint>
    <joint name="head_platform_Rigid_4__47_gz" type="fixed">
      <pose relative_to="head_Head_1">0.0254 0.0 -0.1198 0 0 0</pose>
      <parent>head_10mm-ujoint-base__1__1</parent>
      <child>head_Head_1</child>
      <dynamics>
        <damping>0.0</damping>
        <friction>0.0</friction>
      </dynamics>
    </joint>
    <joint name="head_platform_Rigid_5__48_gz" type="fixed">
      <pose relative_to="head_Head_1">0.0451 0.00 -0.1233 0 0 0</pose>
      <parent>head_10mm-ujoint-base_1</parent>
      <child>head_Head_1</child>
      <dynamics>
        <damping>0.0</damping>
        <friction>0.0</friction>
      </dynamics>
    </joint>
  </gazebo>
  <gazebo reference="head_Rigid 28">
    <preserveFixedJoint>true</preserveFixedJoint>
  </gazebo>
  <link name="Rotate-right-leg_1">
    <inertial>
      <origin rpy="0 0 0" xyz="0.06120754854285463 -0.0029503876001564233 0.014756359444244638"/>
      <mass value="0.5634737106043444"/>
      <inertia ixx="0.001013" ixy="-2.1e-05" ixz="0.000246" iyy="0.002795" iyz="0.000121" izz="0.002177"/>
    </inertial>
    <visual>
      <origin rpy="0 0 0" xyz="0.10502 0.263369 -0.120699"/>
      <geometry>
        <mesh filename="package://dropbear_simplified_urdf/meshes/waist/Rotate-right-leg_1.stl" scale="0.001 0.001 0.001"/>
      </geometry>
      <material name="opaque245245245"/>
    </visual>
    <collision>
      <origin rpy="0 0 0" xyz="0.10502 0.263369 -0.120699"/>
      <geometry>
        <mesh filename="package://dropbear_simplified_urdf/meshes/waist/Rotate-right-leg_1.stl" scale="0.001 0.001 0.001"/>
      </geometry>
    </collision>
  </link>
  <link name="Rotate-left-leg_1">
    <inertial>
      <origin rpy="0 0 0" xyz="0.06120127554004958 -0.0029502323515913087 -0.014767579628205085"/>
      <mass value="0.563679151820761"/>
      <inertia ixx="0.001016" ixy="-2.1e-05" ixz="-0.000248" iyy="0.002797" iyz="-0.000121" izz="0.002177"/>
    </inertial>
    <visual>
      <origin rpy="0 0 0" xyz="0.104988 0.263369 0.001301"/>
      <geometry>
        <mesh filename="package://dropbear_simplified_urdf/meshes/waist/Rotate-left-leg_1.stl" scale="0.001 0.001 0.001"/>
      </geometry>
      <material name="opaque245245245"/>
    </visual>
    <collision>
      <origin rpy="0 0 0" xyz="0.104988 0.263369 0.001301"/>
      <geometry>
        <mesh filename="package://dropbear_simplified_urdf/meshes/waist/Rotate-left-leg_1.stl" scale="0.001 0.001 0.001"/>
      </geometry>
    </collision>
  </link>
  <link name="Left-femur-top_1">
    <inertial>
      <origin rpy="0 0 0" xyz="-4.097892786209326e-06 -0.04138743736457201 0.004860837445485772"/>
      <mass value="0.17034196336973478"/>
      <inertia ixx="0.000221" ixy="0.0" ixz="0.0" iyy="6.8e-05" iyz="1.6e-05" izz="0.000227"/>
    </inertial>
    <visual>
      <origin rpy="0 0 0" xyz="-0.007913 0.284631 0.006662"/>
      <geometry>
        <mesh filename="package://dropbear_simplified_urdf/meshes/waist/Left-femur-top_1.stl" scale="0.001 0.001 0.001"/>
      </geometry>
      <material name="opaque2551530"/>
    </visual>
    <collision>
      <origin rpy="0 0 0" xyz="-0.007913 0.284631 0.006662"/>
      <geometry>
        <mesh filename="package://dropbear_simplified_urdf/meshes/waist/Left-femur-top_1.stl" scale="0.001 0.001 0.001"/>
      </geometry>
    </collision>
  </link>
  <link name="Right-femur-top_1">
    <inertial>
      <origin rpy="0 0 0" xyz="-1.1875230248842295e-05 -0.04016954723293298 -0.005717104429115966"/>
      <mass value="0.17742927672123618"/>
      <inertia ixx="0.000232" ixy="0.0" ixz="-0.0" iyy="7.2e-05" iyz="-1.2e-05" izz="0.000233"/>
    </inertial>
    <visual>
      <origin rpy="0 0 0" xyz="-0.007878 0.284631 -0.126119"/>
      <geometry>
        <mesh filename="package://dropbear_simplified_urdf/meshes/waist/Right-femur-top_1.stl" scale="0.001 0.001 0.001"/>
      </geometry>
      <material name="opaque2551530"/>
    </visual>
    <collision>
      <origin rpy="0 0 0" xyz="-0.007878 0.284631 -0.126119"/>
      <geometry>
        <mesh filename="package://dropbear_simplified_urdf/meshes/waist/Right-femur-top_1.stl" scale="0.001 0.001 0.001"/>
      </geometry>
    </collision>
  </link>
  <link name="DumRightLeg_1">
    <inertial>
      <origin rpy="0 0 0" xyz="-2.719365716774558e-07 -0.00043367314179110217 0.002461581106896815"/>
      <mass value="0.06889197528787226"/>
      <inertia ixx="8e-06" ixy="0.0" ixz="-0.0" iyy="1.4e-05" iyz="-1e-06" izz="2.2e-05"/>
    </inertial>
    <visual>
      <origin rpy="0 0 0" xyz="-0.007871 0.35927 -0.143421"/>
      <geometry>
        <mesh filename="package://dropbear_simplified_urdf/meshes/waist/DumRightLeg_1.stl" scale="0.001 0.001 0.001"/>
      </geometry>
      <material name="opaque2550255"/>
    </visual>
    <collision>
      <origin rpy="0 0 0" xyz="-0.007871 0.35927 -0.143421"/>
      <geometry>
        <mesh filename="package://dropbear_simplified_urdf/meshes/waist/DumRightLeg_1.stl" scale="0.001 0.001 0.001"/>
      </geometry>
    </collision>
  </link>
  <link name="DumLeftLeg_1">
    <inertial>
      <origin rpy="0 0 0" xyz="6.474975373111508e-07 -0.00043367314397685375 -0.0024621363755123714"/>
      <mass value="0.06889197549127557"/>
      <inertia ixx="8e-06" ixy="0.0" ixz="-0.0" iyy="1.4e-05" iyz="1e-06" izz="2.2e-05"/>
    </inertial>
    <visual>
      <origin rpy="0 0 0" xyz="-0.007915 0.35927 0.023964"/>
      <geometry>
        <mesh filename="package://dropbear_simplified_urdf/meshes/waist/DumLeftLeg_1.stl" scale="0.001 0.001 0.001"/>
      </geometry>
      <material name="opaque2550255"/>
    </visual>
    <collision>
      <origin rpy="0 0 0" xyz="-0.007915 0.35927 0.023964"/>
      <geometry>
        <mesh filename="package://dropbear_simplified_urdf/meshes/waist/DumLeftLeg_1.stl" scale="0.001 0.001 0.001"/>
      </geometry>
    </collision>
  </link>
  <link name="Buttocks_1">
    <inertial>
      <origin rpy="0 0 0" xyz="0.07123027976226544 -0.05736392763598394 1.174722519241278e-05"/>
      <mass value="0.9540709404154066"/>
      <inertia ixx="0.004292" ixy="-0.000113" ixz="-1e-06" iyy="0.012882" iyz="0.0" izz="0.011871"/>
    </inertial>
    <visual>
      <origin rpy="0 0 0" xyz="0.140001 0.171194 -0.05969"/>
      <geometry>
        <mesh filename="package://dropbear_simplified_urdf/meshes/waist/Buttocks_1.stl" scale="0.001 0.001 0.001"/>
      </geometry>
      <material name="opaque20400"/>
    </visual>
    <collision>
      <origin rpy="0 0 0" xyz="0.140001 0.171194 -0.05969"/>
      <geometry>
        <mesh filename="package://dropbear_simplified_urdf/meshes/waist/Buttocks_1.stl" scale="0.001 0.001 0.001"/>
      </geometry>
    </collision>
  </link>
  <joint name="right_leg_pitch" type="continuous">
    <origin rpy="0 0 0" xyz="0.034981 -0.092175 0.061009"/>
    <parent link="Buttocks_1"/>
    <child link="Rotate-right-leg_1"/>
    <axis xyz="1.0 -3.2e-05 0.000261"/>
  </joint>
  <joint name="left_leg_pitch" type="continuous">
    <origin rpy="0 0 0" xyz="0.035013 -0.092175 -0.060991"/>
    <parent link="Buttocks_1"/>
    <child link="Rotate-left-leg_1"/>
    <axis xyz="1.0 -3.2e-05 0.000261"/>
  </joint>
  <joint name="left_leg_yaw" type="continuous">
    <origin rpy="0 0 0" xyz="0.112901 -0.021262 -0.005361"/>
    <parent link="Rotate-left-leg_1"/>
    <child link="Left-femur-top_1"/>
    <axis xyz="-7.7e-05 -0.984808 0.173648"/>
  </joint>
  <joint name="right_leg_yaw" type="continuous">
    <origin rpy="0 0 0" xyz="0.112898 -0.021262 0.00542"/>
    <parent link="Rotate-right-leg_1"/>
    <child link="Right-femur-top_1"/>
    <axis xyz="1.4e-05 -0.984808 -0.173648"/>
  </joint>
  <joint name="Connection_to_R_leg" type="fixed">
    <origin rpy="0 0 0" xyz="-7e-06 -0.074639 0.017302"/>
    <parent link="Right-femur-top_1"/>
    <child link="DumRightLeg_1"/>
  </joint>
  <joint name="Connection_to_L_leg" type="fixed">
    <origin rpy="0 0 0" xyz="2e-06 -0.074639 -0.017302"/>
    <parent link="Left-femur-top_1"/>
    <child link="DumLeftLeg_1"/>
  </joint>
  <joint name="torso_connection" type="fixed">
    <!-- <origin xyz="-0.140001 -0.171194 0.05969" rpy="0 0 0"/> -->
    <origin rpy="0 0 0" xyz="-0.140001 -0.171194 0.05969"/>
    <parent link="torso"/>
    <child link="Buttocks_1"/>
  </joint>
  <link name="RH_2020_100mm__9__1">
    <inertial>
      <origin rpy="0 0 0" xyz="-0.0008466746254246146 0.0026057965560190325 0.04747235208031805"/>
      <mass value="0.15134342423432742"/>
      <inertia ixx="0.000135" ixy="4e-06" ixz="0.0" iyy="0.000123" iyz="-1e-06" izz="6.9e-05"/>
    </inertial>
    <visual>
      <origin rpy="0 0 0" xyz="0.0 0.0 -0.0021"/>
      <geometry>
        <mesh filename="package://dropbear_simplified_urdf/meshes/rightarm/2020_100mm__9__1.stl" scale="0.001 0.001 0.001"/>
      </geometry>
      <material name="opaque727161"/>
    </visual>
    <collision>
      <origin rpy="0 0 0" xyz="0.0 0.0 -0.0021"/>
      <geometry>
        <mesh filename="package://dropbear_simplified_urdf/meshes/rightarm/2020_100mm__9__1.stl" scale="0.001 0.001 0.001"/>
      </geometry>
    </collision>
  </link>
  <link name="RH_RMD-X8-Pro_MIR8_MIR1__1__1">
    <inertial>
      <origin rpy="0 0 0" xyz="0.03168610209516673 0.03722389945118263 0.009663941690489952"/>
      <mass value="0.39705688727274907"/>
      <inertia ixx="0.000836" ixy="0.000113" ixz="-0.000101" iyy="0.000815" iyz="-2.7e-05" izz="0.001335"/>
    </inertial>
    <visual>
      <origin rpy="0 0 0" xyz="-0.008343 0.025679 -0.0521"/>
      <geometry>
        <mesh filename="package://dropbear_simplified_urdf/meshes/rightarm/RMD-X8-Pro_MIR8_MIR1__1__1.stl" scale="0.001 0.001 0.001"/>
      </geometry>
      <material name="opaque13110895"/>
    </visual>
    <collision>
      <origin rpy="0 0 0" xyz="-0.008343 0.025679 -0.0521"/>
      <geometry>
        <mesh filename="package://dropbear_simplified_urdf/meshes/rightarm/RMD-X8-Pro_MIR8_MIR1__1__1.stl" scale="0.001 0.001 0.001"/>
      </geometry>
    </collision>
  </link>
  <link name="RH_RMD-X8-Pro_MIR8_MIR1__3__1">
    <inertial>
      <origin rpy="0 0 0" xyz="0.073833397772971 0.021968775763905476 0.008042518945865815"/>
      <mass value="0.2600729816837481"/>
      <inertia ixx="0.000377" ixy="-0.000126" ixz="-2.4e-05" iyy="0.00073" iyz="-1.8e-05" izz="0.000813"/>
    </inertial>
    <visual>
      <origin rpy="0 0 0" xyz="-0.101763 -0.033065 -0.0661"/>
      <geometry>
        <mesh filename="package://dropbear_simplified_urdf/meshes/rightarm/RMD-X8-Pro_MIR8_MIR1__3__1.stl" scale="0.001 0.001 0.001"/>
      </geometry>
      <material name="opaque13110895"/>
    </visual>
    <collision>
      <origin rpy="0 0 0" xyz="-0.101763 -0.033065 -0.0661"/>
      <geometry>
        <mesh filename="package://dropbear_simplified_urdf/meshes/rightarm/RMD-X8-Pro_MIR8_MIR1__3__1.stl" scale="0.001 0.001 0.001"/>
      </geometry>
    </collision>
  </link>
  <link name="RH_bicep-motor-mate_1">
    <inertial>
      <origin rpy="0 0 0" xyz="0.0036413059649407775 0.018293491559330355 -0.004857773320266552"/>
      <mass value="0.023400269164045275"/>
      <inertia ixx="1.3e-05" ixy="-2e-06" ixz="0.0" iyy="3e-06" iyz="0.0" izz="1.5e-05"/>
    </inertial>
    <visual>
      <origin rpy="0 0 0" xyz="-0.198295 -0.06443 -0.0566"/>
      <geometry>
        <mesh filename="package://dropbear_simplified_urdf/meshes/rightarm/bicep-motor-mate_1.stl" scale="0.001 0.001 0.001"/>
      </geometry>
      <material name="opaque22122113"/>
    </visual>
    <collision>
      <origin rpy="0 0 0" xyz="-0.198295 -0.06443 -0.0566"/>
      <geometry>
        <mesh filename="package://dropbear_simplified_urdf/meshes/rightarm/bicep-motor-mate_1.stl" scale="0.001 0.001 0.001"/>
      </geometry>
    </collision>
  </link>
  <link name="RH_bicep_1">
    <inertial>
      <origin rpy="0 0 0" xyz="0.025073949425162723 0.0037579876201125073 0.002524098473845139"/>
      <mass value="0.006005506060977738"/>
      <inertia ixx="0.0" ixy="0.0" ixz="0.0" iyy="3e-06" iyz="0.0" izz="3e-06"/>
    </inertial>
    <visual>
      <origin rpy="0 0 0" xyz="-0.210008 -0.123276 -0.0596"/>
      <geometry>
        <mesh filename="package://dropbear_simplified_urdf/meshes/rightarm/bicep_1.stl" scale="0.001 0.001 0.001"/>
      </geometry>
      <material name="opaque245245245"/>
    </visual>
    <collision>
      <origin rpy="0 0 0" xyz="-0.210008 -0.123276 -0.0596"/>
      <geometry>
        <mesh filename="package://dropbear_simplified_urdf/meshes/rightarm/bicep_1.stl" scale="0.001 0.001 0.001"/>
      </geometry>
    </collision>
  </link>
  <link name="RH_straight-tendon_1">
    <inertial>
      <origin rpy="0 0 0" xyz="0.017202555024465327 -0.030696670853000735 0.01188146583171501"/>
      <mass value="0.03586551706248183"/>
      <inertia ixx="1.4e-05" ixy="1.2e-05" ixz="0.0" iyy="2.2e-05" iyz="0.0" izz="3.1e-05"/>
    </inertial>
    <visual>
      <origin rpy="0 0 0" xyz="-0.259138 -0.132559 -0.0646"/>
      <geometry>
        <mesh filename="package://dropbear_simplified_urdf/meshes/rightarm/straight-tendon_1.stl" scale="0.001 0.001 0.001"/>
      </geometry>
      <material name="opaque191191191"/>
    </visual>
    <collision>
      <origin rpy="0 0 0" xyz="-0.259138 -0.132559 -0.0646"/>
      <geometry>
        <mesh filename="package://dropbear_simplified_urdf/meshes/rightarm/straight-tendon_1.stl" scale="0.001 0.001 0.001"/>
      </geometry>
    </collision>
  </link>
  <link name="RH_elbow-rear-hanger_1">
    <inertial>
      <origin rpy="0 0 0" xyz="0.02838273254466428 0.010873273915161949 -0.01699980031492096"/>
      <mass value="0.02628535609947448"/>
      <inertia ixx="8e-06" ixy="-6e-06" ixz="0.0" iyy="1.5e-05" iyz="0.0" izz="1.6e-05"/>
    </inertial>
    <visual>
      <origin rpy="0 0 0" xyz="-0.269538 -0.089013 -0.0936"/>
      <geometry>
        <mesh filename="package://dropbear_simplified_urdf/meshes/rightarm/elbow-rear-hanger_1.stl" scale="0.001 0.001 0.001"/>
      </geometry>
      <material name="opaque808080"/>
    </visual>
    <collision>
      <origin rpy="0 0 0" xyz="-0.269538 -0.089013 -0.0936"/>
      <geometry>
        <mesh filename="package://dropbear_simplified_urdf/meshes/rightarm/elbow-rear-hanger_1.stl" scale="0.001 0.001 0.001"/>
      </geometry>
    </collision>
  </link>
  <link name="RH_RMD-X8-Pro_MIR8_MIR1__4__1">
    <inertial>
      <origin rpy="0 0 0" xyz="0.03483709188603029 0.029853602123198014 0.009425483341316154"/>
      <mass value="0.1386076860401193"/>
      <inertia ixx="0.000185" ixy="-1e-05" ixz="7e-06" iyy="0.000188" iyz="5e-06" izz="0.00016"/>
    </inertial>
    <visual>
      <origin rpy="0 0 0" xyz="-0.30936 -0.080341 -0.0596"/>
      <geometry>
        <mesh filename="package://dropbear_simplified_urdf/meshes/rightarm/RMD-X8-Pro_MIR8_MIR1__4__1.stl" scale="0.001 0.001 0.001"/>
      </geometry>
      <material name="opaque13110895"/>
    </visual>
    <collision>
      <origin rpy="0 0 0" xyz="-0.30936 -0.080341 -0.0596"/>
      <geometry>
        <mesh filename="package://dropbear_simplified_urdf/meshes/rightarm/RMD-X8-Pro_MIR8_MIR1__4__1.stl" scale="0.001 0.001 0.001"/>
      </geometry>
    </collision>
  </link>
  <link name="RH_shoulder-ex-al-interface_1">
    <inertial>
      <origin rpy="0 0 0" xyz="0.08747987639954247 0.0284217976129367 -3.437234066816508e-09"/>
      <mass value="0.3907290352810328"/>
      <inertia ixx="0.00028" ixy="-0.000184" ixz="0.0" iyy="0.000788" iyz="0.0" izz="0.00084"/>
    </inertial>
    <visual>
      <origin rpy="0 0 0" xyz="-0.384734 -0.124997 -0.0661"/>
      <geometry>
        <mesh filename="package://dropbear_simplified_urdf/meshes/rightarm/shoulder-ex-al-interface_1.stl" scale="0.001 0.001 0.001"/>
      </geometry>
      <material name="opaque22122113"/>
    </visual>
    <collision>
      <origin rpy="0 0 0" xyz="-0.384734 -0.124997 -0.0661"/>
      <geometry>
        <mesh filename="package://dropbear_simplified_urdf/meshes/rightarm/shoulder-ex-al-interface_1.stl" scale="0.001 0.001 0.001"/>
      </geometry>
    </collision>
  </link>
  <joint name="RH_torso_connection" type="revolute">
    <origin rpy="0 0 -1.5707965" xyz="-0.054627 0.160416 0.234212"/>
    <parent link="torso"/>
    <child link="RH_2020_100mm__9__1"/>
    <axis xyz="0.000261 0.0 1.0"/>
    <limit effort="10.0" lower="-3.141593" upper="3.141593" velocity="10.0"/>
  </joint>
  <joint name="RH_pitch" type="continuous">
    <origin rpy="0 0 0" xyz="0.008343 -0.025679 0.05"/>
    <parent link="RH_2020_100mm__9__1"/>
    <child link="RH_RMD-X8-Pro_MIR8_MIR1__1__1"/>
    <axis xyz="0.309017 -0.951057 0.0"/>
  </joint>
  <joint name="RH_roll" type="continuous">
    <origin rpy="0 0 0" xyz="0.09342 0.058744 0.014"/>
    <parent link="RH_RMD-X8-Pro_MIR8_MIR1__1__1"/>
    <child link="RH_RMD-X8-Pro_MIR8_MIR1__3__1"/>
    <axis xyz="0.951057 0.309017 0.0"/>
  </joint>
  <joint name="RH_elbow_joint" type="continuous">
    <origin rpy="0 0 0" xyz="0.096532 0.031365 -0.0095"/>
    <parent link="RH_RMD-X8-Pro_MIR8_MIR1__3__1"/>
    <child link="RH_bicep-motor-mate_1"/>
    <axis xyz="0.0 0.0 -1.0"/>
  </joint>
  <joint name="RH_Revolute 5" type="continuous">
    <origin rpy="0 0 0" xyz="0.011713 0.058846 0.003"/>
    <parent link="RH_bicep-motor-mate_1"/>
    <child link="RH_bicep_1"/>
    <axis xyz="0.0 0.0 1.0"/>
  </joint>
  <joint name="RH_Revolute 6" type="continuous">
    <origin rpy="0 0 0" xyz="0.04913 0.009283 0.005"/>
    <parent link="RH_bicep_1"/>
    <child link="RH_straight-tendon_1"/>
    <axis xyz="0.0 0.0 1.0"/>
  </joint>
  <gazebo>
    <plugin filename="libgazebo_ros_api_plugin.so" name="gazebo_ros"/>
    <joint name="RH_Revolute 7 gz" type="revolute">
      <pose relative_to="RH_RMD-X8-Pro_MIR8_MIR1__3__1">0.145986 0.076614 -0.015322 0 0 0</pose>
      <parent>RH_RMD-X8-Pro_MIR8_MIR1__3__1</parent>
      <child>RH_straight-tendon_1</child>
      <axis>
        <xyz>0 0 1</xyz>
      </axis>
      <limit>
        <lower>-3.142</lower>
        <upper>3.142</upper>
        <effort>10.0</effort>
        <velocity>10.0</velocity>
      </limit>
      <dynamics>
        <damping>0.0</damping>
        <friction>0.0</friction>
      </dynamics>
    </joint>
  </gazebo>
  <joint name="RH_Revolute 8" type="continuous">
    <origin rpy="0 0 0" xyz="0.167775 0.055948 0.0275"/>
    <parent link="RH_RMD-X8-Pro_MIR8_MIR1__3__1"/>
    <child link="RH_elbow-rear-hanger_1"/>
    <axis xyz="0.0 0.0 -1.0"/>
  </joint>
  <joint name="RH_Revolute 9" type="continuous">
    <origin rpy="0 0 0" xyz="0.050222 -0.052218 -0.005"/>
    <parent link="RH_straight-tendon_1"/>
    <child link="RH_RMD-X8-Pro_MIR8_MIR1__4__1"/>
    <axis xyz="0.0 0.0 -1.0"/>
  </joint>
  <gazebo>
    <plugin filename="libgazebo_ros_api_plugin.so" name="gazebo_ros"/>
    <joint name="RH_Revolute 10 gz" type="revolute">
      <pose relative_to="RH_elbow-rear-hanger_1">0.053697 0.025533 -0.034938 0 0 0</pose>
      <parent>RH_elbow-rear-hanger_1</parent>
      <child>RH_RMD-X8-Pro_MIR8_MIR1__4__1</child>
      <axis> 0 0 1 </axis>
      <limit>
        <lower>-3.142</lower>
        <upper>3.142</upper>
        <effort>10.0</effort>
        <velocity>10.0</velocity>
      </limit>
      <dynamics>
        <damping>0.0</damping>
        <friction>0.0</friction>
      </dynamics>
    </joint>
  </gazebo>
  <joint name="RH_wrist_roll" type="continuous">
    <origin rpy="0 0 0" xyz="0.075374 0.044656 0.0065"/>
    <parent link="RH_RMD-X8-Pro_MIR8_MIR1__4__1"/>
    <child link="RH_shoulder-ex-al-interface_1"/>
    <axis xyz="0.951057 0.309017 0.0"/>
  </joint>
  <link name="LH_2020_100mm__9__1">
    <inertial>
      <origin rpy="0 0 0" xyz="-0.0008466746254246146 0.0026057965560190325 -0.04747235208031805"/>
      <mass value="0.15134342423432742"/>
      <inertia ixx="0.000135" ixy="4e-06" ixz="0.0" iyy="0.000123" iyz="-1e-06" izz="6.9e-05"/>
    </inertial>
    <visual>
      <origin rpy="0 0 0" xyz="0.0 0.0 0.0021"/>
      <geometry>
        <mesh filename="package://dropbear_simplified_urdf/meshes/leftarm/2020_100mm__9__1.stl" scale="0.001 0.001 0.001"/>
      </geometry>
      <material name="opaque727161"/>
    </visual>
    <collision>
      <origin rpy="0 0 0" xyz="0.0 0.0 0.0021"/>
      <geometry>
        <mesh filename="package://dropbear_simplified_urdf/meshes/leftarm/2020_100mm__9__1.stl" scale="0.001 0.001 0.001"/>
      </geometry>
    </collision>
  </link>
  <link name="LH_RMD-X8-Pro_MIR8_MIR1__1__1">
    <inertial>
      <origin rpy="0 0 0" xyz="0.03168610209516673 0.03722389945118263 -0.009663941690489952"/>
      <mass value="0.39705688727274907"/>
      <inertia ixx="0.000836" ixy="0.000113" ixz="-0.000101" iyy="0.000815" iyz="-2.7e-05" izz="0.001335"/>
    </inertial>
    <visual>
      <origin rpy="0 0 0" xyz="-0.008343 0.025679 0.0521"/>
      <geometry>
        <mesh filename="package://dropbear_simplified_urdf/meshes/leftarm/RMD-X8-Pro_MIR8_MIR1__1__1.stl" scale="0.001 0.001 0.001"/>
      </geometry>
      <material name="opaque13110895"/>
    </visual>
    <collision>
      <origin rpy="0 0 0" xyz="-0.008343 0.025679 0.0521"/>
      <geometry>
        <mesh filename="package://dropbear_simplified_urdf/meshes/leftarm/RMD-X8-Pro_MIR8_MIR1__1__1.stl" scale="0.001 0.001 0.001"/>
      </geometry>
    </collision>
  </link>
  <link name="LH_RMD-X8-Pro_MIR8_MIR1__3__1">
    <inertial>
      <origin rpy="0 0 0" xyz="0.073833397772971 0.021968775763905476 -0.008042518945865815"/>
      <mass value="0.2600729816837481"/>
      <inertia ixx="0.000377" ixy="-0.000126" ixz="-2.4e-05" iyy="0.00073" iyz="-1.8e-05" izz="0.000813"/>
    </inertial>
    <visual>
      <origin rpy="0 0 0" xyz="-0.101763 -0.033065 0.0661"/>
      <geometry>
        <mesh filename="package://dropbear_simplified_urdf/meshes/leftarm/RMD-X8-Pro_MIR8_MIR1__3__1.stl" scale="0.001 0.001 0.001"/>
      </geometry>
      <material name="opaque13110895"/>
    </visual>
    <collision>
      <origin rpy="0 0 0" xyz="-0.101763 -0.033065 0.0661"/>
      <geometry>
        <mesh filename="package://dropbear_simplified_urdf/meshes/leftarm/RMD-X8-Pro_MIR8_MIR1__3__1.stl" scale="0.001 0.001 0.001"/>
      </geometry>
    </collision>
  </link>
  <link name="LH_bicep-motor-mate_1">
    <inertial>
      <origin rpy="0 0 0" xyz="0.0036413059649407775 0.018293491559330355 0.004857773320266552"/>
      <mass value="0.023400269164045275"/>
      <inertia ixx="1.3e-05" ixy="-2e-06" ixz="0.0" iyy="3e-06" iyz="0.0" izz="1.5e-05"/>
    </inertial>
    <visual>
      <origin rpy="0 0 0" xyz="-0.198295 -0.06443 0.0566"/>
      <geometry>
        <mesh filename="package://dropbear_simplified_urdf/meshes/leftarm/bicep-motor-mate_1.stl" scale="0.001 0.001 0.001"/>
      </geometry>
      <material name="opaque22122113"/>
    </visual>
    <collision>
      <origin rpy="0 0 0" xyz="-0.198295 -0.06443 0.0566"/>
      <geometry>
        <mesh filename="package://dropbear_simplified_urdf/meshes/leftarm/bicep-motor-mate_1.stl" scale="0.001 0.001 0.001"/>
      </geometry>
    </collision>
  </link>
  <link name="LH_bicep_1">
    <inertial>
      <origin rpy="0 0 0" xyz="0.025073949425162723 0.0037579876201125073 -0.002524098473845139"/>
      <mass value="0.006005506060977738"/>
      <inertia ixx="0.0" ixy="0.0" ixz="0.0" iyy="3e-06" iyz="0.0" izz="3e-06"/>
    </inertial>
    <visual>
      <origin rpy="0 0 0" xyz="-0.210008 -0.123276 0.0596"/>
      <geometry>
        <mesh filename="package://dropbear_simplified_urdf/meshes/leftarm/bicep_1.stl" scale="0.001 0.001 0.001"/>
      </geometry>
      <material name="opaque245245245"/>
    </visual>
    <collision>
      <origin rpy="0 0 0" xyz="-0.210008 -0.123276 0.0596"/>
      <geometry>
        <mesh filename="package://dropbear_simplified_urdf/meshes/leftarm/bicep_1.stl" scale="0.001 0.001 0.001"/>
      </geometry>
    </collision>
  </link>
  <link name="LH_straight-tendon_1">
    <inertial>
      <origin rpy="0 0 0" xyz="0.017202555024465327 -0.030696670853000735 -0.01188146583171501"/>
      <mass value="0.03586551706248183"/>
      <inertia ixx="1.4e-05" ixy="1.2e-05" ixz="0.0" iyy="2.2e-05" iyz="0.0" izz="3.1e-05"/>
    </inertial>
    <visual>
      <origin rpy="0 0 0" xyz="-0.259138 -0.132559 0.0646"/>
      <geometry>
        <mesh filename="package://dropbear_simplified_urdf/meshes/leftarm/straight-tendon_1.stl" scale="0.001 0.001 0.001"/>
      </geometry>
      <material name="opaque191191191"/>
    </visual>
    <collision>
      <origin rpy="0 0 0" xyz="-0.259138 -0.132559 0.0646"/>
      <geometry>
        <mesh filename="package://dropbear_simplified_urdf/meshes/leftarm/straight-tendon_1.stl" scale="0.001 0.001 0.001"/>
      </geometry>
    </collision>
  </link>
  <link name="LH_elbow-rear-hanger_1">
    <inertial>
      <origin rpy="0 0 0" xyz="0.02838273254466428 0.010873273915161949 0.01699980031492096"/>
      <mass value="0.02628535609947448"/>
      <inertia ixx="8e-06" ixy="-6e-06" ixz="0.0" iyy="1.5e-05" iyz="0.0" izz="1.6e-05"/>
    </inertial>
    <visual>
      <origin rpy="0 0 0" xyz="-0.269538 -0.089013 0.0936"/>
      <geometry>
        <mesh filename="package://dropbear_simplified_urdf/meshes/leftarm/elbow-rear-hanger_1.stl" scale="0.001 0.001 0.001"/>
      </geometry>
      <material name="opaque808080"/>
    </visual>
    <collision>
      <origin rpy="0 0 0" xyz="-0.269538 -0.089013 0.0936"/>
      <geometry>
        <mesh filename="package://dropbear_simplified_urdf/meshes/leftarm/elbow-rear-hanger_1.stl" scale="0.001 0.001 0.001"/>
      </geometry>
    </collision>
  </link>
  <link name="LH_RMD-X8-Pro_MIR8_MIR1__4__1">
    <inertial>
      <origin rpy="0 0 0" xyz="0.03483709188603029 0.029853602123198014 -0.009425483341316154"/>
      <mass value="0.1386076860401193"/>
      <inertia ixx="0.000185" ixy="-1e-05" ixz="7e-06" iyy="0.000188" iyz="5e-06" izz="0.00016"/>
    </inertial>
    <visual>
      <origin rpy="0 0 0" xyz="-0.30936 -0.080341 0.0596"/>
      <geometry>
        <mesh filename="package://dropbear_simplified_urdf/meshes/leftarm/RMD-X8-Pro_MIR8_MIR1__4__1.stl" scale="0.001 0.001 0.001"/>
      </geometry>
      <material name="opaque13110895"/>
    </visual>
    <collision>
      <origin rpy="0 0 0" xyz="-0.30936 -0.080341 0.0596"/>
      <geometry>
        <mesh filename="package://dropbear_simplified_urdf/meshes/leftarm/RMD-X8-Pro_MIR8_MIR1__4__1.stl" scale="0.001 0.001 0.001"/>
      </geometry>
    </collision>
  </link>
  <link name="LH_shoulder-ex-al-interface_1">
    <inertial>
      <origin rpy="0 0 0" xyz="0.08747987639954247 0.0284217976129367 3.437234066816508e-09"/>
      <mass value="0.3907290352810328"/>
      <inertia ixx="0.00028" ixy="-0.000184" ixz="0.0" iyy="0.000788" iyz="0.0" izz="0.00084"/>
    </inertial>
    <visual>
      <origin rpy="0 0 0" xyz="-0.384734 -0.124997 0.0661"/>
      <geometry>
        <mesh filename="package://dropbear_simplified_urdf/meshes/leftarm/shoulder-ex-al-interface_1.stl" scale="0.001 0.001 0.001"/>
      </geometry>
      <material name="opaque22122113"/>
    </visual>
    <collision>
      <origin rpy="0 0 0" xyz="-0.384734 -0.124997 0.0661"/>
      <geometry>
        <mesh filename="package://dropbear_simplified_urdf/meshes/leftarm/shoulder-ex-al-interface_1.stl" scale="0.001 0.001 0.001"/>
      </geometry>
    </collision>
  </link>
  <joint name="LH_torso_connection" type="revolute">
    <origin rpy="0 0 -1.5707965" xyz="-0.054536 0.160416 -0.114788"/>
    <parent link="torso"/>
    <child link="LH_2020_100mm__9__1"/>
    <axis xyz="0.000261 0.0 -1.0"/>
    <limit effort="10.0" lower="-3.141593" upper="3.141593" velocity="10.0"/>
  </joint>
  <joint name="LH_pitch" type="continuous">
    <origin rpy="0 0 0" xyz="0.008343 -0.025679 -0.05"/>
    <parent link="LH_2020_100mm__9__1"/>
    <child link="LH_RMD-X8-Pro_MIR8_MIR1__1__1"/>
    <axis xyz="0.309017 -0.951057 0.0"/>
  </joint>
  <joint name="LH_roll" type="continuous">
    <origin rpy="0 0 0" xyz="0.09342 0.058744 -0.014"/>
    <parent link="LH_RMD-X8-Pro_MIR8_MIR1__1__1"/>
    <child link="LH_RMD-X8-Pro_MIR8_MIR1__3__1"/>
    <axis xyz="0.951057 0.309017 0.0"/>
  </joint>
  <joint name="LH_elbow_joint" type="continuous">
    <origin rpy="0 0 0" xyz="0.096532 0.031365 0.0095"/>
    <parent link="LH_RMD-X8-Pro_MIR8_MIR1__3__1"/>
    <child link="LH_bicep-motor-mate_1"/>
    <axis xyz="0.0 0.0 -1.0"/>
  </joint>
  <joint name="LH_Revolute 5" type="continuous">
    <origin rpy="0 0 0" xyz="0.011713 0.058846 -0.003"/>
    <parent link="LH_bicep-motor-mate_1"/>
    <child link="LH_bicep_1"/>
    <axis xyz="0.0 0.0 1.0"/>
  </joint>
  <joint name="LH_Revolute 6" type="continuous">
    <origin rpy="0 0 0" xyz="0.04913 0.009283 -0.005"/>
    <parent link="LH_bicep_1"/>
    <child link="LH_straight-tendon_1"/>
    <axis xyz="0.0 0.0 1.0"/>
  </joint>
  <gazebo>
    <plugin filename="libgazebo_ros_api_plugin.so" name="gazebo_ros"/>
    <joint name="LH_Revolute 7 gz" type="revolute">
      <pose relative_to="LH_RMD-X8-Pro_MIR8_MIR1__3__1">0.145986 0.076614 -0.015322 0 0 0</pose>
      <parent>LH_RMD-X8-Pro_MIR8_MIR1__3__1</parent>
      <child>LH_straight-tendon_1</child>
      <axis>
        <xyz>0 0 1</xyz>
      </axis>
      <limit>
        <lower>-3.142</lower>
        <upper>3.142</upper>
        <effort>10.0</effort>
        <velocity>10.0</velocity>
      </limit>
      <dynamics>
        <damping>0.0</damping>
        <friction>0.0</friction>
      </dynamics>
    </joint>
  </gazebo>
  <joint name="LH_Revolute 8" type="continuous">
    <origin rpy="0 0 0" xyz="0.167775 0.055948 -0.0275"/>
    <parent link="LH_RMD-X8-Pro_MIR8_MIR1__3__1"/>
    <child link="LH_elbow-rear-hanger_1"/>
    <axis xyz="0.0 0.0 -1.0"/>
  </joint>
  <joint name="LH_Revolute 9" type="continuous">
    <origin rpy="0 0 0" xyz="0.050222 -0.052218 0.005"/>
    <parent link="LH_straight-tendon_1"/>
    <child link="LH_RMD-X8-Pro_MIR8_MIR1__4__1"/>
    <axis xyz="0.0 0.0 -1.0"/>
  </joint>
  <gazebo>
    <plugin filename="libgazebo_ros_api_plugin.so" name="gazebo_ros"/>
    <joint name="LH_Revolute 10 gz" type="revolute">
      <pose relative_to="LH_elbow-rear-hanger_1">0.053697 0.025533 -0.034938 0 0 0</pose>
      <parent>LH_elbow-rear-hanger_1</parent>
      <child>LH_RMD-X8-Pro_MIR8_MIR1__4__1</child>
      <axis> 0 0 1 </axis>
      <limit>
        <lower>-3.142</lower>
        <upper>3.142</upper>
        <effort>10.0</effort>
        <velocity>10.0</velocity>
      </limit>
      <dynamics>
        <damping>0.0</damping>
        <friction>0.0</friction>
      </dynamics>
    </joint>
  </gazebo>
  <joint name="LH_wrist_roll" type="continuous">
    <origin rpy="0 0 0" xyz="0.075374 0.044656 -0.0065"/>
    <parent link="LH_RMD-X8-Pro_MIR8_MIR1__4__1"/>
    <child link="LH_shoulder-ex-al-interface_1"/>
    <axis xyz="0.951057 0.309017 0.0"/>
  </joint>
  <link name="RL_RMD-X10-S2_MIR4__3_Rotor_1">
    <inertial>
      <origin rpy="0 0 0" xyz="-4.2114800383186157e-07 1.6545859007732755e-05 0.011165715023864597"/>
      <mass value="0.030077996769097937"/>
      <inertia ixx="7e-06" ixy="0.0" ixz="-0.0" iyy="7e-06" iyz="0.0" izz="1e-05"/>
    </inertial>
    <visual>
      <origin rpy="0 0 0" xyz="0.191553 -0.380845 0.16988"/>
      <geometry>
        <mesh filename="package://dropbear_simplified_urdf/meshes/rightleg/RMD-X10-S2_MIR4__3_Rotor_1.stl" scale="0.001 0.001 0.001"/>
      </geometry>
      <material name="opaque727161"/>
    </visual>
    <collision>
      <origin rpy="0 0 0" xyz="0.191553 -0.380845 0.16988"/>
      <geometry>
        <mesh filename="package://dropbear_simplified_urdf/meshes/rightleg/RMD-X10-S2_MIR4__3_Rotor_1.stl" scale="0.001 0.001 0.001"/>
      </geometry>
    </collision>
  </link>
  <link name="RL_RMD-X10-S2_MIR4__3_Stator_1">
    <inertial>
      <origin rpy="0 0 0" xyz="-0.036718214168607155 -0.05423872836967342 0.033683692448425506"/>
      <mass value="0.5483656288061021"/>
      <inertia ixx="0.002044" ixy="-0.000494" ixz="0.000142" iyy="0.001828" iyz="0.000171" izz="0.002663"/>
    </inertial>
    <visual>
      <origin rpy="0 0 0" xyz="0.191553 -0.380845 0.16988"/>
      <geometry>
        <mesh filename="package://dropbear_simplified_urdf/meshes/rightleg/RMD-X10-S2_MIR4__3_Stator_1.stl" scale="0.001 0.001 0.001"/>
      </geometry>
      <material name="opaque727161"/>
    </visual>
    <collision>
      <origin rpy="0 0 0" xyz="0.191553 -0.380845 0.16988"/>
      <geometry>
        <mesh filename="package://dropbear_simplified_urdf/meshes/rightleg/RMD-X10-S2_MIR4__3_Stator_1.stl" scale="0.001 0.001 0.001"/>
      </geometry>
    </collision>
  </link>
  <link name="RL_RMD-X10-S2_MIR4Rotor_1">
    <inertial>
      <origin rpy="0 0 0" xyz="0.004336745411893661 -0.10083451364614476 0.02279900080800254"/>
      <mass value="0.618391872847042"/>
      <inertia ixx="0.006212" ixy="0.000357" ixz="-2e-05" iyy="0.000506" iyz="0.000167" izz="0.00633"/>
    </inertial>
    <visual>
      <origin rpy="0 0 0" xyz="0.263279 -0.282145 0.106399"/>
      <geometry>
        <mesh filename="package://dropbear_simplified_urdf/meshes/rightleg/RMD-X10-S2_MIR4Rotor_1.stl" scale="0.001 0.001 0.001"/>
      </geometry>
      <material name="opaque727161"/>
    </visual>
    <collision>
      <origin rpy="0 0 0" xyz="0.263279 -0.282145 0.106399"/>
      <geometry>
        <mesh filename="package://dropbear_simplified_urdf/meshes/rightleg/RMD-X10-S2_MIR4Rotor_1.stl" scale="0.001 0.001 0.001"/>
      </geometry>
    </collision>
  </link>
  <link name="RL_double-bracket_1">
    <inertial>
      <origin rpy="0 0 0" xyz="-0.0024174004635344193 -0.17065516771979955 -0.026188805978005034"/>
      <mass value="0.5941741295649757"/>
      <inertia ixx="0.006967" ixy="-0.000485" ixz="-4.1e-05" iyy="0.001718" iyz="0.001043" izz="0.006134"/>
    </inertial>
    <visual>
      <origin rpy="0 0 0" xyz="0.141302 -0.364392 0.089867"/>
      <geometry>
        <mesh filename="package://dropbear_simplified_urdf/meshes/rightleg/double-bracket_1.stl" scale="0.001 0.001 0.001"/>
      </geometry>
      <material name="opaque245245245"/>
    </visual>
    <collision>
      <origin rpy="0 0 0" xyz="0.141302 -0.364392 0.089867"/>
      <geometry>
        <mesh filename="package://dropbear_simplified_urdf/meshes/rightleg/double-bracket_1.stl" scale="0.001 0.001 0.001"/>
      </geometry>
    </collision>
  </link>
  <link name="RL_conjstraint-knee-test-oute_1">
    <inertial>
      <origin rpy="0 0 0" xyz="0.0388201387802167 0.0020245681514819616 -0.009921514877255011"/>
      <mass value="0.17273623323347898"/>
      <inertia ixx="0.000316" ixy="-0.000137" ixz="-0.0" iyy="0.000318" iyz="0.0" izz="0.000394"/>
    </inertial>
    <visual>
      <origin rpy="0 0 0" xyz="0.243318 0.012178 0.069894"/>
      <geometry>
        <mesh filename="package://dropbear_simplified_urdf/meshes/rightleg/conjstraint-knee-test-oute_1.stl" scale="0.001 0.001 0.001"/>
      </geometry>
      <material name="opaque191191191"/>
    </visual>
    <collision>
      <origin rpy="0 0 0" xyz="0.243318 0.012178 0.069894"/>
      <geometry>
        <mesh filename="package://dropbear_simplified_urdf/meshes/rightleg/conjstraint-knee-test-oute_1.stl" scale="0.001 0.001 0.001"/>
      </geometry>
    </collision>
  </link>
  <link name="RL_knee-strap-second-test_1">
    <inertial>
      <origin rpy="0 0 0" xyz="0.02289817601670563 -0.05000799500593258 -0.009994439699335583"/>
      <mass value="0.06382003552060014"/>
      <inertia ixx="9.8e-05" ixy="3.6e-05" ixz="1e-06" iyy="3.7e-05" iyz="-2e-06" izz="0.000101"/>
    </inertial>
    <visual>
      <origin rpy="0 0 0" xyz="0.20361 -0.034819 0.069883"/>
      <geometry>
        <mesh filename="package://dropbear_simplified_urdf/meshes/rightleg/knee-strap-second-test_1.stl" scale="0.001 0.001 0.001"/>
      </geometry>
      <material name="opaque245245245"/>
    </visual>
    <collision>
      <origin rpy="0 0 0" xyz="0.20361 -0.034819 0.069883"/>
      <geometry>
        <mesh filename="package://dropbear_simplified_urdf/meshes/rightleg/knee-strap-second-test_1.stl" scale="0.001 0.001 0.001"/>
      </geometry>
    </collision>
  </link>
  <link name="RL_double-bracket-10deg_MIR_MIR_MIR_1">
    <inertial>
      <origin rpy="0 0 0" xyz="-0.023030853980666094 -0.20870609984957944 0.04394857851730673"/>
      <mass value="0.972328284996074"/>
      <inertia ixx="0.01683" ixy="0.001098" ixz="-0.000198" iyy="0.002068" iyz="0.002791" izz="0.017418"/>
    </inertial>
    <visual>
      <origin rpy="0 0 0" xyz="0.157814 0.065197 0.089871"/>
      <geometry>
        <mesh filename="package://dropbear_simplified_urdf/meshes/rightleg/double-bracket-10deg_MIR_MIR_MIR_1.stl" scale="0.001 0.001 0.001"/>
      </geometry>
      <material name="opaque245245245"/>
    </visual>
    <collision>
      <origin rpy="0 0 0" xyz="0.157814 0.065197 0.089871"/>
      <geometry>
        <mesh filename="package://dropbear_simplified_urdf/meshes/rightleg/double-bracket-10deg_MIR_MIR_MIR_1.stl" scale="0.001 0.001 0.001"/>
      </geometry>
    </collision>
  </link>
  <link name="RL_calf-motor-driver-ext_1">
    <inertial>
      <origin rpy="0 0 0" xyz="0.01018087483375632 -0.006406414275960254 -0.010824350415873277"/>
      <mass value="0.03904654588774605"/>
      <inertia ixx="7e-06" ixy="4e-06" ixz="1e-06" iyy="1.4e-05" iyz="-0.0" izz="1.8e-05"/>
    </inertial>
    <visual>
      <origin rpy="0 0 0" xyz="0.212594 0.236458 0.073139"/>
      <geometry>
        <mesh filename="package://dropbear_simplified_urdf/meshes/rightleg/calf-motor-driver-ext_1.stl" scale="0.001 0.001 0.001"/>
      </geometry>
      <material name="opaque2552550"/>
    </visual>
    <collision>
      <origin rpy="0 0 0" xyz="0.212594 0.236458 0.073139"/>
      <geometry>
        <mesh filename="package://dropbear_simplified_urdf/meshes/rightleg/calf-motor-driver-ext_1.stl" scale="0.001 0.001 0.001"/>
      </geometry>
    </collision>
  </link>
  <link name="RL_290mm-tie-rod_v1_1">
    <inertial>
      <origin rpy="0 0 0" xyz="-0.008618850844608478 -0.1441043639671668 0.01627466914432321"/>
      <mass value="0.31671295572679664"/>
      <inertia ixx="0.00297" ixy="-0.000175" ixz="3.1e-05" iyy="0.000108" iyz="0.000506" izz="0.002894"/>
    </inertial>
    <visual>
      <origin rpy="0 0 0" xyz="0.175826 0.256902 0.096784"/>
      <geometry>
        <mesh filename="package://dropbear_simplified_urdf/meshes/rightleg/290mm-tie-rod_v1_1.stl" scale="0.001 0.001 0.001"/>
      </geometry>
      <material name="opaque191191191"/>
    </visual>
    <collision>
      <origin rpy="0 0 0" xyz="0.175826 0.256902 0.096784"/>
      <geometry>
        <mesh filename="package://dropbear_simplified_urdf/meshes/rightleg/290mm-tie-rod_v1_1.stl" scale="0.001 0.001 0.001"/>
      </geometry>
    </collision>
  </link>
  <link name="RL_calf-motor-driver-ext__1__1">
    <inertial>
      <origin rpy="0 0 0" xyz="0.010997941306614883 0.002322003619584123 0.011641556204172841"/>
      <mass value="0.03904654588774605"/>
      <inertia ixx="5e-06" ixy="-1e-06" ixz="-2e-06" iyy="1.6e-05" iyz="0.0" izz="1.8e-05"/>
    </inertial>
    <visual>
      <origin rpy="0 0 0" xyz="0.210465 0.325998 0.016729"/>
      <geometry>
        <mesh filename="package://dropbear_simplified_urdf/meshes/rightleg/calf-motor-driver-ext__1__1.stl" scale="0.001 0.001 0.001"/>
      </geometry>
      <material name="opaque2552550"/>
    </visual>
    <collision>
      <origin rpy="0 0 0" xyz="0.210465 0.325998 0.016729"/>
      <geometry>
        <mesh filename="package://dropbear_simplified_urdf/meshes/rightleg/calf-motor-driver-ext__1__1.stl" scale="0.001 0.001 0.001"/>
      </geometry>
    </collision>
  </link>
  <link name="RL_210mm-tie-rod_v1_1">
    <inertial>
      <origin rpy="0 0 0" xyz="-0.011696719594497779 -0.10121354316624126 0.026926339548267383"/>
      <mass value="0.24352587221730845"/>
      <inertia ixx="0.001287" ixy="-0.000141" ixz="2.5e-05" iyy="6.1e-05" iyz="0.000219" izz="0.001267"/>
    </inertial>
    <visual>
      <origin rpy="0 0 0" xyz="0.170599 0.320333 -0.009872"/>
      <geometry>
        <mesh filename="package://dropbear_simplified_urdf/meshes/rightleg/210mm-tie-rod_v1_1.stl" scale="0.001 0.001 0.001"/>
      </geometry>
      <material name="opaque191191191"/>
    </visual>
    <collision>
      <origin rpy="0 0 0" xyz="0.170599 0.320333 -0.009872"/>
      <geometry>
        <mesh filename="package://dropbear_simplified_urdf/meshes/rightleg/210mm-tie-rod_v1_1.stl" scale="0.001 0.001 0.001"/>
      </geometry>
    </collision>
  </link>
  <link name="RL_basis_left_1">
    <inertial>
      <origin rpy="0 0 0" xyz="-0.00029764813988561456 -0.020222597886624838 0.013552063748571314"/>
      <mass value="0.09371675054362279"/>
      <inertia ixx="6.4e-05" ixy="-0.0" ixz="0.0" iyy="3.3e-05" iyz="4e-06" izz="5.6e-05"/>
    </inertial>
    <visual>
      <origin rpy="0 0 0" xyz="0.146891 0.512935 0.013949"/>
      <geometry>
        <mesh filename="package://dropbear_simplified_urdf/meshes/rightleg/basis_left_1.stl" scale="0.001 0.001 0.001"/>
      </geometry>
      <material name="opaque245245245"/>
    </visual>
    <collision>
      <origin rpy="0 0 0" xyz="0.146891 0.512935 0.013949"/>
      <geometry>
        <mesh filename="package://dropbear_simplified_urdf/meshes/rightleg/basis_left_1.stl" scale="0.001 0.001 0.001"/>
      </geometry>
    </collision>
  </link>
  <link name="RL_heel-bracket_left_1">
    <inertial>
      <origin rpy="0 0 0" xyz="0.012688445147171948 -0.00771159949391742 0.0016067039154728817"/>
      <mass value="0.7069787408674384"/>
      <inertia ixx="0.000698" ixy="0.000121" ixz="-4.2e-05" iyy="0.005471" iyz="-8.5e-05" izz="0.005014"/>
    </inertial>
    <visual>
      <origin rpy="0 0 0" xyz="0.127372 0.550788 -0.002967"/>
      <geometry>
        <mesh filename="package://dropbear_simplified_urdf/meshes/rightleg/heel-bracket_left_1.stl" scale="0.001 0.001 0.001"/>
      </geometry>
      <material name="opaque245245245"/>
    </visual>
    <collision>
      <origin rpy="0 0 0" xyz="0.127372 0.550788 -0.002967"/>
      <geometry>
        <mesh filename="package://dropbear_simplified_urdf/meshes/rightleg/heel-bracket_left_1.stl" scale="0.001 0.001 0.001"/>
      </geometry>
    </collision>
  </link>
  <joint name="RL_leg_connection" type="fixed">
    <origin rpy="0.17453294444444445 0 0" xyz="0.0 0.0 0.0"/>
    <parent link="DumRightLeg_1"/>
    <child link="RL_RMD-X10-S2_MIR4__3_Rotor_1"/>
  </joint>
  <joint name="RL_hip_joint" type="continuous">
    <origin rpy="0 0 0" xyz="0.0 0.0 0.0"/>
    <parent link="RL_RMD-X10-S2_MIR4__3_Rotor_1"/>
    <child link="RL_RMD-X10-S2_MIR4__3_Stator_1"/>
    <axis xyz="0.000261 -0.0 -1.0"/>
  </joint>
  <joint name="RL_knee_joint" type="continuous">
    <origin rpy="0 0 0" xyz="-0.071726 -0.0987 0.063481"/>
    <parent link="RL_RMD-X10-S2_MIR4__3_Stator_1"/>
    <child link="RL_RMD-X10-S2_MIR4Rotor_1"/>
    <axis xyz="-0.000261 0.0 1.0"/>
  </joint>
  <joint name="RL_Revolute 4" type="continuous">
    <origin rpy="0 0 0" xyz="0.050251 -0.016453 0.080013"/>
    <parent link="RL_RMD-X10-S2_MIR4__3_Stator_1"/>
    <child link="RL_double-bracket_1"/>
    <axis xyz="-0.000261 0.0 1.0"/>
  </joint>
  <joint name="RL_Revolute 5" type="continuous">
    <origin rpy="0 0 0" xyz="0.02018 -0.294308 0.036505"/>
    <parent link="RL_RMD-X10-S2_MIR4Rotor_1"/>
    <child link="RL_conjstraint-knee-test-oute_1"/>
    <axis xyz="-0.000261 0.0 1.0"/>
  </joint>
  <gazebo>
    <plugin filename="libgazebo_ros_api_plugin.so" name="gazebo_ros"/>
    <joint name="RL_Revolute 6 gz" type="revolute">
      <pose relative_to="RL_double-bracket_1">-0.002137 -0.329993 0.019999 0 0 0</pose>
      <parent>RL_double-bracket_1</parent>
      <child>RL_conjstraint-knee-test-oute_1</child>
      <axis>
        <xyz>0 0 1</xyz>
      </axis>
      <limit>
        <lower>-3.142</lower>
        <upper>3.142</upper>
        <effort>10.0</effort>
        <velocity>10.0</velocity>
      </limit>
      <dynamics>
        <damping>0.0</damping>
        <friction>0.0</friction>
      </dynamics>
    </joint>
  </gazebo>
  <joint name="RL_Revolute 7" type="continuous">
    <origin rpy="0 0 0" xyz="-0.062308 -0.329573 0.019984"/>
    <parent link="RL_double-bracket_1"/>
    <child link="RL_knee-strap-second-test_1"/>
    <axis xyz="-0.000261 0.0 1.0"/>
  </joint>
  <joint name="RL_Revolute 8" type="continuous">
    <origin rpy="0 0 0" xyz="0.045796 -0.100016 -0.019988"/>
    <parent link="RL_knee-strap-second-test_1"/>
    <child link="RL_double-bracket-10deg_MIR_MIR_MIR_1"/>
    <axis xyz="-0.000261 0.0 1.0"/>
  </joint>
  <gazebo>
    <plugin filename="libgazebo_ros_api_plugin.so" name="gazebo_ros"/>
    <joint name="RL_Revolute 9 gz" type="revolute">
      <pose relative_to="RL_conjstraint-knee-test-oute_1">0.025403 -0.05436 -0.019993 0 0 0</pose>
      <parent>RL_conjstraint-knee-test-oute_1</parent>
      <child>RL_double-bracket-10deg_MIR_MIR_MIR_1</child>
      <axis>
        <xyz> 0 0 1</xyz>
      </axis>
      <limit>
        <lower>-3.142</lower>
        <upper>3.142</upper>
        <effort>10.0</effort>
        <velocity>10.0</velocity>
      </limit>
      <dynamics>
        <damping>0.0</damping>
        <friction>0.0</friction>
      </dynamics>
    </joint>
  </gazebo>
  <joint name="RL_Revolute 10" type="continuous">
    <origin rpy="0 0 0" xyz="-0.05478 -0.171261 0.016732"/>
    <parent link="RL_double-bracket-10deg_MIR_MIR_MIR_1"/>
    <child link="RL_calf-motor-driver-ext_1"/>
    <axis xyz="0.004499 -0.173596 -0.984807"/>
  </joint>
  <joint name="RL_Revolute 11" type="continuous">
    <origin rpy="0 0 0" xyz="0.036768 -0.020444 -0.023645"/>
    <parent link="RL_calf-motor-driver-ext_1"/>
    <child link="RL_290mm-tie-rod_v1_1"/>
    <axis xyz="0.004499 -0.173596 -0.984807"/>
  </joint>
  <joint name="RL_Revolute 12" type="continuous">
    <origin rpy="0 0 0" xyz="-0.052651 -0.260801 0.073142"/>
    <parent link="RL_double-bracket-10deg_MIR_MIR_MIR_1"/>
    <child link="RL_calf-motor-driver-ext__1__1"/>
    <axis xyz="-0.004499 0.173596 0.984807"/>
  </joint>
  <joint name="RL_Revolute 13" type="continuous">
    <origin rpy="0 0 0" xyz="0.039866 0.005665 0.026601"/>
    <parent link="RL_calf-motor-driver-ext__1__1"/>
    <child link="RL_210mm-tie-rod_v1_1"/>
    <axis xyz="-0.004499 0.173596 0.984807"/>
  </joint>
  <joint name="RL_Revolute 14" type="continuous">
    <origin rpy="0 0 0" xyz="0.010923 -0.447738 0.075922"/>
    <parent link="RL_double-bracket-10deg_MIR_MIR_MIR_1"/>
    <child link="RL_basis_left_1"/>
    <axis xyz="0.004499 -0.173596 -0.984807"/>
  </joint>
  <joint name="RL_Revolute 15" type="continuous">
    <origin rpy="0 0 0" xyz="0.019519 -0.037853 0.016916"/>
    <parent link="RL_basis_left_1"/>
    <child link="RL_heel-bracket_left_1"/>
    <axis xyz="0.999931 -0.00994 0.006321"/>
  </joint>
  <gazebo>
    <plugin filename="libgazebo_ros_api_plugin.so" name="gazebo_ros"/>
    <joint name="RL_Revolute 16 gz" type="revolute">
      <pose relative_to="RL_heel-bracket_left_1">-0.067753 0.029044 0.045342 0 0 0</pose>
      <parent>RL_heel-bracket_left_1</parent>
      <child>RL_210mm-tie-rod_v1_1</child>
      <axis>
        <xyz> 0 0 1</xyz>
      </axis>
      <limit>
        <lower>-3.142</lower>
        <upper>3.142</upper>
        <effort>10.0</effort>
        <velocity>10.0</velocity>
      </limit>
      <dynamics>
        <damping>0.0</damping>
        <friction>0.0</friction>
      </dynamics>
    </joint>
  </gazebo>
  <gazebo>
    <plugin filename="libgazebo_ros_api_plugin.so" name="gazebo_ros"/>
    <joint name="RL_Revolute 17 gz" type="revolute">
      <pose relative_to="RL_heel-bracket_left_1">-0.067303 0.011689 -0.05314 0 0 0</pose>
      <parent>RL_heel-bracket_left_1</parent>
      <child>RL_290mm-tie-rod_v1_1</child>
      <axis>
        <xyz> 0 0 1</xyz>
      </axis>
      <limit>
        <lower>-3.142</lower>
        <upper>3.142</upper>
        <effort>10.0</effort>
        <velocity>10.0</velocity>
      </limit>
      <dynamics>
        <damping>0.0</damping>
        <friction>0.0</friction>
      </dynamics>
    </joint>
  </gazebo>
  <link name="LL_RMD-X10-S2_MIR4__3_Rotor_1">
    <inertial>
      <origin rpy="0 0 0" xyz="-4.2114800383186157e-07 1.6545859007732755e-05 -0.011165715023864597"/>
      <mass value="0.030077996769097937"/>
      <inertia ixx="7e-06" ixy="0.0" ixz="-0.0" iyy="7e-06" iyz="0.0" izz="1e-05"/>
    </inertial>
    <visual>
      <origin rpy="0 0 0" xyz="0.191553 -0.380845 -0.16988"/>
      <geometry>
        <mesh filename="package://dropbear_simplified_urdf/meshes/leftleg/RMD-X10-S2_MIR4__3_Rotor_1.stl" scale="0.001 0.001 0.001"/>
      </geometry>
      <material name="opaque727161"/>
    </visual>
    <collision>
      <origin rpy="0 0 0" xyz="0.191553 -0.380845 -0.16988"/>
      <geometry>
        <mesh filename="package://dropbear_simplified_urdf/meshes/leftleg/RMD-X10-S2_MIR4__3_Rotor_1.stl" scale="0.001 0.001 0.001"/>
      </geometry>
    </collision>
  </link>
  <link name="LL_RMD-X10-S2_MIR4__3_Stator_1">
    <inertial>
      <origin rpy="0 0 0" xyz="-0.036718214168607155 -0.05423872836967342 -0.033683692448425506"/>
      <mass value="0.5483656288061021"/>
      <inertia ixx="0.002044" ixy="-0.000494" ixz="0.000142" iyy="0.001828" iyz="0.000171" izz="0.002663"/>
    </inertial>
    <visual>
      <origin rpy="0 0 0" xyz="0.191553 -0.380845 -0.16988"/>
      <geometry>
        <mesh filename="package://dropbear_simplified_urdf/meshes/leftleg/RMD-X10-S2_MIR4__3_Stator_1.stl" scale="0.001 0.001 0.001"/>
      </geometry>
      <material name="opaque727161"/>
    </visual>
    <collision>
      <origin rpy="0 0 0" xyz="0.191553 -0.380845 -0.16988"/>
      <geometry>
        <mesh filename="package://dropbear_simplified_urdf/meshes/leftleg/RMD-X10-S2_MIR4__3_Stator_1.stl" scale="0.001 0.001 0.001"/>
      </geometry>
    </collision>
  </link>
  <link name="LL_RMD-X10-S2_MIR4Rotor_1">
    <inertial>
      <origin rpy="0 0 0" xyz="0.004336745411893661 -0.10083451364614476 -0.02279900080800254"/>
      <mass value="0.618391872847042"/>
      <inertia ixx="0.006212" ixy="0.000357" ixz="-2e-05" iyy="0.000506" iyz="0.000167" izz="0.00633"/>
    </inertial>
    <visual>
      <origin rpy="0 0 0" xyz="0.263279 -0.282145 -0.106399"/>
      <geometry>
        <mesh filename="package://dropbear_simplified_urdf/meshes/leftleg/RMD-X10-S2_MIR4Rotor_1.stl" scale="0.001 0.001 0.001"/>
      </geometry>
      <material name="opaque727161"/>
    </visual>
    <collision>
      <origin rpy="0 0 0" xyz="0.263279 -0.282145 -0.106399"/>
      <geometry>
        <mesh filename="package://dropbear_simplified_urdf/meshes/leftleg/RMD-X10-S2_MIR4Rotor_1.stl" scale="0.001 0.001 0.001"/>
      </geometry>
    </collision>
  </link>
  <link name="LL_double-bracket_1">
    <inertial>
      <origin rpy="0 0 0" xyz="-0.0024174004635344193 -0.17065516771979955 0.026188805978005034"/>
      <mass value="0.5941741295649757"/>
      <inertia ixx="0.006967" ixy="-0.000485" ixz="-4.1e-05" iyy="0.001718" iyz="0.001043" izz="0.006134"/>
    </inertial>
    <visual>
      <origin rpy="0 0 0" xyz="0.141302 -0.364392 -0.089867"/>
      <geometry>
        <mesh filename="package://dropbear_simplified_urdf/meshes/leftleg/double-bracket_1.stl" scale="0.001 0.001 0.001"/>
      </geometry>
      <material name="opaque245245245"/>
    </visual>
    <collision>
      <origin rpy="0 0 0" xyz="0.141302 -0.364392 -0.089867"/>
      <geometry>
        <mesh filename="package://dropbear_simplified_urdf/meshes/leftleg/double-bracket_1.stl" scale="0.001 0.001 0.001"/>
      </geometry>
    </collision>
  </link>
  <link name="LL_conjstraint-knee-test-oute_1">
    <inertial>
      <origin rpy="0 0 0" xyz="0.0388201387802167 0.0020245681514819616 0.009921514877255011"/>
      <mass value="0.17273623323347898"/>
      <inertia ixx="0.000316" ixy="-0.000137" ixz="-0.0" iyy="0.000318" iyz="0.0" izz="0.000394"/>
    </inertial>
    <visual>
      <origin rpy="0 0 0" xyz="0.243318 0.012178 -0.069894"/>
      <geometry>
        <mesh filename="package://dropbear_simplified_urdf/meshes/leftleg/conjstraint-knee-test-oute_1.stl" scale="0.001 0.001 0.001"/>
      </geometry>
      <material name="opaque191191191"/>
    </visual>
    <collision>
      <origin rpy="0 0 0" xyz="0.243318 0.012178 -0.069894"/>
      <geometry>
        <mesh filename="package://dropbear_simplified_urdf/meshes/leftleg/conjstraint-knee-test-oute_1.stl" scale="0.001 0.001 0.001"/>
      </geometry>
    </collision>
  </link>
  <link name="LL_knee-strap-second-test_1">
    <inertial>
      <origin rpy="0 0 0" xyz="0.02289817601670563 -0.05000799500593258 0.009994439699335583"/>
      <mass value="0.06382003552060014"/>
      <inertia ixx="9.8e-05" ixy="3.6e-05" ixz="1e-06" iyy="3.7e-05" iyz="-2e-06" izz="0.000101"/>
    </inertial>
    <visual>
      <origin rpy="0 0 0" xyz="0.20361 -0.034819 -0.069883"/>
      <geometry>
        <mesh filename="package://dropbear_simplified_urdf/meshes/leftleg/knee-strap-second-test_1.stl" scale="0.001 0.001 0.001"/>
      </geometry>
      <material name="opaque245245245"/>
    </visual>
    <collision>
      <origin rpy="0 0 0" xyz="0.20361 -0.034819 -0.069883"/>
      <geometry>
        <mesh filename="package://dropbear_simplified_urdf/meshes/leftleg/knee-strap-second-test_1.stl" scale="0.001 0.001 0.001"/>
      </geometry>
    </collision>
  </link>
  <link name="LL_double-bracket-10deg_MIR_MIR_MIR_1">
    <inertial>
      <origin rpy="0 0 0" xyz="-0.023030853980666094 -0.20870609984957944 -0.04394857851730673"/>
      <mass value="0.972328284996074"/>
      <inertia ixx="0.01683" ixy="0.001098" ixz="-0.000198" iyy="0.002068" iyz="0.002791" izz="0.017418"/>
    </inertial>
    <visual>
      <origin rpy="0 0 0" xyz="0.157814 0.065197 -0.089871"/>
      <geometry>
        <mesh filename="package://dropbear_simplified_urdf/meshes/leftleg/double-bracket-10deg_MIR_MIR_MIR_1.stl" scale="0.001 0.001 0.001"/>
      </geometry>
      <material name="opaque245245245"/>
    </visual>
    <collision>
      <origin rpy="0 0 0" xyz="0.157814 0.065197 -0.089871"/>
      <geometry>
        <mesh filename="package://dropbear_simplified_urdf/meshes/leftleg/double-bracket-10deg_MIR_MIR_MIR_1.stl" scale="0.001 0.001 0.001"/>
      </geometry>
    </collision>
  </link>
  <link name="LL_calf-motor-driver-ext_1">
    <inertial>
      <origin rpy="0 0 0" xyz="0.01018087483375632 -0.006406414275960254 0.010824350415873277"/>
      <mass value="0.03904654588774605"/>
      <inertia ixx="7e-06" ixy="4e-06" ixz="1e-06" iyy="1.4e-05" iyz="-0.0" izz="1.8e-05"/>
    </inertial>
    <visual>
      <origin rpy="0 0 0" xyz="0.212594 0.236458 -0.073139"/>
      <geometry>
        <mesh filename="package://dropbear_simplified_urdf/meshes/leftleg/calf-motor-driver-ext_1.stl" scale="0.001 0.001 0.001"/>
      </geometry>
      <material name="opaque2552550"/>
    </visual>
    <collision>
      <origin rpy="0 0 0" xyz="0.212594 0.236458 -0.073139"/>
      <geometry>
        <mesh filename="package://dropbear_simplified_urdf/meshes/leftleg/calf-motor-driver-ext_1.stl" scale="0.001 0.001 0.001"/>
      </geometry>
    </collision>
  </link>
  <link name="LL_290mm-tie-rod_v1_1">
    <inertial>
      <origin rpy="0 0 0" xyz="-0.008618850844608478 -0.1441043639671668 -0.01627466914432321"/>
      <mass value="0.31671295572679664"/>
      <inertia ixx="0.00297" ixy="-0.000175" ixz="3.1e-05" iyy="0.000108" iyz="0.000506" izz="0.002894"/>
    </inertial>
    <visual>
      <origin rpy="0 0 0" xyz="0.175826 0.256902 -0.096784"/>
      <geometry>
        <mesh filename="package://dropbear_simplified_urdf/meshes/leftleg/290mm-tie-rod_v1_1.stl" scale="0.001 0.001 0.001"/>
      </geometry>
      <material name="opaque191191191"/>
    </visual>
    <collision>
      <origin rpy="0 0 0" xyz="0.175826 0.256902 -0.096784"/>
      <geometry>
        <mesh filename="package://dropbear_simplified_urdf/meshes/leftleg/290mm-tie-rod_v1_1.stl" scale="0.001 0.001 0.001"/>
      </geometry>
    </collision>
  </link>
  <link name="LL_calf-motor-driver-ext__1__1">
    <inertial>
      <origin rpy="0 0 0" xyz="0.010997941306614883 0.002322003619584123 -0.011641556204172841"/>
      <mass value="0.03904654588774605"/>
      <inertia ixx="5e-06" ixy="-1e-06" ixz="-2e-06" iyy="1.6e-05" iyz="0.0" izz="1.8e-05"/>
    </inertial>
    <visual>
      <origin rpy="0 0 0" xyz="0.210465 0.325998 -0.016729"/>
      <geometry>
        <mesh filename="package://dropbear_simplified_urdf/meshes/leftleg/calf-motor-driver-ext__1__1.stl" scale="0.001 0.001 0.001"/>
      </geometry>
      <material name="opaque2552550"/>
    </visual>
    <collision>
      <origin rpy="0 0 0" xyz="0.210465 0.325998 -0.016729"/>
      <geometry>
        <mesh filename="package://dropbear_simplified_urdf/meshes/leftleg/calf-motor-driver-ext__1__1.stl" scale="0.001 0.001 0.001"/>
      </geometry>
    </collision>
  </link>
  <link name="LL_210mm-tie-rod_v1_1">
    <inertial>
      <origin rpy="0 0 0" xyz="-0.011696719594497779 -0.10121354316624126 -0.026926339548267383"/>
      <mass value="0.24352587221730845"/>
      <inertia ixx="0.001287" ixy="-0.000141" ixz="2.5e-05" iyy="6.1e-05" iyz="0.000219" izz="0.001267"/>
    </inertial>
    <visual>
      <origin rpy="0 0 0" xyz="0.170599 0.320333 0.009872"/>
      <geometry>
        <mesh filename="package://dropbear_simplified_urdf/meshes/leftleg/210mm-tie-rod_v1_1.stl" scale="0.001 0.001 0.001"/>
      </geometry>
      <material name="opaque191191191"/>
    </visual>
    <collision>
      <origin rpy="0 0 0" xyz="0.170599 0.320333 0.009872"/>
      <geometry>
        <mesh filename="package://dropbear_simplified_urdf/meshes/leftleg/210mm-tie-rod_v1_1.stl" scale="0.001 0.001 0.001"/>
      </geometry>
    </collision>
  </link>
  <link name="LL_basis_left_1">
    <inertial>
      <origin rpy="0 0 0" xyz="-0.00029764813988561456 -0.020222597886624838 -0.013552063748571314"/>
      <mass value="0.09371675054362279"/>
      <inertia ixx="6.4e-05" ixy="-0.0" ixz="0.0" iyy="3.3e-05" iyz="4e-06" izz="5.6e-05"/>
    </inertial>
    <visual>
      <origin rpy="0 0 0" xyz="0.146891 0.512935 -0.013949"/>
      <geometry>
        <mesh filename="package://dropbear_simplified_urdf/meshes/leftleg/basis_left_1.stl" scale="0.001 0.001 0.001"/>
      </geometry>
      <material name="opaque245245245"/>
    </visual>
    <collision>
      <origin rpy="0 0 0" xyz="0.146891 0.512935 -0.013949"/>
      <geometry>
        <mesh filename="package://dropbear_simplified_urdf/meshes/leftleg/basis_left_1.stl" scale="0.001 0.001 0.001"/>
      </geometry>
    </collision>
  </link>
  <link name="LL_heel-bracket_left_1">
    <inertial>
      <origin rpy="0 0 0" xyz="0.012688445147171948 -0.00771159949391742 -0.0016067039154728817"/>
      <mass value="0.7069787408674384"/>
      <inertia ixx="0.000698" ixy="0.000121" ixz="-4.2e-05" iyy="0.005471" iyz="-8.5e-05" izz="0.005014"/>
    </inertial>
    <visual>
      <origin rpy="0 0 0" xyz="0.127372 0.550788 0.002967"/>
      <geometry>
        <mesh filename="package://dropbear_simplified_urdf/meshes/leftleg/heel-bracket_left_1.stl" scale="0.001 0.001 0.001"/>
      </geometry>
      <material name="opaque245245245"/>
    </visual>
    <collision>
      <origin rpy="0 0 0" xyz="0.127372 0.550788 0.002967"/>
      <geometry>
        <mesh filename="package://dropbear_simplified_urdf/meshes/leftleg/heel-bracket_left_1.stl" scale="0.001 0.001 0.001"/>
      </geometry>
    </collision>
  </link>
  <joint name="LL_leg_connection" type="fixed">
    <origin rpy="-0.17453294444444445 0 0" xyz="0.0 0.0 0.0"/>
    <parent link="DumLeftLeg_1"/>
    <child link="LL_RMD-X10-S2_MIR4__3_Rotor_1"/>
  </joint>
  <joint name="LL_hip_joint" type="continuous">
    <origin rpy="0 0 0" xyz="0.0 0.0 -0.0"/>
    <parent link="LL_RMD-X10-S2_MIR4__3_Rotor_1"/>
    <child link="LL_RMD-X10-S2_MIR4__3_Stator_1"/>
    <axis xyz="0.000261 -0.0 -1.0"/>
  </joint>
  <joint name="LL_knee_joint" type="continuous">
    <origin rpy="0 0 0" xyz="-0.071726 -0.0987 -0.063481"/>
    <parent link="LL_RMD-X10-S2_MIR4__3_Stator_1"/>
    <child link="LL_RMD-X10-S2_MIR4Rotor_1"/>
    <axis xyz="-0.000261 0.0 1.0"/>
  </joint>
  <joint name="LL_Revolute 4" type="continuous">
    <origin rpy="0 0 0" xyz="0.050251 -0.016453 -0.080013"/>
    <parent link="LL_RMD-X10-S2_MIR4__3_Stator_1"/>
    <child link="LL_double-bracket_1"/>
    <axis xyz="-0.000261 0.0 1.0"/>
  </joint>
  <joint name="LL_Revolute 5" type="continuous">
    <origin rpy="0 0 0" xyz="0.02018 -0.294308 -0.036505"/>
    <parent link="LL_RMD-X10-S2_MIR4Rotor_1"/>
    <child link="LL_conjstraint-knee-test-oute_1"/>
    <axis xyz="-0.000261 0.0 1.0"/>
  </joint>
  <gazebo>
    <plugin filename="libgazebo_ros_api_plugin.so" name="gazebo_ros"/>
    <joint name="LL_Revolute 6 gz" type="revolute">
      <pose relative_to="LL_double-bracket_1">-0.002137 -0.329993 -0.019999 0 0 0</pose>
      <parent>LL_double-bracket_1</parent>
      <child>LL_conjstraint-knee-test-oute_1</child>
      <axis>
        <xyz>0 0 1</xyz>
      </axis>
      <limit>
        <lower>-3.142</lower>
        <upper>3.142</upper>
        <effort>10.0</effort>
        <velocity>10.0</velocity>
      </limit>
      <dynamics>
        <damping>0.0</damping>
        <friction>0.0</friction>
      </dynamics>
    </joint>
  </gazebo>
  <joint name="LL_Revolute 7" type="continuous">
    <origin rpy="0 0 0" xyz="-0.062308 -0.329573 -0.019984"/>
    <parent link="LL_double-bracket_1"/>
    <child link="LL_knee-strap-second-test_1"/>
    <axis xyz="-0.000261 0.0 1.0"/>
  </joint>
  <joint name="LL_Revolute 8" type="continuous">
    <origin rpy="0 0 0" xyz="0.045796 -0.100016 0.019988"/>
    <parent link="LL_knee-strap-second-test_1"/>
    <child link="LL_double-bracket-10deg_MIR_MIR_MIR_1"/>
    <axis xyz="-0.000261 0.0 1.0"/>
  </joint>
  <gazebo>
    <plugin filename="libgazebo_ros_api_plugin.so" name="gazebo_ros"/>
    <joint name="LL_Revolute 9 gz" type="revolute">
      <pose relative_to="LL_conjstraint-knee-test-oute_1">0.025403 -0.05436 0.019993 0 0 0</pose>
      <parent>LL_conjstraint-knee-test-oute_1</parent>
      <child>LL_double-bracket-10deg_MIR_MIR_MIR_1</child>
      <axis>
        <xyz> 0 0 1</xyz>
      </axis>
      <limit>
        <lower>-3.142</lower>
        <upper>3.142</upper>
        <effort>10.0</effort>
        <velocity>10.0</velocity>
      </limit>
      <dynamics>
        <damping>0.0</damping>
        <friction>0.0</friction>
      </dynamics>
    </joint>
  </gazebo>
  <joint name="LL_Revolute 10" type="continuous">
    <origin rpy="0 0 0" xyz="-0.05478 -0.171261 -0.016732"/>
    <parent link="LL_double-bracket-10deg_MIR_MIR_MIR_1"/>
    <child link="LL_calf-motor-driver-ext_1"/>
    <axis xyz="0.004499 -0.173596 -0.984807"/>
  </joint>
  <joint name="LL_Revolute 11" type="continuous">
    <origin rpy="0 0 0" xyz="0.036768 -0.020444 0.023645"/>
    <parent link="LL_calf-motor-driver-ext_1"/>
    <child link="LL_290mm-tie-rod_v1_1"/>
    <axis xyz="0.004499 -0.173596 -0.984807"/>
  </joint>
  <joint name="LL_Revolute 12" type="continuous">
    <origin rpy="0 0 0" xyz="-0.052651 -0.260801 -0.073142"/>
    <parent link="LL_double-bracket-10deg_MIR_MIR_MIR_1"/>
    <child link="LL_calf-motor-driver-ext__1__1"/>
    <axis xyz="-0.004499 0.173596 0.984807"/>
  </joint>
  <joint name="LL_Revolute 13" type="continuous">
    <origin rpy="0 0 0" xyz="0.039866 0.005665 -0.026601"/>
    <parent link="LL_calf-motor-driver-ext__1__1"/>
    <child link="LL_210mm-tie-rod_v1_1"/>
    <axis xyz="-0.004499 0.173596 0.984807"/>
  </joint>
  <joint name="LL_Revolute 14" type="continuous">
    <origin rpy="0 0 0" xyz="0.010923 -0.447738 -0.075922"/>
    <parent link="LL_double-bracket-10deg_MIR_MIR_MIR_1"/>
    <child link="LL_basis_left_1"/>
    <axis xyz="0.004499 -0.173596 -0.984807"/>
  </joint>
  <joint name="LL_Revolute 15" type="continuous">
    <origin rpy="0 0 0" xyz="0.019519 -0.037853 -0.016916"/>
    <parent link="LL_basis_left_1"/>
    <child link="LL_heel-bracket_left_1"/>
    <axis xyz="0.999931 -0.00994 0.006321"/>
  </joint>
  <gazebo>
    <plugin filename="libgazebo_ros_api_plugin.so" name="gazebo_ros"/>
    <joint name="LL_Revolute 16 gz" type="revolute">
      <pose relative_to="LL_heel-bracket_left_1">-0.067753 0.029044 -0.045342 0 0 0</pose>
      <parent>LL_heel-bracket_left_1</parent>
      <child>LL_210mm-tie-rod_v1_1</child>
      <axis>
        <xyz> 0 0 1</xyz>
      </axis>
      <limit>
        <lower>-3.142</lower>
        <upper>3.142</upper>
        <effort>10.0</effort>
        <velocity>10.0</velocity>
      </limit>
      <dynamics>
        <damping>0.0</damping>
        <friction>0.0</friction>
      </dynamics>
    </joint>
  </gazebo>
  <gazebo>
    <plugin filename="libgazebo_ros_api_plugin.so" name="gazebo_ros"/>
    <joint name="LL_Revolute 17 gz" type="revolute">
      <pose relative_to="LL_heel-bracket_left_1">-0.067303 0.011689 0.05314 0 0 0</pose>
      <parent>LL_heel-bracket_left_1</parent>
      <child>LL_290mm-tie-rod_v1_1</child>
      <axis>
        <xyz> 0 0 1</xyz>
      </axis>
      <limit>
        <lower>-3.142</lower>
        <upper>3.142</upper>
        <effort>10.0</effort>
        <velocity>10.0</velocity>
      </limit>
      <dynamics>
        <damping>0.0</damping>
        <friction>0.0</friction>
      </dynamics>
    </joint>
  </gazebo>
</robot>
