<?xml version="1.0" ?>
<!-- =================================================================================== -->
<!-- |    This document was autogenerated by xacro from urdf/dropbear_simplified.urdf.xacro | -->
<!-- |    EDITING THIS FILE BY HAND IS NOT RECOMMENDED                                 | -->
<!-- =================================================================================== -->
<robot xmlns:xacro="http://www.ros.org/wiki/xacro" name="humanoid">
  <!-- Constants -->
  <!-- Head xacro -->
  <!-- Torso xacro -->
  <material name="silver_default">
    <color rgba="0.700 0.700 0.700 1.000"/>
  </material>
  <material name="opaque727161">
    <color rgba="0.2823529411764706 0.2784313725490196 0.23921568627450981 1.0"/>
  </material>
  <material name="opaque2550255">
    <color rgba="1.0 0.0 1.0 1.0"/>
  </material>
  <material name="opaque245245245">
    <color rgba="0.9607843137254902 0.9607843137254902 0.9607843137254902 1.0"/>
  </material>
  <material name="opaque20400">
    <color rgba="0.8 0.0 0.0 1.0"/>
  </material>
  <material name="opaque2551530">
    <color rgba="1.0 0.6 0.0 1.0"/>
  </material>
  <material name="opaque22122113">
    <color rgba="0.8666666666666667 0.8666666666666667 0.050980392156862744 1.0"/>
  </material>
  <material name="opaque191191191">
    <color rgba="0.7490196078431373 0.7490196078431373 0.7490196078431373 1.0"/>
  </material>
  <material name="opaque252525">
    <color rgba="0.09803921568627451 0.09803921568627451 0.09803921568627451 1.0"/>
  </material>
  <material name="opaque0125168">
    <color rgba="0.0 0.49019607843137253 0.6588235294117647 1.0"/>
  </material>
  <material name="opaque2552550">
    <color rgba="1.0 1.0 0.0 1.0"/>
  </material>
  <material name="opaque13110895">
    <color rgba="0.5137254901960784 0.4235294117647059 0.37254901960784315 1.0"/>
  </material>
  <material name="powder_coat_green">
    <color rgba="0.26666666666666666 0.5882352941176471 0.2823529411764706 0.0"/>
  </material>
  <material name="opaque808080">
    <color rgba="0.3137254901960784 0.3137254901960784 0.3137254901960784 1.0"/>
  </material>
  <material name="opaque25514347">
    <color rgba="1.0 0.5607843137254902 0.1843137254901961 1.0"/>
  </material>
  <!-- Waist xacro -->
  <!-- Arm xacro -->
  <!-- Leg Xacro -->
  <!-- World Link -->
  <link name="sim_world"/>
  <!-- Torso macro -->
  <link name="torso">
    <inertial>
      <origin xyz="-0.03675640917673825 0.10469671997794947 0.060052559811593326" rpy="0 0 0"/>
      <mass value="3.2595669741313733"/>
      <inertia ixx="0.075048" iyy="0.064931" izz="0.077575" ixy="0.004011" iyz="0.00017" ixz="3.6e-05"/>
    </inertial>
    <visual>
      <origin xyz="0 0 0" rpy="0 0 0"/>
      <geometry>
        <mesh filename="package://dropbear_simplified_urdf/meshes/torso/base_link.stl" scale="0.001 0.001 0.001"/>
      </geometry>
      <material name="opaque727161"/>
    </visual>
    <collision>
      <origin xyz="0 0 0" rpy="0 0 0"/>
      <geometry>
        <mesh filename="package://dropbear_simplified_urdf/meshes/torso/base_link.stl" scale="0.001 0.001 0.001"/>
      </geometry>
    </collision>
  </link>
  <!-- base_link to world joint -->
  <joint name="base_link_sim_world_joint" type="fixed">
    <origin xyz="0.0 0.0 1.2" rpy="1.5707965 0.0 0.0"/>
    <parent link="sim_world"/>
    <child link="torso"/>
  </joint>
  <!-- Head -->
  <link name="head_center-bracket2_1">
    <inertial>
      <origin xyz="3.8346437243874654e-05 0.028284627969764248 -0.09750810940579985" rpy="0 0 0"/>
      <mass value="0.9900409412989982"/>
      <inertia ixx="0.003998" iyy="0.00721" izz="0.004001" ixy="-0.0" iyz="2e-06" ixz="2e-06"/>
    </inertial>
    <visual>
      <origin xyz="-0.283942 0.18654 -0.126791" rpy="0 0 0"/>
      <geometry>
        <mesh filename="package://dropbear_simplified_urdf/meshes/head/center-bracket2_1.stl" scale="0.001 0.001 0.001"/>
      </geometry>
      <material name="opaque22122113"/>
    </visual>
    <collision>
      <origin xyz="-0.283942 0.18654 -0.126791" rpy="0 0 0"/>
      <geometry>
        <mesh filename="package://dropbear_simplified_urdf/meshes/head/center-bracket2_1.stl" scale="0.001 0.001 0.001"/>
      </geometry>
    </collision>
  </link>
  <link name="head_5mm-ujoint-base__5__1">
    <inertial>
      <origin xyz="-3.06424356499857e-07 -0.0018028909754423672 -4.006902962760961e-07" rpy="0 0 0"/>
      <mass value="0.0019034168312865901"/>
      <inertia ixx="0.0" iyy="0.0" izz="0.0" ixy="0.0" iyz="-0.0" ixz="-0.0"/>
    </inertial>
    <visual>
      <origin xyz="-0.308942 0.12754 -0.129291" rpy="0 0 0"/>
      <geometry>
        <mesh filename="package://dropbear_simplified_urdf/meshes/head/5mm-ujoint-base__5__1.stl" scale="0.001 0.001 0.001"/>
      </geometry>
      <material name="opaque191191191"/>
    </visual>
    <collision>
      <origin xyz="-0.308942 0.12754 -0.129291" rpy="0 0 0"/>
      <geometry>
        <mesh filename="package://dropbear_simplified_urdf/meshes/head/5mm-ujoint-base__5__1.stl" scale="0.001 0.001 0.001"/>
      </geometry>
    </collision>
  </link>
  <link name="head_5mm-ujoint-base__2__1">
    <inertial>
      <origin xyz="-2.8817588032525876e-07 -0.001802890975445226 -4.730412566378295e-07" rpy="0 0 0"/>
      <mass value="0.0019034168312865901"/>
      <inertia ixx="0.0" iyy="0.0" izz="0.0" ixy="-0.0" iyz="0.0" ixz="-0.0"/>
    </inertial>
    <visual>
      <origin xyz="-0.258942 0.12754 -0.129291" rpy="0 0 0"/>
      <geometry>
        <mesh filename="package://dropbear_simplified_urdf/meshes/head/5mm-ujoint-base__2__1.stl" scale="0.001 0.001 0.001"/>
      </geometry>
      <material name="opaque191191191"/>
    </visual>
    <collision>
      <origin xyz="-0.258942 0.12754 -0.129291" rpy="0 0 0"/>
      <geometry>
        <mesh filename="package://dropbear_simplified_urdf/meshes/head/5mm-ujoint-base__2__1.stl" scale="0.001 0.001 0.001"/>
      </geometry>
    </collision>
  </link>
  <link name="head_5mm-ujoint-base__1__1">
    <inertial>
      <origin xyz="2.425383274773374e-07 -0.0018028909754462807 1.629635675003691e-07" rpy="0 0 0"/>
      <mass value="0.0019034168312865901"/>
      <inertia ixx="0.0" iyy="0.0" izz="0.0" ixy="0.0" iyz="0.0" ixz="0.0"/>
    </inertial>
    <visual>
      <origin xyz="-0.383044 0.12754 -0.000941" rpy="0 0 0"/>
      <geometry>
        <mesh filename="package://dropbear_simplified_urdf/meshes/head/5mm-ujoint-base__1__1.stl" scale="0.001 0.001 0.001"/>
      </geometry>
      <material name="opaque191191191"/>
    </visual>
    <collision>
      <origin xyz="-0.383044 0.12754 -0.000941" rpy="0 0 0"/>
      <geometry>
        <mesh filename="package://dropbear_simplified_urdf/meshes/head/5mm-ujoint-base__1__1.stl" scale="0.001 0.001 0.001"/>
      </geometry>
    </collision>
  </link>
  <link name="head_5mm-ujoint-base_1">
    <inertial>
      <origin xyz="2.168950684611204e-07 -0.0018028909754433942 -5.184531954444127e-08" rpy="0 0 0"/>
      <mass value="0.0019034168312865901"/>
      <inertia ixx="0.0" iyy="0.0" izz="0.0" ixy="0.0" iyz="-0.0" ixz="-0.0"/>
    </inertial>
    <visual>
      <origin xyz="-0.358044 0.12754 0.04236" rpy="0 0 0"/>
      <geometry>
        <mesh filename="package://dropbear_simplified_urdf/meshes/head/5mm-ujoint-base_1.stl" scale="0.001 0.001 0.001"/>
      </geometry>
      <material name="opaque191191191"/>
    </visual>
    <collision>
      <origin xyz="-0.358044 0.12754 0.04236" rpy="0 0 0"/>
      <geometry>
        <mesh filename="package://dropbear_simplified_urdf/meshes/head/5mm-ujoint-base_1.stl" scale="0.001 0.001 0.001"/>
      </geometry>
    </collision>
  </link>
  <link name="head_5mm-ujoint-base__3__1">
    <inertial>
      <origin xyz="1.9223092723175128e-07 -0.0018028909754772282 -3.93148458163739e-08" rpy="0 0 0"/>
      <mass value="0.0019034168312865901"/>
      <inertia ixx="0.0" iyy="0.0" izz="0.0" ixy="-0.0" iyz="-0.0" ixz="0.0"/>
    </inertial>
    <visual>
      <origin xyz="-0.209839 0.12754 0.04236" rpy="0 0 0"/>
      <geometry>
        <mesh filename="package://dropbear_simplified_urdf/meshes/head/5mm-ujoint-base__3__1.stl" scale="0.001 0.001 0.001"/>
      </geometry>
      <material name="opaque191191191"/>
    </visual>
    <collision>
      <origin xyz="-0.209839 0.12754 0.04236" rpy="0 0 0"/>
      <geometry>
        <mesh filename="package://dropbear_simplified_urdf/meshes/head/5mm-ujoint-base__3__1.stl" scale="0.001 0.001 0.001"/>
      </geometry>
    </collision>
  </link>
  <link name="head_5mm-ujoint-base__4__1">
    <inertial>
      <origin xyz="1.6798179230947952e-07 -0.0018028909754432276 1.620475144446928e-07" rpy="0 0 0"/>
      <mass value="0.0019034168312865901"/>
      <inertia ixx="0.0" iyy="0.0" izz="0.0" ixy="0.0" iyz="0.0" ixz="-0.0"/>
    </inertial>
    <visual>
      <origin xyz="-0.184839 0.12754 -0.000941" rpy="0 0 0"/>
      <geometry>
        <mesh filename="package://dropbear_simplified_urdf/meshes/head/5mm-ujoint-base__4__1.stl" scale="0.001 0.001 0.001"/>
      </geometry>
      <material name="opaque191191191"/>
    </visual>
    <collision>
      <origin xyz="-0.184839 0.12754 -0.000941" rpy="0 0 0"/>
      <geometry>
        <mesh filename="package://dropbear_simplified_urdf/meshes/head/5mm-ujoint-base__4__1.stl" scale="0.001 0.001 0.001"/>
      </geometry>
    </collision>
  </link>
  <link name="head_u-joint-center__6__1">
    <inertial>
      <origin xyz="-0.004226364224141799 -3.831484210459202e-08 -0.002671317839583104" rpy="0 0 0"/>
      <mass value="0.0009727380393185158"/>
      <inertia ixx="0.0" iyy="0.0" izz="0.0" ixy="0.0" iyz="-0.0" ixz="-0.0"/>
    </inertial>
    <visual>
      <origin xyz="-0.313168 0.11854 -0.131962" rpy="0 0 0"/>
      <geometry>
        <mesh filename="package://dropbear_simplified_urdf/meshes/head/u-joint-center__6__1.stl" scale="0.001 0.001 0.001"/>
      </geometry>
      <material name="opaque191191191"/>
    </visual>
    <collision>
      <origin xyz="-0.313168 0.11854 -0.131962" rpy="0 0 0"/>
      <geometry>
        <mesh filename="package://dropbear_simplified_urdf/meshes/head/u-joint-center__6__1.stl" scale="0.001 0.001 0.001"/>
      </geometry>
    </collision>
  </link>
  <link name="head_leadscrew__4___1">
    <inertial>
      <origin xyz="0.008090913802082988 0.05478640097420695 -0.015967801610564242" rpy="0 0 0"/>
      <mass value="0.041870324726393286"/>
      <inertia ixx="3.6e-05" iyy="8e-06" izz="3.2e-05" ixy="-7e-06" iyz="1.3e-05" ixz="3e-06"/>
    </inertial>
    <visual>
      <origin xyz="-0.312784 0.122047 -0.123213" rpy="0 0 0"/>
      <geometry>
        <mesh filename="package://dropbear_simplified_urdf/meshes/head/leadscrew__4___1.stl" scale="0.001 0.001 0.001"/>
      </geometry>
      <material name="opaque191191191"/>
    </visual>
    <collision>
      <origin xyz="-0.312784 0.122047 -0.123213" rpy="0 0 0"/>
      <geometry>
        <mesh filename="package://dropbear_simplified_urdf/meshes/head/leadscrew__4___1.stl" scale="0.001 0.001 0.001"/>
      </geometry>
    </collision>
  </link>
  <link name="head_screw-reciever_1">
    <inertial>
      <origin xyz="0.007426461752526592 0.03190986660772625 -0.013718757939493342" rpy="0 0 0"/>
      <mass value="0.04298268184364639"/>
      <inertia ixx="5.2e-05" iyy="1.2e-05" izz="4.7e-05" ixy="-1e-05" iyz="1.8e-05" ixz="4e-06"/>
    </inertial>
    <visual>
      <origin xyz="-0.310823 0.110454 -0.125815" rpy="0 0 0"/>
      <geometry>
        <mesh filename="package://dropbear_simplified_urdf/meshes/head/screw-reciever_1.stl" scale="0.001 0.001 0.001"/>
      </geometry>
      <material name="opaque25514347"/>
    </visual>
    <collision>
      <origin xyz="-0.310823 0.110454 -0.125815" rpy="0 0 0"/>
      <geometry>
        <mesh filename="package://dropbear_simplified_urdf/meshes/head/screw-reciever_1.stl" scale="0.001 0.001 0.001"/>
      </geometry>
    </collision>
  </link>
  <link name="head_u-joint-center__1__1">
    <inertial>
      <origin xyz="-0.0049303029733915316 1.0162823491088879e-07 -0.0008343581172669257" rpy="0 0 0"/>
      <mass value="0.0009727380393185158"/>
      <inertia ixx="0.0" iyy="0.0" izz="0.0" ixy="0.0" iyz="-0.0" ixz="-0.0"/>
    </inertial>
    <visual>
      <origin xyz="-0.263872 0.11854 -0.130125" rpy="0 0 0"/>
      <geometry>
        <mesh filename="package://dropbear_simplified_urdf/meshes/head/u-joint-center__1__1.stl" scale="0.001 0.001 0.001"/>
      </geometry>
      <material name="opaque191191191"/>
    </visual>
    <collision>
      <origin xyz="-0.263872 0.11854 -0.130125" rpy="0 0 0"/>
      <geometry>
        <mesh filename="package://dropbear_simplified_urdf/meshes/head/u-joint-center__1__1.stl" scale="0.001 0.001 0.001"/>
      </geometry>
    </collision>
  </link>
  <link name="head_leadscrew__5___1__1">
    <inertial>
      <origin xyz="-0.010697780740818036 0.0484324768709017 -0.02935746116647918" rpy="0 0 0"/>
      <mass value="0.04187032472639328"/>
      <inertia ixx="3.6e-05" iyy="8e-06" izz="3.2e-05" ixy="7e-06" iyz="1.3e-05" ixz="-3e-06"/>
    </inertial>
    <visual>
      <origin xyz="-0.257696 0.115673 -0.136655" rpy="0 0 0"/>
      <geometry>
        <mesh filename="package://dropbear_simplified_urdf/meshes/head/leadscrew__5___1__1.stl" scale="0.001 0.001 0.001"/>
      </geometry>
      <material name="opaque191191191"/>
    </visual>
    <collision>
      <origin xyz="-0.257696 0.115673 -0.136655" rpy="0 0 0"/>
      <geometry>
        <mesh filename="package://dropbear_simplified_urdf/meshes/head/leadscrew__5___1__1.stl" scale="0.001 0.001 0.001"/>
      </geometry>
    </collision>
  </link>
  <link name="head_screw-reciever__4__1">
    <inertial>
      <origin xyz="-0.0074348154663718136 0.03193576048858819 -0.013691785153830918" rpy="0 0 0"/>
      <mass value="0.042982681843648216"/>
      <inertia ixx="5.2e-05" iyy="1.2e-05" izz="4.7e-05" ixy="1e-05" iyz="1.8e-05" ixz="-4e-06"/>
    </inertial>
    <visual>
      <origin xyz="-0.257058 0.110451 -0.125823" rpy="0 0 0"/>
      <geometry>
        <mesh filename="package://dropbear_simplified_urdf/meshes/head/screw-reciever__4__1.stl" scale="0.001 0.001 0.001"/>
      </geometry>
      <material name="opaque25514347"/>
    </visual>
    <collision>
      <origin xyz="-0.257058 0.110451 -0.125823" rpy="0 0 0"/>
      <geometry>
        <mesh filename="package://dropbear_simplified_urdf/meshes/head/screw-reciever__4__1.stl" scale="0.001 0.001 0.001"/>
      </geometry>
    </collision>
  </link>
  <link name="head_u-joint-center__3__1">
    <inertial>
      <origin xyz="-0.004978762007825044 -4.937069579546982e-08 0.00046206432615511966" rpy="0 0 0"/>
      <mass value="0.0009727380393185158"/>
      <inertia ixx="0.0" iyy="0.0" izz="0.0" ixy="0.0" iyz="0.0" ixz="0.0"/>
    </inertial>
    <visual>
      <origin xyz="-0.388023 0.11854 -0.000479" rpy="0 0 0"/>
      <geometry>
        <mesh filename="package://dropbear_simplified_urdf/meshes/head/u-joint-center__3__1.stl" scale="0.001 0.001 0.001"/>
      </geometry>
      <material name="opaque191191191"/>
    </visual>
    <collision>
      <origin xyz="-0.388023 0.11854 -0.000479" rpy="0 0 0"/>
      <geometry>
        <mesh filename="package://dropbear_simplified_urdf/meshes/head/u-joint-center__3__1.stl" scale="0.001 0.001 0.001"/>
      </geometry>
    </collision>
  </link>
  <link name="head_leadscrew__1___1__1">
    <inertial>
      <origin xyz="-0.012356712790251911 0.048365296241757866 0.028810741379527917" rpy="0 0 0"/>
      <mass value="0.04187032472639327"/>
      <inertia ixx="3.6e-05" iyy="8e-06" izz="3.2e-05" ixy="8e-06" iyz="-1.2e-05" ixz="3e-06"/>
    </inertial>
    <visual>
      <origin xyz="-0.382356 0.115621 0.006475" rpy="0 0 0"/>
      <geometry>
        <mesh filename="package://dropbear_simplified_urdf/meshes/head/leadscrew__1___1__1.stl" scale="0.001 0.001 0.001"/>
      </geometry>
      <material name="opaque191191191"/>
    </visual>
    <collision>
      <origin xyz="-0.382356 0.115621 0.006475" rpy="0 0 0"/>
      <geometry>
        <mesh filename="package://dropbear_simplified_urdf/meshes/head/leadscrew__1___1__1.stl" scale="0.001 0.001 0.001"/>
      </geometry>
    </collision>
  </link>
  <link name="head_screw-reciever__1__1">
    <inertial>
      <origin xyz="-0.008120661984091504 0.03192691679860454 0.013318601322868981" rpy="0 0 0"/>
      <mass value="0.04298268184364818"/>
      <inertia ixx="5.2e-05" iyy="1.2e-05" izz="4.7e-05" ixy="1.1e-05" iyz="-1.8e-05" ixz="4e-06"/>
    </inertial>
    <visual>
      <origin xyz="-0.380987 0.110454 -0.004315" rpy="0 0 0"/>
      <geometry>
        <mesh filename="package://dropbear_simplified_urdf/meshes/head/screw-reciever__1__1.stl" scale="0.001 0.001 0.001"/>
      </geometry>
      <material name="opaque25514347"/>
    </visual>
    <collision>
      <origin xyz="-0.380987 0.110454 -0.004315" rpy="0 0 0"/>
      <geometry>
        <mesh filename="package://dropbear_simplified_urdf/meshes/head/screw-reciever__1__1.stl" scale="0.001 0.001 0.001"/>
      </geometry>
    </collision>
  </link>
  <link name="head_u-joint-center__2__1">
    <inertial>
      <origin xyz="0.0018403789193226494 -4.1457359517549364e-08 0.004648879074007656" rpy="0 0 0"/>
      <mass value="0.0009727380393185158"/>
      <inertia ixx="0.0" iyy="0.0" izz="0.0" ixy="-0.0" iyz="0.0" ixz="-0.0"/>
    </inertial>
    <visual>
      <origin xyz="-0.356204 0.11854 0.047009" rpy="0 0 0"/>
      <geometry>
        <mesh filename="package://dropbear_simplified_urdf/meshes/head/u-joint-center__2__1.stl" scale="0.001 0.001 0.001"/>
      </geometry>
      <material name="opaque191191191"/>
    </visual>
    <collision>
      <origin xyz="-0.356204 0.11854 0.047009" rpy="0 0 0"/>
      <geometry>
        <mesh filename="package://dropbear_simplified_urdf/meshes/head/u-joint-center__2__1.stl" scale="0.001 0.001 0.001"/>
      </geometry>
    </collision>
  </link>
  <link name="head_leadscrew__0__1">
    <inertial>
      <origin xyz="-0.031857275970217425 0.047916784457887496 0.0033276778975500285" rpy="0 0 0"/>
      <mass value="0.04187032472639328"/>
      <inertia ixx="3e-05" iyy="8e-06" izz="3.7e-05" ixy="1.5e-05" iyz="-0.0" ixz="0.0"/>
    </inertial>
    <visual>
      <origin xyz="-0.364802 0.115197 0.045036" rpy="0 0 0"/>
      <geometry>
        <mesh filename="package://dropbear_simplified_urdf/meshes/head/leadscrew__0__1.stl" scale="0.001 0.001 0.001"/>
      </geometry>
      <material name="opaque191191191"/>
    </visual>
    <collision>
      <origin xyz="-0.364802 0.115197 0.045036" rpy="0 0 0"/>
      <geometry>
        <mesh filename="package://dropbear_simplified_urdf/meshes/head/leadscrew__0__1.stl" scale="0.001 0.001 0.001"/>
      </geometry>
    </collision>
  </link>
  <link name="head_screw-reciever__2__1">
    <inertial>
      <origin xyz="-0.01561212278275853 0.03188457435312017 0.00040503058741351433" rpy="0 0 0"/>
      <mass value="0.042982681843648195"/>
      <inertia ixx="4.4e-05" iyy="1.2e-05" izz="5.4e-05" ixy="2.1e-05" iyz="-1e-06" ixz="0.0"/>
    </inertial>
    <visual>
      <origin xyz="-0.354087 0.110458 0.042257" rpy="0 0 0"/>
      <geometry>
        <mesh filename="package://dropbear_simplified_urdf/meshes/head/screw-reciever__2__1.stl" scale="0.001 0.001 0.001"/>
      </geometry>
      <material name="opaque25514347"/>
    </visual>
    <collision>
      <origin xyz="-0.354087 0.110458 0.042257" rpy="0 0 0"/>
      <geometry>
        <mesh filename="package://dropbear_simplified_urdf/meshes/head/screw-reciever__2__1.stl" scale="0.001 0.001 0.001"/>
      </geometry>
    </collision>
  </link>
  <link name="head_u-joint-center__4__1">
    <inertial>
      <origin xyz="0.004356124760737379 9.141860647654543e-08 -0.002455149691664195" rpy="0 0 0"/>
      <mass value="0.0009727380393185158"/>
      <inertia ixx="0.0" iyy="0.0" izz="0.0" ixy="0.0" iyz="0.0" ixz="0.0"/>
    </inertial>
    <visual>
      <origin xyz="-0.205483 0.11854 0.039905" rpy="0 0 0"/>
      <geometry>
        <mesh filename="package://dropbear_simplified_urdf/meshes/head/u-joint-center__4__1.stl" scale="0.001 0.001 0.001"/>
      </geometry>
      <material name="opaque191191191"/>
    </visual>
    <collision>
      <origin xyz="-0.205483 0.11854 0.039905" rpy="0 0 0"/>
      <geometry>
        <mesh filename="package://dropbear_simplified_urdf/meshes/head/u-joint-center__4__1.stl" scale="0.001 0.001 0.001"/>
      </geometry>
    </collision>
  </link>
  <link name="head_leadscrew__3___1__1">
    <inertial>
      <origin xyz="0.028842623507411347 0.04934271537953708 0.007439093732284317" rpy="0 0 0"/>
      <mass value="0.04187032472639327"/>
      <inertia ixx="3e-05" iyy="8e-06" izz="3.7e-05" ixy="-1.5e-05" iyz="-0.0" ixz="-0.0"/>
    </inertial>
    <visual>
      <origin xyz="-0.20603 0.116591 0.049119" rpy="0 0 0"/>
      <geometry>
        <mesh filename="package://dropbear_simplified_urdf/meshes/head/leadscrew__3___1__1.stl" scale="0.001 0.001 0.001"/>
      </geometry>
      <material name="opaque191191191"/>
    </visual>
    <collision>
      <origin xyz="-0.20603 0.116591 0.049119" rpy="0 0 0"/>
      <geometry>
        <mesh filename="package://dropbear_simplified_urdf/meshes/head/leadscrew__3___1__1.stl" scale="0.001 0.001 0.001"/>
      </geometry>
    </collision>
  </link>
  <link name="head_screw-reciever__3__1">
    <inertial>
      <origin xyz="0.015584715497152818 0.03193070525388275 0.0004236047800553547" rpy="0 0 0"/>
      <mass value="0.04298268184354137"/>
      <inertia ixx="4.5e-05" iyy="1.2e-05" izz="5.5e-05" ixy="-2.1e-05" iyz="-1e-06" ixz="-0.0"/>
    </inertial>
    <visual>
      <origin xyz="-0.213786 0.110452 0.042253" rpy="0 0 0"/>
      <geometry>
        <mesh filename="package://dropbear_simplified_urdf/meshes/head/screw-reciever__3__1.stl" scale="0.001 0.001 0.001"/>
      </geometry>
      <material name="opaque25514347"/>
    </visual>
    <collision>
      <origin xyz="-0.213786 0.110452 0.042253" rpy="0 0 0"/>
      <geometry>
        <mesh filename="package://dropbear_simplified_urdf/meshes/head/screw-reciever__3__1.stl" scale="0.001 0.001 0.001"/>
      </geometry>
    </collision>
  </link>
  <link name="head_u-joint-center__5__1">
    <inertial>
      <origin xyz="0.004985175531100422 1.0243782577745719e-07 0.00038312367678919757" rpy="0 0 0"/>
      <mass value="0.0009727380393185158"/>
      <inertia ixx="0.0" iyy="0.0" izz="0.0" ixy="-0.0" iyz="0.0" ixz="-0.0"/>
    </inertial>
    <visual>
      <origin xyz="-0.179854 0.11854 -0.000558" rpy="0 0 0"/>
      <geometry>
        <mesh filename="package://dropbear_simplified_urdf/meshes/head/u-joint-center__5__1.stl" scale="0.001 0.001 0.001"/>
      </geometry>
      <material name="opaque191191191"/>
    </visual>
    <collision>
      <origin xyz="-0.179854 0.11854 -0.000558" rpy="0 0 0"/>
      <geometry>
        <mesh filename="package://dropbear_simplified_urdf/meshes/head/u-joint-center__5__1.stl" scale="0.001 0.001 0.001"/>
      </geometry>
    </collision>
  </link>
  <link name="head_leadscrew__2___1__1">
    <inertial>
      <origin xyz="0.012505547819126883 0.04834098253159427 0.028787508745766965" rpy="0 0 0"/>
      <mass value="0.041870324726393286"/>
      <inertia ixx="3.6e-05" iyy="8e-06" izz="3.2e-05" ixy="-8e-06" iyz="-1.2e-05" ixz="-3e-06"/>
    </inertial>
    <visual>
      <origin xyz="-0.18541 0.115595 0.006475" rpy="0 0 0"/>
      <geometry>
        <mesh filename="package://dropbear_simplified_urdf/meshes/head/leadscrew__2___1__1.stl" scale="0.001 0.001 0.001"/>
      </geometry>
      <material name="opaque191191191"/>
    </visual>
    <collision>
      <origin xyz="-0.18541 0.115595 0.006475" rpy="0 0 0"/>
      <geometry>
        <mesh filename="package://dropbear_simplified_urdf/meshes/head/leadscrew__2___1__1.stl" scale="0.001 0.001 0.001"/>
      </geometry>
    </collision>
  </link>
  <link name="head_screw-reciever__5__1">
    <inertial>
      <origin xyz="0.008061623594433992 0.03161751443189505 0.013175413237320646" rpy="0 0 0"/>
      <mass value="0.042818900146596034"/>
      <inertia ixx="5.1e-05" iyy="1.2e-05" izz="4.6e-05" ixy="-1.1e-05" iyz="-1.7e-05" ixz="-4e-06"/>
    </inertial>
    <visual>
      <origin xyz="-0.186901 0.110453 -0.004311" rpy="0 0 0"/>
      <geometry>
        <mesh filename="package://dropbear_simplified_urdf/meshes/head/screw-reciever__5__1.stl" scale="0.001 0.001 0.001"/>
      </geometry>
      <material name="opaque25514347"/>
    </visual>
    <collision>
      <origin xyz="-0.186901 0.110453 -0.004311" rpy="0 0 0"/>
      <geometry>
        <mesh filename="package://dropbear_simplified_urdf/meshes/head/screw-reciever__5__1.stl" scale="0.001 0.001 0.001"/>
      </geometry>
    </collision>
  </link>
  <link name="head_u-joint-center__8__1">
    <inertial>
      <origin xyz="-0.004714550703244946 0.0014502030420447346 0.000820321543006583" rpy="0 0 0"/>
      <mass value="0.0009727380393185158"/>
      <inertia ixx="0.0" iyy="0.0" izz="0.0" ixy="0.0" iyz="-0.0" ixz="-0.0"/>
    </inertial>
    <visual>
      <origin xyz="-0.34418 -0.011176 -0.072081" rpy="0 0 0"/>
      <geometry>
        <mesh filename="package://dropbear_simplified_urdf/meshes/head/u-joint-center__8__1.stl" scale="0.001 0.001 0.001"/>
      </geometry>
      <material name="opaque191191191"/>
    </visual>
    <collision>
      <origin xyz="-0.34418 -0.011176 -0.072081" rpy="0 0 0"/>
      <geometry>
        <mesh filename="package://dropbear_simplified_urdf/meshes/head/u-joint-center__8__1.stl" scale="0.001 0.001 0.001"/>
      </geometry>
    </collision>
  </link>
  <link name="head_10mm-ujoint-base__3__1">
    <inertial>
      <origin xyz="-0.0008631103535244322 0.0100927968035996 -0.004917803052373437" rpy="0 0 0"/>
      <mass value="0.0014232382644525146"/>
      <inertia ixx="0.0" iyy="0.0" izz="0.0" ixy="0.0" iyz="-0.0" ixz="-0.0"/>
    </inertial>
    <visual>
      <origin xyz="-0.340322 -0.012623 -0.077827" rpy="0 0 0"/>
      <geometry>
        <mesh filename="package://dropbear_simplified_urdf/meshes/head/10mm-ujoint-base__3__1.stl" scale="0.001 0.001 0.001"/>
      </geometry>
      <material name="opaque191191191"/>
    </visual>
    <collision>
      <origin xyz="-0.340322 -0.012623 -0.077827" rpy="0 0 0"/>
      <geometry>
        <mesh filename="package://dropbear_simplified_urdf/meshes/head/10mm-ujoint-base__3__1.stl" scale="0.001 0.001 0.001"/>
      </geometry>
    </collision>
  </link>
  <link name="head_Head_1">
    <inertial>
      <origin xyz="-0.05445785559977906 0.0791227204508759 -0.050633116327556904" rpy="0 0 0"/>
      <mass value="1.8674963122317672"/>
      <inertia ixx="0.011021" iyy="0.011236" izz="0.008366" ixy="-7e-06" iyz="0.000445" ixz="2e-05"/>
    </inertial>
    <visual>
      <origin xyz="-0.339454 -0.029626 -0.072915" rpy="0 0 0"/>
      <geometry>
        <mesh filename="package://dropbear_simplified_urdf/meshes/head/Head_1.stl" scale="0.001 0.001 0.001"/>
      </geometry>
      <material name="opaque191191191"/>
    </visual>
    <collision>
      <origin xyz="-0.339454 -0.029626 -0.072915" rpy="0 0 0"/>
      <geometry>
        <mesh filename="package://dropbear_simplified_urdf/meshes/head/Head_1.stl" scale="0.001 0.001 0.001"/>
      </geometry>
    </collision>
  </link>
  <link name="head_u-joint-center__7__1">
    <inertial>
      <origin xyz="-0.001164126831218526 -0.0021212943707097434 0.004375827543159155" rpy="0 0 0"/>
      <mass value="0.0009727380393185158"/>
      <inertia ixx="0.0" iyy="0.0" izz="0.0" ixy="-0.0" iyz="0.0" ixz="-0.0"/>
    </inertial>
    <visual>
      <origin xyz="-0.350841 -0.01476 -0.05129" rpy="0 0 0"/>
      <geometry>
        <mesh filename="package://dropbear_simplified_urdf/meshes/head/u-joint-center__7__1.stl" scale="0.001 0.001 0.001"/>
      </geometry>
      <material name="opaque191191191"/>
    </visual>
    <collision>
      <origin xyz="-0.350841 -0.01476 -0.05129" rpy="0 0 0"/>
      <geometry>
        <mesh filename="package://dropbear_simplified_urdf/meshes/head/u-joint-center__7__1.stl" scale="0.001 0.001 0.001"/>
      </geometry>
    </collision>
  </link>
  <link name="head_10mm-ujoint-base__2__1">
    <inertial>
      <origin xyz="-0.0048251103398560535 0.010093321294563556 -0.0012805299667578013" rpy="0 0 0"/>
      <mass value="0.0014232382644525146"/>
      <inertia ixx="0.0" iyy="0.0" izz="0.0" ixy="0.0" iyz="-0.0" ixz="-0.0"/>
    </inertial>
    <visual>
      <origin xyz="-0.354509 -0.012635 -0.056949" rpy="0 0 0"/>
      <geometry>
        <mesh filename="package://dropbear_simplified_urdf/meshes/head/10mm-ujoint-base__2__1.stl" scale="0.001 0.001 0.001"/>
      </geometry>
      <material name="opaque191191191"/>
    </visual>
    <collision>
      <origin xyz="-0.354509 -0.012635 -0.056949" rpy="0 0 0"/>
      <geometry>
        <mesh filename="package://dropbear_simplified_urdf/meshes/head/10mm-ujoint-base__2__1.stl" scale="0.001 0.001 0.001"/>
      </geometry>
    </collision>
  </link>
  <link name="head_dum5_1">
    <inertial>
      <origin xyz="1.3793844981235814e-06 0.002499675228971175 1.0015849780733999e-06" rpy="0 0 0"/>
      <mass value="0.004808992954482425"/>
      <inertia ixx="0.0" iyy="0.0" izz="0.0" ixy="0.0" iyz="0.0" ixz="0.0"/>
    </inertial>
    <visual>
      <origin xyz="-0.349689 -0.029639 -0.05567" rpy="0 0 0"/>
      <geometry>
        <mesh filename="package://dropbear_simplified_urdf/meshes/head/dum5_1.stl" scale="0.001 0.001 0.001"/>
      </geometry>
      <material name="opaque2550255"/>
    </visual>
    <collision>
      <origin xyz="-0.349689 -0.029639 -0.05567" rpy="0 0 0"/>
      <geometry>
        <mesh filename="package://dropbear_simplified_urdf/meshes/head/dum5_1.stl" scale="0.001 0.001 0.001"/>
      </geometry>
    </collision>
  </link>
  <link name="head_u-joint-center__9__1">
    <inertial>
      <origin xyz="0.0023709258457064175 0.0011070871145714267 0.00426110181416265" rpy="0 0 0"/>
      <mass value="0.0009727380393185158"/>
      <inertia ixx="0.0" iyy="0.0" izz="0.0" ixy="-0.0" iyz="-0.0" ixz="0.0"/>
    </inertial>
    <visual>
      <origin xyz="-0.291472 -0.011469 0.044954" rpy="0 0 0"/>
      <geometry>
        <mesh filename="package://dropbear_simplified_urdf/meshes/head/u-joint-center__9__1.stl" scale="0.001 0.001 0.001"/>
      </geometry>
      <material name="opaque191191191"/>
    </visual>
    <collision>
      <origin xyz="-0.291472 -0.011469 0.044954" rpy="0 0 0"/>
      <geometry>
        <mesh filename="package://dropbear_simplified_urdf/meshes/head/u-joint-center__9__1.stl" scale="0.001 0.001 0.001"/>
      </geometry>
    </collision>
  </link>
  <link name="head_10mm-ujoint-base__1__1">
    <inertial>
      <origin xyz="-0.004374417577884759 0.010085622713966397 0.0024369614949263582" rpy="0 0 0"/>
      <mass value="0.0014232382644525146"/>
      <inertia ixx="0.0" iyy="0.0" izz="0.0" ixy="-0.0" iyz="-0.0" ixz="0.0"/>
    </inertial>
    <visual>
      <origin xyz="-0.298212 -0.01258 0.043124" rpy="0 0 0"/>
      <geometry>
        <mesh filename="package://dropbear_simplified_urdf/meshes/head/10mm-ujoint-base__1__1.stl" scale="0.001 0.001 0.001"/>
      </geometry>
      <material name="opaque191191191"/>
    </visual>
    <collision>
      <origin xyz="-0.298212 -0.01258 0.043124" rpy="0 0 0"/>
      <geometry>
        <mesh filename="package://dropbear_simplified_urdf/meshes/head/10mm-ujoint-base__1__1.stl" scale="0.001 0.001 0.001"/>
      </geometry>
    </collision>
  </link>
  <link name="head_dum2_1">
    <inertial>
      <origin xyz="-1.4141794991151535e-06 0.002499976284172079 1.47636454261163e-06" rpy="0 0 0"/>
      <mass value="0.004808992954482494"/>
      <inertia ixx="0.0" iyy="0.0" izz="0.0" ixy="-0.0" iyz="0.0" ixz="-0.0"/>
    </inertial>
    <visual>
      <origin xyz="-0.293834 -0.029576 0.040683" rpy="0 0 0"/>
      <geometry>
        <mesh filename="package://dropbear_simplified_urdf/meshes/head/dum2_1.stl" scale="0.001 0.001 0.001"/>
      </geometry>
      <material name="opaque2550255"/>
    </visual>
    <collision>
      <origin xyz="-0.293834 -0.029576 0.040683" rpy="0 0 0"/>
      <geometry>
        <mesh filename="package://dropbear_simplified_urdf/meshes/head/dum2_1.stl" scale="0.001 0.001 0.001"/>
      </geometry>
    </collision>
  </link>
  <link name="head_u-joint-center_1">
    <inertial>
      <origin xyz="-0.002654534649389917 0.001241606002754329 0.004051810068480127" rpy="0 0 0"/>
      <mass value="0.0009727380393185158"/>
      <inertia ixx="0.0" iyy="0.0" izz="0.0" ixy="0.0" iyz="-0.0" ixz="-0.0"/>
    </inertial>
    <visual>
      <origin xyz="-0.276526 -0.011416 0.044672" rpy="0 0 0"/>
      <geometry>
        <mesh filename="package://dropbear_simplified_urdf/meshes/head/u-joint-center_1.stl" scale="0.001 0.001 0.001"/>
      </geometry>
      <material name="opaque191191191"/>
    </visual>
    <collision>
      <origin xyz="-0.276526 -0.011416 0.044672" rpy="0 0 0"/>
      <geometry>
        <mesh filename="package://dropbear_simplified_urdf/meshes/head/u-joint-center_1.stl" scale="0.001 0.001 0.001"/>
      </geometry>
    </collision>
  </link>
  <link name="head_10mm-ujoint-base_1">
    <inertial>
      <origin xyz="-0.00418094602180985 0.010091298212800023 -0.0027347789599892758" rpy="0 0 0"/>
      <mass value="0.0014232382644525146"/>
      <inertia ixx="0.0" iyy="0.0" izz="0.0" ixy="0.0" iyz="-0.0" ixz="-0.0"/>
    </inertial>
    <visual>
      <origin xyz="-0.278054 -0.012656 0.03788" rpy="0 0 0"/>
      <geometry>
        <mesh filename="package://dropbear_simplified_urdf/meshes/head/10mm-ujoint-base_1.stl" scale="0.001 0.001 0.001"/>
      </geometry>
      <material name="opaque191191191"/>
    </visual>
    <collision>
      <origin xyz="-0.278054 -0.012656 0.03788" rpy="0 0 0"/>
      <geometry>
        <mesh filename="package://dropbear_simplified_urdf/meshes/head/10mm-ujoint-base_1.stl" scale="0.001 0.001 0.001"/>
      </geometry>
    </collision>
  </link>
  <link name="head_dum4_1">
    <inertial>
      <origin xyz="4.704824180246092e-07 0.0024996531762756548 1.4317024103691067e-06" rpy="0 0 0"/>
      <mass value="0.004808992954482493"/>
      <inertia ixx="0.0" iyy="0.0" izz="0.0" ixy="0.0" iyz="0.0" ixz="0.0"/>
    </inertial>
    <visual>
      <origin xyz="-0.273874 -0.029658 0.040611" rpy="0 0 0"/>
      <geometry>
        <mesh filename="package://dropbear_simplified_urdf/meshes/head/dum4_1.stl" scale="0.001 0.001 0.001"/>
      </geometry>
      <material name="opaque2550255"/>
    </visual>
    <collision>
      <origin xyz="-0.273874 -0.029658 0.040611" rpy="0 0 0"/>
      <geometry>
        <mesh filename="package://dropbear_simplified_urdf/meshes/head/dum4_1.stl" scale="0.001 0.001 0.001"/>
      </geometry>
    </collision>
  </link>
  <link name="head_u-joint-center__10__1">
    <inertial>
      <origin xyz="0.0010869079977688934 -0.0021109819465681343 0.004400401099097305" rpy="0 0 0"/>
      <mass value="0.0009727380393185158"/>
      <inertia ixx="0.0" iyy="0.0" izz="0.0" ixy="0.0" iyz="0.0" ixz="0.0"/>
    </inertial>
    <visual>
      <origin xyz="-0.2172 -0.014754 -0.051206" rpy="0 0 0"/>
      <geometry>
        <mesh filename="package://dropbear_simplified_urdf/meshes/head/u-joint-center__10__1.stl" scale="0.001 0.001 0.001"/>
      </geometry>
      <material name="opaque191191191"/>
    </visual>
    <collision>
      <origin xyz="-0.2172 -0.014754 -0.051206" rpy="0 0 0"/>
      <geometry>
        <mesh filename="package://dropbear_simplified_urdf/meshes/head/u-joint-center__10__1.stl" scale="0.001 0.001 0.001"/>
      </geometry>
    </collision>
  </link>
  <link name="head_10mm-ujoint-base__5__1">
    <inertial>
      <origin xyz="0.005217041197059458 0.00986470883503762 -0.0015102147129289062" rpy="0 0 0"/>
      <mass value="0.0014232382644525146"/>
      <inertia ixx="0.0" iyy="0.0" izz="0.0" ixy="0.0" iyz="0.0" ixz="0.0"/>
    </inertial>
    <visual>
      <origin xyz="-0.213462 -0.012858 -0.056901" rpy="0 0 0"/>
      <geometry>
        <mesh filename="package://dropbear_simplified_urdf/meshes/head/10mm-ujoint-base__5__1.stl" scale="0.001 0.001 0.001"/>
      </geometry>
      <material name="opaque191191191"/>
    </visual>
    <collision>
      <origin xyz="-0.213462 -0.012858 -0.056901" rpy="0 0 0"/>
      <geometry>
        <mesh filename="package://dropbear_simplified_urdf/meshes/head/10mm-ujoint-base__5__1.stl" scale="0.001 0.001 0.001"/>
      </geometry>
    </collision>
  </link>
  <link name="head_dum1_1">
    <inertial>
      <origin xyz="9.676115574566713e-05 0.0024978072679708307 -5.322929502842022e-05" rpy="0 0 0"/>
      <mass value="0.004808992954482493"/>
      <inertia ixx="0.0" iyy="0.0" izz="0.0" ixy="0.0" iyz="-0.0" ixz="-0.0"/>
    </inertial>
    <visual>
      <origin xyz="-0.218948 -0.029626 -0.055243" rpy="0 0 0"/>
      <geometry>
        <mesh filename="package://dropbear_simplified_urdf/meshes/head/dum1_1.stl" scale="0.001 0.001 0.001"/>
      </geometry>
      <material name="opaque2550255"/>
    </visual>
    <collision>
      <origin xyz="-0.218948 -0.029626 -0.055243" rpy="0 0 0"/>
      <geometry>
        <mesh filename="package://dropbear_simplified_urdf/meshes/head/dum1_1.stl" scale="0.001 0.001 0.001"/>
      </geometry>
    </collision>
  </link>
  <link name="head_u-joint-center__11__1">
    <inertial>
      <origin xyz="-3.210636303846437e-06 -0.0019705200384065574 -0.004594639231801437" rpy="0 0 0"/>
      <mass value="0.0009727380393185158"/>
      <inertia ixx="0.0" iyy="0.0" izz="0.0" ixy="0.0" iyz="-0.0" ixz="-0.0"/>
    </inertial>
    <visual>
      <origin xyz="-0.228395 -0.014648 -0.07763" rpy="0 0 0"/>
      <geometry>
        <mesh filename="package://dropbear_simplified_urdf/meshes/head/u-joint-center__11__1.stl" scale="0.001 0.001 0.001"/>
      </geometry>
      <material name="opaque191191191"/>
    </visual>
    <collision>
      <origin xyz="-0.228395 -0.014648 -0.07763" rpy="0 0 0"/>
      <geometry>
        <mesh filename="package://dropbear_simplified_urdf/meshes/head/u-joint-center__11__1.stl" scale="0.001 0.001 0.001"/>
      </geometry>
    </collision>
  </link>
  <link name="head_10mm-ujoint-base__4__1">
    <inertial>
      <origin xyz="0.005005631071676758 0.010087151077690207 -4.07206132493898e-06" rpy="0 0 0"/>
      <mass value="0.0014232382644525146"/>
      <inertia ixx="0.0" iyy="0.0" izz="0.0" ixy="0.0" iyz="0.0" ixz="0.0"/>
    </inertial>
    <visual>
      <origin xyz="-0.223392 -0.01268 -0.073037" rpy="0 0 0"/>
      <geometry>
        <mesh filename="package://dropbear_simplified_urdf/meshes/head/10mm-ujoint-base__4__1.stl" scale="0.001 0.001 0.001"/>
      </geometry>
      <material name="opaque191191191"/>
    </visual>
    <collision>
      <origin xyz="-0.223392 -0.01268 -0.073037" rpy="0 0 0"/>
      <geometry>
        <mesh filename="package://dropbear_simplified_urdf/meshes/head/10mm-ujoint-base__4__1.stl" scale="0.001 0.001 0.001"/>
      </geometry>
    </collision>
  </link>
  <link name="head_dum3_1">
    <inertial>
      <origin xyz="1.1149251306630248e-06 0.002499505760358508 -1.6247544400160852e-07" rpy="0 0 0"/>
      <mass value="0.004808992954482499"/>
      <inertia ixx="0.0" iyy="0.0" izz="0.0" ixy="0.0" iyz="-0.0" ixz="-0.0"/>
    </inertial>
    <visual>
      <origin xyz="-0.228402 -0.029678 -0.073031" rpy="0 0 0"/>
      <geometry>
        <mesh filename="package://dropbear_simplified_urdf/meshes/head/dum3_1.stl" scale="0.001 0.001 0.001"/>
      </geometry>
      <material name="opaque2550255"/>
    </visual>
    <collision>
      <origin xyz="-0.228402 -0.029678 -0.073031" rpy="0 0 0"/>
      <geometry>
        <mesh filename="package://dropbear_simplified_urdf/meshes/head/dum3_1.stl" scale="0.001 0.001 0.001"/>
      </geometry>
    </collision>
  </link>
  <link name="head_dum1__1__1">
    <inertial>
      <origin xyz="-1.5884686790923475e-06 0.0025002181249646586 1.5290897213693366e-06" rpy="0 0 0"/>
      <mass value="0.004808991648704888"/>
      <inertia ixx="0.0" iyy="0.0" izz="0.0" ixy="-0.0" iyz="0.0" ixz="-0.0"/>
    </inertial>
    <visual>
      <origin xyz="-0.218222 -0.029562 -0.055517" rpy="0 0 0"/>
      <geometry>
        <mesh filename="package://dropbear_simplified_urdf/meshes/head/dum1__1__1.stl" scale="0.001 0.001 0.001"/>
      </geometry>
      <material name="opaque2550255"/>
    </visual>
    <collision>
      <origin xyz="-0.218222 -0.029562 -0.055517" rpy="0 0 0"/>
      <geometry>
        <mesh filename="package://dropbear_simplified_urdf/meshes/head/dum1__1__1.stl" scale="0.001 0.001 0.001"/>
      </geometry>
    </collision>
  </link>
  <link name="head_dum3__1__1">
    <inertial>
      <origin xyz="-1.6604851890700267e-06 0.002500080666971643 2.42340941165875e-06" rpy="0 0 0"/>
      <mass value="0.004808992331200635"/>
      <inertia ixx="0.0" iyy="0.0" izz="0.0" ixy="-0.0" iyz="0.0" ixz="-0.0"/>
    </inertial>
    <visual>
      <origin xyz="-0.228211 -0.029555 -0.072843" rpy="0 0 0"/>
      <geometry>
        <mesh filename="package://dropbear_simplified_urdf/meshes/head/dum3__1__1.stl" scale="0.001 0.001 0.001"/>
      </geometry>
      <material name="opaque2550255"/>
    </visual>
    <collision>
      <origin xyz="-0.228211 -0.029555 -0.072843" rpy="0 0 0"/>
      <geometry>
        <mesh filename="package://dropbear_simplified_urdf/meshes/head/dum3__1__1.stl" scale="0.001 0.001 0.001"/>
      </geometry>
    </collision>
  </link>
  <link name="head_dum5__1__1">
    <inertial>
      <origin xyz="-2.0855579985212813e-06 0.002500062931232845 1.4601564256241928e-06" rpy="0 0 0"/>
      <mass value="0.004808992954482824"/>
      <inertia ixx="0.0" iyy="0.0" izz="0.0" ixy="-0.0" iyz="0.0" ixz="-0.0"/>
    </inertial>
    <visual>
      <origin xyz="-0.349466 -0.029646 -0.055601" rpy="0 0 0"/>
      <geometry>
        <mesh filename="package://dropbear_simplified_urdf/meshes/head/dum5__1__1.stl" scale="0.001 0.001 0.001"/>
      </geometry>
      <material name="opaque2550255"/>
    </visual>
    <collision>
      <origin xyz="-0.349466 -0.029646 -0.055601" rpy="0 0 0"/>
      <geometry>
        <mesh filename="package://dropbear_simplified_urdf/meshes/head/dum5__1__1.stl" scale="0.001 0.001 0.001"/>
      </geometry>
    </collision>
  </link>
  <link name="head_dum2__1__1">
    <inertial>
      <origin xyz="-1.2793028496549397e-06 0.0024997627418174607 2.1927656866024825e-06" rpy="0 0 0"/>
      <mass value="0.004808989144025898"/>
      <inertia ixx="0.0" iyy="0.0" izz="0.0" ixy="-0.0" iyz="0.0" ixz="0.0"/>
    </inertial>
    <visual>
      <origin xyz="-0.293905 -0.029686 0.040775" rpy="0 0 0"/>
      <geometry>
        <mesh filename="package://dropbear_simplified_urdf/meshes/head/dum2__1__1.stl" scale="0.001 0.001 0.001"/>
      </geometry>
      <material name="opaque2550255"/>
    </visual>
    <collision>
      <origin xyz="-0.293905 -0.029686 0.040775" rpy="0 0 0"/>
      <geometry>
        <mesh filename="package://dropbear_simplified_urdf/meshes/head/dum2__1__1.stl" scale="0.001 0.001 0.001"/>
      </geometry>
    </collision>
  </link>
  <link name="head_dum4__1__1">
    <inertial>
      <origin xyz="-1.2711319041236457e-06 0.002499985763122912 2.40264589832645e-06" rpy="0 0 0"/>
      <mass value="0.004808992066310556"/>
      <inertia ixx="0.0" iyy="0.0" izz="0.0" ixy="-0.0" iyz="0.0" ixz="-0.0"/>
    </inertial>
    <visual>
      <origin xyz="-0.273905 -0.029673 0.040788" rpy="0 0 0"/>
      <geometry>
        <mesh filename="package://dropbear_simplified_urdf/meshes/head/dum4__1__1.stl" scale="0.001 0.001 0.001"/>
      </geometry>
      <material name="opaque2550255"/>
    </visual>
    <collision>
      <origin xyz="-0.273905 -0.029673 0.040788" rpy="0 0 0"/>
      <geometry>
        <mesh filename="package://dropbear_simplified_urdf/meshes/head/dum4__1__1.stl" scale="0.001 0.001 0.001"/>
      </geometry>
    </collision>
  </link>
  <joint name="head_torso_connection" type="fixed">
    <origin xyz="0.078519 0.116226 0.059747" rpy="0 1.5707965 0"/>
    <parent link="torso"/>
    <child link="head_center-bracket2_1"/>
  </joint>
  <joint name="head_Revolute 2" type="continuous">
    <origin xyz="0.025 0.059 0.0025" rpy="0 0 0"/>
    <parent link="head_center-bracket2_1"/>
    <child link="head_5mm-ujoint-base__5__1"/>
    <axis xyz="0.0 1.0 0.0"/>
  </joint>
  <joint name="head_Revolute 3" type="continuous">
    <origin xyz="-0.025 0.059 0.0025" rpy="0 0 0"/>
    <parent link="head_center-bracket2_1"/>
    <child link="head_5mm-ujoint-base__2__1"/>
    <axis xyz="0.0 1.0 0.0"/>
  </joint>
  <joint name="head_Revolute 4" type="continuous">
    <origin xyz="0.099102 0.059 -0.12585" rpy="0 0 0"/>
    <parent link="head_center-bracket2_1"/>
    <child link="head_5mm-ujoint-base__1__1"/>
    <axis xyz="0.0 1.0 0.0"/>
  </joint>
  <joint name="head_Revolute 5" type="continuous">
    <origin xyz="0.074102 0.059 -0.169151" rpy="0 0 0"/>
    <parent link="head_center-bracket2_1"/>
    <child link="head_5mm-ujoint-base_1"/>
    <axis xyz="0.0 1.0 0.0"/>
  </joint>
  <joint name="head_Revolute 6" type="continuous">
    <origin xyz="-0.074103 0.059 -0.169151" rpy="0 0 0"/>
    <parent link="head_center-bracket2_1"/>
    <child link="head_5mm-ujoint-base__3__1"/>
    <axis xyz="0.0 1.0 0.0"/>
  </joint>
  <joint name="head_Revolute 7" type="continuous">
    <origin xyz="-0.099103 0.059 -0.12585" rpy="0 0 0"/>
    <parent link="head_center-bracket2_1"/>
    <child link="head_5mm-ujoint-base__4__1"/>
    <axis xyz="0.0 1.0 0.0"/>
  </joint>
  <joint name="head_Revolute 8" type="continuous">
    <origin xyz="0.004226 0.009 0.002671" rpy="0 0 0"/>
    <parent link="head_5mm-ujoint-base__5__1"/>
    <child link="head_u-joint-center__6__1"/>
    <axis xyz="-0.845262 0.0 -0.534352"/>
  </joint>
  <joint name="head_Revolute 9" type="continuous">
    <origin xyz="-0.000384 -0.003507 -0.008749" rpy="0 0 0"/>
    <parent link="head_u-joint-center__6__1"/>
    <child link="head_leadscrew__4___1"/>
    <axis xyz="0.480273 -0.438371 -0.759716"/>
  </joint>
  <joint name="head_Slider 10" type="prismatic">
    <origin xyz="-0.001961 0.011593 0.002602" rpy="0 0 0"/>
    <parent link="head_leadscrew__4___1"/>
    <child link="head_screw-reciever_1"/>
    <axis xyz="-0.209066 -0.898398 0.386228"/>
    <limit upper="0.0" lower="-0.075" effort="100" velocity="100"/>
  </joint>
  <joint name="head_Revolute 11" type="continuous">
    <origin xyz="0.00493 0.009 0.000834" rpy="0 0 0"/>
    <parent link="head_5mm-ujoint-base__2__1"/>
    <child link="head_u-joint-center__1__1"/>
    <axis xyz="-0.985983 0.0 -0.166846"/>
  </joint>
  <joint name="head_Revolute 12" type="continuous">
    <origin xyz="-0.006176 0.002867 0.00653" rpy="0 0 0"/>
    <parent link="head_u-joint-center__1__1"/>
    <child link="head_leadscrew__5___1__1"/>
    <axis xyz="-0.155764 0.358368 0.920494"/>
  </joint>
  <joint name="head_Slider 13" type="prismatic">
    <origin xyz="-0.000638 0.005222 -0.010832" rpy="0 0 0"/>
    <parent link="head_leadscrew__5___1__1"/>
    <child link="head_screw-reciever__4__1"/>
    <axis xyz="0.209246 -0.89875 0.385311"/>
    <limit upper="0.0" lower="-0.075" effort="100" velocity="100"/>
  </joint>
  <joint name="head_Revolute 14" type="continuous">
    <origin xyz="0.004979 0.009 -0.000462" rpy="0 0 0"/>
    <parent link="head_5mm-ujoint-base__1__1"/>
    <child link="head_u-joint-center__3__1"/>
    <axis xyz="-0.995725 0.0 0.092371"/>
  </joint>
  <joint name="head_Revolute 15" type="continuous">
    <origin xyz="-0.005667 0.002919 -0.006954" rpy="0 0 0"/>
    <parent link="head_u-joint-center__3__1"/>
    <child link="head_leadscrew__1___1__1"/>
    <axis xyz="-0.086002 0.364877 -0.927075"/>
  </joint>
  <joint name="head_Slider 16" type="prismatic">
    <origin xyz="-0.001369 0.005167 0.01079" rpy="0 0 0"/>
    <parent link="head_leadscrew__1___1__1"/>
    <child link="head_screw-reciever__1__1"/>
    <axis xyz="0.228543 -0.898484 -0.374825"/>
    <limit upper="0.0" lower="-0.075" effort="100" velocity="100"/>
  </joint>
  <joint name="head_Revolute 17" type="continuous">
    <origin xyz="-0.00184 0.009 -0.004649" rpy="0 0 0"/>
    <parent link="head_5mm-ujoint-base_1"/>
    <child link="head_u-joint-center__2__1"/>
    <axis xyz="0.368125 -0.0 0.929776"/>
  </joint>
  <joint name="head_Revolute 18" type="continuous">
    <origin xyz="0.008598 0.003343 0.001973" rpy="0 0 0"/>
    <parent link="head_u-joint-center__2__1"/>
    <child link="head_leadscrew__0__1"/>
    <axis xyz="0.84471 0.417867 -0.334444"/>
  </joint>
  <joint name="head_Slider 19" type="prismatic">
    <origin xyz="-0.010715 0.004739 0.002779" rpy="0 0 0"/>
    <parent link="head_leadscrew__0__1"/>
    <child link="head_screw-reciever__2__1"/>
    <axis xyz="0.439735 -0.898055 -0.011418"/>
    <limit upper="0.0" lower="-0.075" effort="100" velocity="100"/>
  </joint>
  <joint name="head_Revolute 20" type="continuous">
    <origin xyz="-0.004356 0.009 0.002455" rpy="0 0 0"/>
    <parent link="head_5mm-ujoint-base__3__1"/>
    <child link="head_u-joint-center__4__1"/>
    <axis xyz="0.871168 -0.0 -0.490985"/>
  </joint>
  <joint name="head_Revolute 21" type="continuous">
    <origin xyz="0.000547 0.001949 -0.009214" rpy="0 0 0"/>
    <parent link="head_u-joint-center__4__1"/>
    <child link="head_leadscrew__3___1__1"/>
    <axis xyz="-0.476193 0.243615 -0.844921"/>
  </joint>
  <joint name="head_Slider 22" type="prismatic">
    <origin xyz="0.007756 0.006139 0.006866" rpy="0 0 0"/>
    <parent link="head_leadscrew__3___1__1"/>
    <child link="head_screw-reciever__3__1"/>
    <axis xyz="-0.438578 -0.898614 -0.011916"/>
    <limit upper="0.0" lower="-0.075" effort="100" velocity="100"/>
  </joint>
  <joint name="head_Revolute 23" type="continuous">
    <origin xyz="-0.004985 0.009 -0.000383" rpy="0 0 0"/>
    <parent link="head_5mm-ujoint-base__4__1"/>
    <child link="head_u-joint-center__5__1"/>
    <axis xyz="0.997055 -0.0 0.076689"/>
  </joint>
  <joint name="head_Revolute 24" type="continuous">
    <origin xyz="0.005556 0.002945 -0.007033" rpy="0 0 0"/>
    <parent link="head_u-joint-center__5__1"/>
    <child link="head_leadscrew__2___1__1"/>
    <axis xyz="0.071303 0.368125 -0.927038"/>
  </joint>
  <joint name="head_Slider 25" type="prismatic">
    <origin xyz="0.001491 0.005142 0.010786" rpy="0 0 0"/>
    <parent link="head_leadscrew__2___1__1"/>
    <child link="head_screw-reciever__5__1"/>
    <axis xyz="-0.229094 -0.898514 -0.374418"/>
    <limit upper="0.0" lower="-0.075" effort="100" velocity="100"/>
  </joint>
  <joint name="head_Revolute 26" type="continuous">
    <origin xyz="0.033357 0.12163 -0.053734" rpy="0 0 0"/>
    <parent link="head_screw-reciever_1"/>
    <child link="head_u-joint-center__8__1"/>
    <axis xyz="-0.942857 0.289971 0.164128"/>
  </joint>
  <joint name="head_Revolute 27" type="continuous">
    <origin xyz="-0.003858 0.001447 0.005746" rpy="0 0 0"/>
    <parent link="head_u-joint-center__8__1"/>
    <child link="head_10mm-ujoint-base__3__1"/>
    <axis xyz="0.1713 -0.000659 0.985219"/>
  </joint>
  <joint name="head_Rigid 28" type="fixed">
    <origin xyz="-0.000868 0.017003 -0.004912" rpy="0 0 0"/>
    <parent link="head_10mm-ujoint-base__3__1"/>
    <child link="head_Head_1"/>
  </joint>
  <joint name="head_Revolute 29" type="continuous">
    <origin xyz="-0.030146 0.125214 0.046975" rpy="0 0 0"/>
    <parent link="head_screw-reciever__1__1"/>
    <child link="head_u-joint-center__7__1"/>
    <axis xyz="-0.232746 -0.424277 0.87511"/>
  </joint>
  <joint name="head_Revolute 30" type="continuous">
    <origin xyz="0.003668 -0.002125 0.005659" rpy="0 0 0"/>
    <parent link="head_u-joint-center__7__1"/>
    <child link="head_10mm-ujoint-base__2__1"/>
    <axis xyz="0.966493 -0.000738 0.256693"/>
  </joint>
  <joint name="head_Rigid 31" type="fixed">
    <origin xyz="-0.00482 0.017004 -0.001279" rpy="0 0 0"/>
    <parent link="head_10mm-ujoint-base__2__1"/>
    <child link="head_dum5_1"/>
  </joint>
  <joint name="head_Revolute 32" type="continuous">
    <origin xyz="-0.062615 0.121927 -0.002697" rpy="0 0 0"/>
    <parent link="head_screw-reciever__2__1"/>
    <child link="head_u-joint-center__9__1"/>
    <axis xyz="0.474078 0.221298 0.852219"/>
  </joint>
  <joint name="head_Revolute 33" type="continuous">
    <origin xyz="0.00674 0.001111 0.00183" rpy="0 0 0"/>
    <parent link="head_u-joint-center__9__1"/>
    <child link="head_10mm-ujoint-base__1__1"/>
    <axis xyz="0.873803 0.000747 -0.486279"/>
  </joint>
  <joint name="head_Rigid 34" type="fixed">
    <origin xyz="-0.004378 0.016996 0.002441" rpy="0 0 0"/>
    <parent link="head_10mm-ujoint-base__1__1"/>
    <child link="head_dum2_1"/>
  </joint>
  <joint name="head_Revolute 35" type="continuous">
    <origin xyz="0.06274 0.121868 -0.002419" rpy="0 0 0"/>
    <parent link="head_screw-reciever__3__1"/>
    <child link="head_u-joint-center_1"/>
    <axis xyz="-0.530813 0.248324 0.810292"/>
  </joint>
  <joint name="head_Revolute 36" type="continuous">
    <origin xyz="0.001528 0.00124 0.006792" rpy="0 0 0"/>
    <parent link="head_u-joint-center_1"/>
    <child link="head_10mm-ujoint-base_1"/>
    <axis xyz="0.836433 -0.000427 0.548069"/>
  </joint>
  <joint name="head_Rigid 37" type="fixed">
    <origin xyz="-0.00418 0.017002 -0.002731" rpy="0 0 0"/>
    <parent link="head_10mm-ujoint-base_1"/>
    <child link="head_dum4_1"/>
  </joint>
  <joint name="head_Revolute 38" type="continuous">
    <origin xyz="0.030299 0.125207 0.046895" rpy="0 0 0"/>
    <parent link="head_screw-reciever__5__1"/>
    <child link="head_u-joint-center__10__1"/>
    <axis xyz="0.2173 -0.422149 0.880097"/>
  </joint>
  <joint name="head_Revolute 39" type="continuous">
    <origin xyz="-0.003738 -0.001896 0.005695" rpy="0 0 0"/>
    <parent link="head_u-joint-center__10__1"/>
    <child link="head_10mm-ujoint-base__5__1"/>
    <axis xyz="-0.96494 0.043076 0.25891"/>
  </joint>
  <joint name="head_Rigid 40" type="fixed">
    <origin xyz="0.005486 0.016768 -0.001658" rpy="0 0 0"/>
    <parent link="head_10mm-ujoint-base__5__1"/>
    <child link="head_dum1_1"/>
  </joint>
  <joint name="head_Revolute 41" type="continuous">
    <origin xyz="-0.028663 0.125099 -0.048193" rpy="0 0 0"/>
    <parent link="head_screw-reciever__4__1"/>
    <child link="head_u-joint-center__11__1"/>
    <axis xyz="-0.000586 -0.394148 -0.919047"/>
  </joint>
  <joint name="head_Revolute 42" type="continuous">
    <origin xyz="-0.005003 -0.001968 -0.004593" rpy="0 0 0"/>
    <parent link="head_u-joint-center__11__1"/>
    <child link="head_10mm-ujoint-base__4__1"/>
    <axis xyz="-1.0 0.000581 0.000388"/>
  </joint>
  <joint name="head_Rigid 43" type="fixed">
    <origin xyz="0.00501 0.016998 -6e-06" rpy="0 0 0"/>
    <parent link="head_10mm-ujoint-base__4__1"/>
    <child link="head_dum3_1"/>
  </joint>
  <joint name="head_Rigid 44" type="fixed">
    <origin xyz="-0.121232 -6.4e-05 -0.017398" rpy="0 0 0"/>
    <parent link="head_Head_1"/>
    <child link="head_dum1__1__1"/>
  </joint>
  <joint name="head_Rigid 45" type="fixed">
    <origin xyz="-0.111243 -7.1e-05 -7.2e-05" rpy="0 0 0"/>
    <parent link="head_Head_1"/>
    <child link="head_dum3__1__1"/>
  </joint>
  <joint name="head_Rigid 46" type="fixed">
    <origin xyz="0.010012 2e-05 -0.017314" rpy="0 0 0"/>
    <parent link="head_Head_1"/>
    <child link="head_dum5__1__1"/>
  </joint>
  <joint name="head_Rigid 47" type="fixed">
    <origin xyz="-0.045549 6e-05 -0.11369" rpy="0 0 0"/>
    <parent link="head_Head_1"/>
    <child link="head_dum2__1__1"/>
  </joint>
  <joint name="head_Rigid 48" type="fixed">
    <origin xyz="-0.065549 4.7e-05 -0.113703" rpy="0 0 0"/>
    <parent link="head_Head_1"/>
    <child link="head_dum4__1__1"/>
  </joint>
  <!-- waist -->
  <link name="Rotate-right-leg_1">
    <inertial>
      <origin xyz="0.06120754854285463 -0.0029503876001564233 0.014756359444244638" rpy="0 0 0"/>
      <mass value="0.5634737106043444"/>
      <inertia ixx="0.001013" iyy="0.002795" izz="0.002177" ixy="-2.1e-05" iyz="0.000121" ixz="0.000246"/>
    </inertial>
    <visual>
      <origin xyz="0.10502 0.263369 -0.120699" rpy="0 0 0"/>
      <geometry>
        <mesh filename="package://dropbear_simplified_urdf/meshes/waist/Rotate-right-leg_1.stl" scale="0.001 0.001 0.001"/>
      </geometry>
      <material name="opaque245245245"/>
    </visual>
    <collision>
      <origin xyz="0.10502 0.263369 -0.120699" rpy="0 0 0"/>
      <geometry>
        <mesh filename="package://dropbear_simplified_urdf/meshes/waist/Rotate-right-leg_1.stl" scale="0.001 0.001 0.001"/>
      </geometry>
    </collision>
  </link>
  <link name="Rotate-left-leg_1">
    <inertial>
      <origin xyz="0.06120127554004958 -0.0029502323515913087 -0.014767579628205085" rpy="0 0 0"/>
      <mass value="0.563679151820761"/>
      <inertia ixx="0.001016" iyy="0.002797" izz="0.002177" ixy="-2.1e-05" iyz="-0.000121" ixz="-0.000248"/>
    </inertial>
    <visual>
      <origin xyz="0.104988 0.263369 0.001301" rpy="0 0 0"/>
      <geometry>
        <mesh filename="package://dropbear_simplified_urdf/meshes/waist/Rotate-left-leg_1.stl" scale="0.001 0.001 0.001"/>
      </geometry>
      <material name="opaque245245245"/>
    </visual>
    <collision>
      <origin xyz="0.104988 0.263369 0.001301" rpy="0 0 0"/>
      <geometry>
        <mesh filename="package://dropbear_simplified_urdf/meshes/waist/Rotate-left-leg_1.stl" scale="0.001 0.001 0.001"/>
      </geometry>
    </collision>
  </link>
  <link name="Left-femur-top_1">
    <inertial>
      <origin xyz="-4.097892786209326e-06 -0.04138743736457201 0.004860837445485772" rpy="0 0 0"/>
      <mass value="0.17034196336973478"/>
      <inertia ixx="0.000221" iyy="6.8e-05" izz="0.000227" ixy="0.0" iyz="1.6e-05" ixz="0.0"/>
    </inertial>
    <visual>
      <origin xyz="-0.007913 0.284631 0.006662" rpy="0 0 0"/>
      <geometry>
        <mesh filename="package://dropbear_simplified_urdf/meshes/waist/Left-femur-top_1.stl" scale="0.001 0.001 0.001"/>
      </geometry>
      <material name="opaque2551530"/>
    </visual>
    <collision>
      <origin xyz="-0.007913 0.284631 0.006662" rpy="0 0 0"/>
      <geometry>
        <mesh filename="package://dropbear_simplified_urdf/meshes/waist/Left-femur-top_1.stl" scale="0.001 0.001 0.001"/>
      </geometry>
    </collision>
  </link>
  <link name="Right-femur-top_1">
    <inertial>
      <origin xyz="-1.1875230248842295e-05 -0.04016954723293298 -0.005717104429115966" rpy="0 0 0"/>
      <mass value="0.17742927672123618"/>
      <inertia ixx="0.000232" iyy="7.2e-05" izz="0.000233" ixy="0.0" iyz="-1.2e-05" ixz="-0.0"/>
    </inertial>
    <visual>
      <origin xyz="-0.007878 0.284631 -0.126119" rpy="0 0 0"/>
      <geometry>
        <mesh filename="package://dropbear_simplified_urdf/meshes/waist/Right-femur-top_1.stl" scale="0.001 0.001 0.001"/>
      </geometry>
      <material name="opaque2551530"/>
    </visual>
    <collision>
      <origin xyz="-0.007878 0.284631 -0.126119" rpy="0 0 0"/>
      <geometry>
        <mesh filename="package://dropbear_simplified_urdf/meshes/waist/Right-femur-top_1.stl" scale="0.001 0.001 0.001"/>
      </geometry>
    </collision>
  </link>
  <link name="DumRightLeg_1">
    <inertial>
      <origin xyz="-2.719365716774558e-07 -0.00043367314179110217 0.002461581106896815" rpy="0 0 0"/>
      <mass value="0.06889197528787226"/>
      <inertia ixx="8e-06" iyy="1.4e-05" izz="2.2e-05" ixy="0.0" iyz="-1e-06" ixz="-0.0"/>
    </inertial>
    <visual>
      <origin xyz="-0.007871 0.35927 -0.143421" rpy="0 0 0"/>
      <geometry>
        <mesh filename="package://dropbear_simplified_urdf/meshes/waist/DumRightLeg_1.stl" scale="0.001 0.001 0.001"/>
      </geometry>
      <material name="opaque2550255"/>
    </visual>
    <collision>
      <origin xyz="-0.007871 0.35927 -0.143421" rpy="0 0 0"/>
      <geometry>
        <mesh filename="package://dropbear_simplified_urdf/meshes/waist/DumRightLeg_1.stl" scale="0.001 0.001 0.001"/>
      </geometry>
    </collision>
  </link>
  <link name="DumLeftLeg_1">
    <inertial>
      <origin xyz="6.474975373111508e-07 -0.00043367314397685375 -0.0024621363755123714" rpy="0 0 0"/>
      <mass value="0.06889197549127557"/>
      <inertia ixx="8e-06" iyy="1.4e-05" izz="2.2e-05" ixy="0.0" iyz="1e-06" ixz="-0.0"/>
    </inertial>
    <visual>
      <origin xyz="-0.007915 0.35927 0.023964" rpy="0 0 0"/>
      <geometry>
        <mesh filename="package://dropbear_simplified_urdf/meshes/waist/DumLeftLeg_1.stl" scale="0.001 0.001 0.001"/>
      </geometry>
      <material name="opaque2550255"/>
    </visual>
    <collision>
      <origin xyz="-0.007915 0.35927 0.023964" rpy="0 0 0"/>
      <geometry>
        <mesh filename="package://dropbear_simplified_urdf/meshes/waist/DumLeftLeg_1.stl" scale="0.001 0.001 0.001"/>
      </geometry>
    </collision>
  </link>
  <link name="Buttocks_1">
    <inertial>
      <origin xyz="0.07123027976226544 -0.05736392763598394 1.174722519241278e-05" rpy="0 0 0"/>
      <mass value="0.9540709404154066"/>
      <inertia ixx="0.004292" iyy="0.012882" izz="0.011871" ixy="-0.000113" iyz="0.0" ixz="-1e-06"/>
    </inertial>
    <visual>
      <origin xyz="0.140001 0.171194 -0.05969" rpy="0 0 0"/>
      <geometry>
        <mesh filename="package://dropbear_simplified_urdf/meshes/waist/Buttocks_1.stl" scale="0.001 0.001 0.001"/>
      </geometry>
      <material name="opaque20400"/>
    </visual>
    <collision>
      <origin xyz="0.140001 0.171194 -0.05969" rpy="0 0 0"/>
      <geometry>
        <mesh filename="package://dropbear_simplified_urdf/meshes/waist/Buttocks_1.stl" scale="0.001 0.001 0.001"/>
      </geometry>
    </collision>
  </link>
  <joint name="right_leg_pitch" type="continuous">
    <origin xyz="0.034981 -0.092175 0.061009" rpy="0 0 0"/>
    <parent link="Buttocks_1"/>
    <child link="Rotate-right-leg_1"/>
    <axis xyz="1.0 -3.2e-05 0.000261"/>
  </joint>
  <joint name="left_leg_pitch" type="continuous">
    <origin xyz="0.035013 -0.092175 -0.060991" rpy="0 0 0"/>
    <parent link="Buttocks_1"/>
    <child link="Rotate-left-leg_1"/>
    <axis xyz="1.0 -3.2e-05 0.000261"/>
  </joint>
  <joint name="left_leg_yaw" type="continuous">
    <origin xyz="0.112901 -0.021262 -0.005361" rpy="0 0 0"/>
    <parent link="Rotate-left-leg_1"/>
    <child link="Left-femur-top_1"/>
    <axis xyz="-7.7e-05 -0.984808 0.173648"/>
  </joint>
  <joint name="right_leg_yaw" type="continuous">
    <origin xyz="0.112898 -0.021262 0.00542" rpy="0 0 0"/>
    <parent link="Rotate-right-leg_1"/>
    <child link="Right-femur-top_1"/>
    <axis xyz="1.4e-05 -0.984808 -0.173648"/>
  </joint>
  <joint name="Connection_to_R_leg" type="fixed">
    <origin xyz="-7e-06 -0.074639 0.017302" rpy="0 0 0"/>
    <parent link="Right-femur-top_1"/>
    <child link="DumRightLeg_1"/>
  </joint>
  <joint name="Connection_to_L_leg" type="fixed">
    <origin xyz="2e-06 -0.074639 -0.017302" rpy="0 0 0"/>
    <parent link="Left-femur-top_1"/>
    <child link="DumLeftLeg_1"/>
  </joint>
  <joint name="torso_connection" type="fixed">
    <!-- <origin xyz="-0.140001 -0.171194 0.05969" rpy="0 0 0"/> -->
    <origin xyz="-0.140001 -0.171194 0.05969" rpy="0 0 0"/>
    <parent link="torso"/>
    <child link="Buttocks_1"/>
  </joint>
  <!-- Right Arm-->
  <link name="RH_2020_100mm__9__1">
    <inertial>
      <origin xyz="-0.0008466746254246146 0.0026057965560190325 0.04747235208031805" rpy="0 0 0"/>
      <mass value="0.15134342423432742"/>
      <inertia ixx="0.000135" iyy="0.000123" izz="6.9e-05" ixy="4e-06" iyz="-1e-06" ixz="0.0"/>
    </inertial>
    <visual>
      <origin xyz="0.0 0.0 -0.0021" rpy="0 0 0"/>
      <geometry>
        <mesh filename="package://dropbear_simplified_urdf/meshes/rightarm/2020_100mm__9__1.stl" scale="0.001 0.001 0.001"/>
      </geometry>
      <material name="opaque727161"/>
    </visual>
    <collision>
      <origin xyz="0.0 0.0 -0.0021" rpy="0 0 0"/>
      <geometry>
        <mesh filename="package://dropbear_simplified_urdf/meshes/rightarm/2020_100mm__9__1.stl" scale="0.001 0.001 0.001"/>
      </geometry>
    </collision>
  </link>
  <link name="RH_RMD-X8-Pro_MIR8_MIR1__1__1">
    <inertial>
      <origin xyz="0.03168610209516673 0.03722389945118263 0.009663941690489952" rpy="0 0 0"/>
      <mass value="0.39705688727274907"/>
      <inertia ixx="0.000836" iyy="0.000815" izz="0.001335" ixy="0.000113" iyz="-2.7e-05" ixz="-0.000101"/>
    </inertial>
    <visual>
      <origin xyz="-0.008343 0.025679 -0.0521" rpy="0 0 0"/>
      <geometry>
        <mesh filename="package://dropbear_simplified_urdf/meshes/rightarm/RMD-X8-Pro_MIR8_MIR1__1__1.stl" scale="0.001 0.001 0.001"/>
      </geometry>
      <material name="opaque13110895"/>
    </visual>
    <collision>
      <origin xyz="-0.008343 0.025679 -0.0521" rpy="0 0 0"/>
      <geometry>
        <mesh filename="package://dropbear_simplified_urdf/meshes/rightarm/RMD-X8-Pro_MIR8_MIR1__1__1.stl" scale="0.001 0.001 0.001"/>
      </geometry>
    </collision>
  </link>
  <link name="RH_RMD-X8-Pro_MIR8_MIR1__3__1">
    <inertial>
      <origin xyz="0.073833397772971 0.021968775763905476 0.008042518945865815" rpy="0 0 0"/>
      <mass value="0.2600729816837481"/>
      <inertia ixx="0.000377" iyy="0.00073" izz="0.000813" ixy="-0.000126" iyz="-1.8e-05" ixz="-2.4e-05"/>
    </inertial>
    <visual>
      <origin xyz="-0.101763 -0.033065 -0.0661" rpy="0 0 0"/>
      <geometry>
        <mesh filename="package://dropbear_simplified_urdf/meshes/rightarm/RMD-X8-Pro_MIR8_MIR1__3__1.stl" scale="0.001 0.001 0.001"/>
      </geometry>
      <material name="opaque13110895"/>
    </visual>
    <collision>
      <origin xyz="-0.101763 -0.033065 -0.0661" rpy="0 0 0"/>
      <geometry>
        <mesh filename="package://dropbear_simplified_urdf/meshes/rightarm/RMD-X8-Pro_MIR8_MIR1__3__1.stl" scale="0.001 0.001 0.001"/>
      </geometry>
    </collision>
  </link>
  <link name="RH_bicep-motor-mate_1">
    <inertial>
      <origin xyz="0.0036413059649407775 0.018293491559330355 -0.004857773320266552" rpy="0 0 0"/>
      <mass value="0.023400269164045275"/>
      <inertia ixx="1.3e-05" iyy="3e-06" izz="1.5e-05" ixy="-2e-06" iyz="-0.0" ixz="-0.0"/>
    </inertial>
    <visual>
      <origin xyz="-0.198295 -0.06443 -0.0566" rpy="0 0 0"/>
      <geometry>
        <mesh filename="package://dropbear_simplified_urdf/meshes/rightarm/bicep-motor-mate_1.stl" scale="0.001 0.001 0.001"/>
      </geometry>
      <material name="opaque22122113"/>
    </visual>
    <collision>
      <origin xyz="-0.198295 -0.06443 -0.0566" rpy="0 0 0"/>
      <geometry>
        <mesh filename="package://dropbear_simplified_urdf/meshes/rightarm/bicep-motor-mate_1.stl" scale="0.001 0.001 0.001"/>
      </geometry>
    </collision>
  </link>
  <link name="RH_bicep_1">
    <inertial>
      <origin xyz="0.025073949425162723 0.0037579876201125073 0.002524098473845139" rpy="0 0 0"/>
      <mass value="0.006005506060977738"/>
      <inertia ixx="0.0" iyy="3e-06" izz="3e-06" ixy="-0.0" iyz="-0.0" ixz="-0.0"/>
    </inertial>
    <visual>
      <origin xyz="-0.210008 -0.123276 -0.0596" rpy="0 0 0"/>
      <geometry>
        <mesh filename="package://dropbear_simplified_urdf/meshes/rightarm/bicep_1.stl" scale="0.001 0.001 0.001"/>
      </geometry>
      <material name="opaque245245245"/>
    </visual>
    <collision>
      <origin xyz="-0.210008 -0.123276 -0.0596" rpy="0 0 0"/>
      <geometry>
        <mesh filename="package://dropbear_simplified_urdf/meshes/rightarm/bicep_1.stl" scale="0.001 0.001 0.001"/>
      </geometry>
    </collision>
  </link>
  <link name="RH_straight-tendon_1">
    <inertial>
      <origin xyz="0.017202555024465327 -0.030696670853000735 0.01188146583171501" rpy="0 0 0"/>
      <mass value="0.03586551706248183"/>
      <inertia ixx="1.4e-05" iyy="2.2e-05" izz="3.1e-05" ixy="1.2e-05" iyz="0.0" ixz="-0.0"/>
    </inertial>
    <visual>
      <origin xyz="-0.259138 -0.132559 -0.0646" rpy="0 0 0"/>
      <geometry>
        <mesh filename="package://dropbear_simplified_urdf/meshes/rightarm/straight-tendon_1.stl" scale="0.001 0.001 0.001"/>
      </geometry>
      <material name="opaque191191191"/>
    </visual>
    <collision>
      <origin xyz="-0.259138 -0.132559 -0.0646" rpy="0 0 0"/>
      <geometry>
        <mesh filename="package://dropbear_simplified_urdf/meshes/rightarm/straight-tendon_1.stl" scale="0.001 0.001 0.001"/>
      </geometry>
    </collision>
  </link>
  <link name="RH_elbow-rear-hanger_1">
    <inertial>
      <origin xyz="0.02838273254466428 0.010873273915161949 -0.01699980031492096" rpy="0 0 0"/>
      <mass value="0.02628535609947448"/>
      <inertia ixx="8e-06" iyy="1.5e-05" izz="1.6e-05" ixy="-6e-06" iyz="-0.0" ixz="0.0"/>
    </inertial>
    <visual>
      <origin xyz="-0.269538 -0.089013 -0.0936" rpy="0 0 0"/>
      <geometry>
        <mesh filename="package://dropbear_simplified_urdf/meshes/rightarm/elbow-rear-hanger_1.stl" scale="0.001 0.001 0.001"/>
      </geometry>
      <material name="opaque808080"/>
    </visual>
    <collision>
      <origin xyz="-0.269538 -0.089013 -0.0936" rpy="0 0 0"/>
      <geometry>
        <mesh filename="package://dropbear_simplified_urdf/meshes/rightarm/elbow-rear-hanger_1.stl" scale="0.001 0.001 0.001"/>
      </geometry>
    </collision>
  </link>
  <link name="RH_RMD-X8-Pro_MIR8_MIR1__4__1">
    <inertial>
      <origin xyz="0.03483709188603029 0.029853602123198014 0.009425483341316154" rpy="0 0 0"/>
      <mass value="0.1386076860401193"/>
      <inertia ixx="0.000185" iyy="0.000188" izz="0.00016" ixy="-1e-05" iyz="5e-06" ixz="7e-06"/>
    </inertial>
    <visual>
      <origin xyz="-0.30936 -0.080341 -0.0596" rpy="0 0 0"/>
      <geometry>
        <mesh filename="package://dropbear_simplified_urdf/meshes/rightarm/RMD-X8-Pro_MIR8_MIR1__4__1.stl" scale="0.001 0.001 0.001"/>
      </geometry>
      <material name="opaque13110895"/>
    </visual>
    <collision>
      <origin xyz="-0.30936 -0.080341 -0.0596" rpy="0 0 0"/>
      <geometry>
        <mesh filename="package://dropbear_simplified_urdf/meshes/rightarm/RMD-X8-Pro_MIR8_MIR1__4__1.stl" scale="0.001 0.001 0.001"/>
      </geometry>
    </collision>
  </link>
  <link name="RH_shoulder-ex-al-interface_1">
    <inertial>
      <origin xyz="0.08747987639954247 0.0284217976129367 -3.437234066816508e-09" rpy="0 0 0"/>
      <mass value="0.3907290352810328"/>
      <inertia ixx="0.00028" iyy="0.000788" izz="0.00084" ixy="-0.000184" iyz="0.0" ixz="0.0"/>
    </inertial>
    <visual>
      <origin xyz="-0.384734 -0.124997 -0.0661" rpy="0 0 0"/>
      <geometry>
        <mesh filename="package://dropbear_simplified_urdf/meshes/rightarm/shoulder-ex-al-interface_1.stl" scale="0.001 0.001 0.001"/>
      </geometry>
      <material name="opaque22122113"/>
    </visual>
    <collision>
      <origin xyz="-0.384734 -0.124997 -0.0661" rpy="0 0 0"/>
      <geometry>
        <mesh filename="package://dropbear_simplified_urdf/meshes/rightarm/shoulder-ex-al-interface_1.stl" scale="0.001 0.001 0.001"/>
      </geometry>
    </collision>
  </link>
  <joint name="RH_torso_connection" type="revolute">
    <origin xyz="-0.054627 0.160416 0.234212" rpy="0 0 -1.5707965"/>
    <parent link="torso"/>
    <child link="RH_2020_100mm__9__1"/>
    <axis xyz="0.000261 0.0 1.0"/>
    <limit upper="3.141593" lower="-3.141593" velocity="10.0" effort="10.0"/>
  </joint>
  <joint name="RH_pitch" type="continuous">
    <origin xyz="0.008343 -0.025679 0.05" rpy="0 0 0"/>
    <parent link="RH_2020_100mm__9__1"/>
    <child link="RH_RMD-X8-Pro_MIR8_MIR1__1__1"/>
    <axis xyz="0.309017 -0.951057 0.0"/>
  </joint>
  <joint name="RH_roll" type="continuous">
    <origin xyz="0.09342 0.058744 0.014" rpy="0 0 0"/>
    <parent link="RH_RMD-X8-Pro_MIR8_MIR1__1__1"/>
    <child link="RH_RMD-X8-Pro_MIR8_MIR1__3__1"/>
    <axis xyz="0.951057 0.309017 0.0"/>
  </joint>
  <joint name="RH_elbow_joint" type="revolute">
    <origin xyz="0.096532 0.031365 -0.0095" rpy="0 0 0"/>
    <parent link="RH_RMD-X8-Pro_MIR8_MIR1__3__1"/>
    <child link="RH_bicep-motor-mate_1"/>
    <axis xyz="0.0 0.0 -1.0"/>
    <limit lower="-0.2617994166666667" upper="0.0" effort="0.0" velocity="0.0"/>
  </joint>
  <joint name="RH_Revolute 5" type="continuous">
    <mimic joint="RH_elbow_joint" multiplier="1.0"/>
    <origin xyz="0.011713 0.058846 0.003" rpy="0 0 0"/>
    <parent link="RH_bicep-motor-mate_1"/>
    <child link="RH_bicep_1"/>
    <axis xyz="0.0 0.0 1.0"/>
  </joint>
  <joint name="RH_Revolute 6" type="continuous">
    <mimic joint="RH_elbow_joint" multiplier="-2.433"/>
    <origin xyz="0.04913 0.009283 0.005" rpy="0 0 0"/>
    <parent link="RH_bicep_1"/>
    <child link="RH_straight-tendon_1"/>
    <axis xyz="-0.0 -0.0 1.0"/>
  </joint>
  <joint name="RH_Revolute 8" type="continuous">
    <mimic joint="RH_elbow_joint" multiplier="3.273"/>
    <origin xyz="0.167775 0.055948 0.0275" rpy="0 0 0"/>
    <parent link="RH_RMD-X8-Pro_MIR8_MIR1__3__1"/>
    <child link="RH_elbow-rear-hanger_1"/>
    <axis xyz="0.0 0.0 -1.0"/>
  </joint>
  <joint name="RH_Revolute 9" type="continuous">
    <mimic joint="RH_elbow_joint" multiplier="2.304"/>
    <origin xyz="0.050222 -0.052218 -0.005" rpy="0 0 0"/>
    <parent link="RH_straight-tendon_1"/>
    <child link="RH_RMD-X8-Pro_MIR8_MIR1__4__1"/>
    <axis xyz="0.0 0.0 -1.0"/>
  </joint>
  <joint name="RH_wrist_roll" type="revolute">
    <origin xyz="0.075374 0.044656 0.0065" rpy="0 0 0"/>
    <parent link="RH_RMD-X8-Pro_MIR8_MIR1__4__1"/>
    <child link="RH_shoulder-ex-al-interface_1"/>
    <axis xyz="0.951057 0.309017 -0.0"/>
    <limit upper="3.141593" lower="-3.141593" velocity="10.0" effort="10.0"/>
  </joint>
  <!-- Left Arm -->
  <link name="LH_2020_100mm__9__1">
    <inertial>
      <origin xyz="-0.0008466746254246146 0.0026057965560190325 -0.04747235208031805" rpy="0 0 0"/>
      <mass value="0.15134342423432742"/>
      <inertia ixx="0.000135" iyy="0.000123" izz="6.9e-05" ixy="4e-06" iyz="-1e-06" ixz="0.0"/>
    </inertial>
    <visual>
      <origin xyz="0.0 0.0 0.0021" rpy="0 0 0"/>
      <geometry>
        <mesh filename="package://dropbear_simplified_urdf/meshes/leftarm/2020_100mm__9__1.stl" scale="0.001 0.001 0.001"/>
      </geometry>
      <material name="opaque727161"/>
    </visual>
    <collision>
      <origin xyz="0.0 0.0 0.0021" rpy="0 0 0"/>
      <geometry>
        <mesh filename="package://dropbear_simplified_urdf/meshes/leftarm/2020_100mm__9__1.stl" scale="0.001 0.001 0.001"/>
      </geometry>
    </collision>
  </link>
  <link name="LH_RMD-X8-Pro_MIR8_MIR1__1__1">
    <inertial>
      <origin xyz="0.03168610209516673 0.03722389945118263 -0.009663941690489952" rpy="0 0 0"/>
      <mass value="0.39705688727274907"/>
      <inertia ixx="0.000836" iyy="0.000815" izz="0.001335" ixy="0.000113" iyz="-2.7e-05" ixz="-0.000101"/>
    </inertial>
    <visual>
      <origin xyz="-0.008343 0.025679 0.0521" rpy="0 0 0"/>
      <geometry>
        <mesh filename="package://dropbear_simplified_urdf/meshes/leftarm/RMD-X8-Pro_MIR8_MIR1__1__1.stl" scale="0.001 0.001 0.001"/>
      </geometry>
      <material name="opaque13110895"/>
    </visual>
    <collision>
      <origin xyz="-0.008343 0.025679 0.0521" rpy="0 0 0"/>
      <geometry>
        <mesh filename="package://dropbear_simplified_urdf/meshes/leftarm/RMD-X8-Pro_MIR8_MIR1__1__1.stl" scale="0.001 0.001 0.001"/>
      </geometry>
    </collision>
  </link>
  <link name="LH_RMD-X8-Pro_MIR8_MIR1__3__1">
    <inertial>
      <origin xyz="0.073833397772971 0.021968775763905476 -0.008042518945865815" rpy="0 0 0"/>
      <mass value="0.2600729816837481"/>
      <inertia ixx="0.000377" iyy="0.00073" izz="0.000813" ixy="-0.000126" iyz="-1.8e-05" ixz="-2.4e-05"/>
    </inertial>
    <visual>
      <origin xyz="-0.101763 -0.033065 0.0661" rpy="0 0 0"/>
      <geometry>
        <mesh filename="package://dropbear_simplified_urdf/meshes/leftarm/RMD-X8-Pro_MIR8_MIR1__3__1.stl" scale="0.001 0.001 0.001"/>
      </geometry>
      <material name="opaque13110895"/>
    </visual>
    <collision>
      <origin xyz="-0.101763 -0.033065 0.0661" rpy="0 0 0"/>
      <geometry>
        <mesh filename="package://dropbear_simplified_urdf/meshes/leftarm/RMD-X8-Pro_MIR8_MIR1__3__1.stl" scale="0.001 0.001 0.001"/>
      </geometry>
    </collision>
  </link>
  <link name="LH_bicep-motor-mate_1">
    <inertial>
      <origin xyz="0.0036413059649407775 0.018293491559330355 0.004857773320266552" rpy="0 0 0"/>
      <mass value="0.023400269164045275"/>
      <inertia ixx="1.3e-05" iyy="3e-06" izz="1.5e-05" ixy="-2e-06" iyz="-0.0" ixz="-0.0"/>
    </inertial>
    <visual>
      <origin xyz="-0.198295 -0.06443 0.0566" rpy="0 0 0"/>
      <geometry>
        <mesh filename="package://dropbear_simplified_urdf/meshes/leftarm/bicep-motor-mate_1.stl" scale="0.001 0.001 0.001"/>
      </geometry>
      <material name="opaque22122113"/>
    </visual>
    <collision>
      <origin xyz="-0.198295 -0.06443 0.0566" rpy="0 0 0"/>
      <geometry>
        <mesh filename="package://dropbear_simplified_urdf/meshes/leftarm/bicep-motor-mate_1.stl" scale="0.001 0.001 0.001"/>
      </geometry>
    </collision>
  </link>
  <link name="LH_bicep_1">
    <inertial>
      <origin xyz="0.025073949425162723 0.0037579876201125073 -0.002524098473845139" rpy="0 0 0"/>
      <mass value="0.006005506060977738"/>
      <inertia ixx="0.0" iyy="3e-06" izz="3e-06" ixy="-0.0" iyz="-0.0" ixz="-0.0"/>
    </inertial>
    <visual>
      <origin xyz="-0.210008 -0.123276 0.0596" rpy="0 0 0"/>
      <geometry>
        <mesh filename="package://dropbear_simplified_urdf/meshes/leftarm/bicep_1.stl" scale="0.001 0.001 0.001"/>
      </geometry>
      <material name="opaque245245245"/>
    </visual>
    <collision>
      <origin xyz="-0.210008 -0.123276 0.0596" rpy="0 0 0"/>
      <geometry>
        <mesh filename="package://dropbear_simplified_urdf/meshes/leftarm/bicep_1.stl" scale="0.001 0.001 0.001"/>
      </geometry>
    </collision>
  </link>
  <link name="LH_straight-tendon_1">
    <inertial>
      <origin xyz="0.017202555024465327 -0.030696670853000735 -0.01188146583171501" rpy="0 0 0"/>
      <mass value="0.03586551706248183"/>
      <inertia ixx="1.4e-05" iyy="2.2e-05" izz="3.1e-05" ixy="1.2e-05" iyz="0.0" ixz="-0.0"/>
    </inertial>
    <visual>
      <origin xyz="-0.259138 -0.132559 0.0646" rpy="0 0 0"/>
      <geometry>
        <mesh filename="package://dropbear_simplified_urdf/meshes/leftarm/straight-tendon_1.stl" scale="0.001 0.001 0.001"/>
      </geometry>
      <material name="opaque191191191"/>
    </visual>
    <collision>
      <origin xyz="-0.259138 -0.132559 0.0646" rpy="0 0 0"/>
      <geometry>
        <mesh filename="package://dropbear_simplified_urdf/meshes/leftarm/straight-tendon_1.stl" scale="0.001 0.001 0.001"/>
      </geometry>
    </collision>
  </link>
  <link name="LH_elbow-rear-hanger_1">
    <inertial>
      <origin xyz="0.02838273254466428 0.010873273915161949 0.01699980031492096" rpy="0 0 0"/>
      <mass value="0.02628535609947448"/>
      <inertia ixx="8e-06" iyy="1.5e-05" izz="1.6e-05" ixy="-6e-06" iyz="-0.0" ixz="0.0"/>
    </inertial>
    <visual>
      <origin xyz="-0.269538 -0.089013 0.0936" rpy="0 0 0"/>
      <geometry>
        <mesh filename="package://dropbear_simplified_urdf/meshes/leftarm/elbow-rear-hanger_1.stl" scale="0.001 0.001 0.001"/>
      </geometry>
      <material name="opaque808080"/>
    </visual>
    <collision>
      <origin xyz="-0.269538 -0.089013 0.0936" rpy="0 0 0"/>
      <geometry>
        <mesh filename="package://dropbear_simplified_urdf/meshes/leftarm/elbow-rear-hanger_1.stl" scale="0.001 0.001 0.001"/>
      </geometry>
    </collision>
  </link>
  <link name="LH_RMD-X8-Pro_MIR8_MIR1__4__1">
    <inertial>
      <origin xyz="0.03483709188603029 0.029853602123198014 -0.009425483341316154" rpy="0 0 0"/>
      <mass value="0.1386076860401193"/>
      <inertia ixx="0.000185" iyy="0.000188" izz="0.00016" ixy="-1e-05" iyz="5e-06" ixz="7e-06"/>
    </inertial>
    <visual>
      <origin xyz="-0.30936 -0.080341 0.0596" rpy="0 0 0"/>
      <geometry>
        <mesh filename="package://dropbear_simplified_urdf/meshes/leftarm/RMD-X8-Pro_MIR8_MIR1__4__1.stl" scale="0.001 0.001 0.001"/>
      </geometry>
      <material name="opaque13110895"/>
    </visual>
    <collision>
      <origin xyz="-0.30936 -0.080341 0.0596" rpy="0 0 0"/>
      <geometry>
        <mesh filename="package://dropbear_simplified_urdf/meshes/leftarm/RMD-X8-Pro_MIR8_MIR1__4__1.stl" scale="0.001 0.001 0.001"/>
      </geometry>
    </collision>
  </link>
  <link name="LH_shoulder-ex-al-interface_1">
    <inertial>
      <origin xyz="0.08747987639954247 0.0284217976129367 3.437234066816508e-09" rpy="0 0 0"/>
      <mass value="0.3907290352810328"/>
      <inertia ixx="0.00028" iyy="0.000788" izz="0.00084" ixy="-0.000184" iyz="0.0" ixz="0.0"/>
    </inertial>
    <visual>
      <origin xyz="-0.384734 -0.124997 0.0661" rpy="0 0 0"/>
      <geometry>
        <mesh filename="package://dropbear_simplified_urdf/meshes/leftarm/shoulder-ex-al-interface_1.stl" scale="0.001 0.001 0.001"/>
      </geometry>
      <material name="opaque22122113"/>
    </visual>
    <collision>
      <origin xyz="-0.384734 -0.124997 0.0661" rpy="0 0 0"/>
      <geometry>
        <mesh filename="package://dropbear_simplified_urdf/meshes/leftarm/shoulder-ex-al-interface_1.stl" scale="0.001 0.001 0.001"/>
      </geometry>
    </collision>
  </link>
  <joint name="LH_torso_connection" type="revolute">
    <origin xyz="-0.054536 0.160416 -0.114788" rpy="0 0 -1.5707965"/>
    <parent link="torso"/>
    <child link="LH_2020_100mm__9__1"/>
    <axis xyz="0.000261 0.0 -1.0"/>
    <limit upper="3.141593" lower="-3.141593" velocity="10.0" effort="10.0"/>
  </joint>
  <joint name="LH_pitch" type="continuous">
    <origin xyz="0.008343 -0.025679 -0.05" rpy="0 0 0"/>
    <parent link="LH_2020_100mm__9__1"/>
    <child link="LH_RMD-X8-Pro_MIR8_MIR1__1__1"/>
    <axis xyz="0.309017 -0.951057 0.0"/>
  </joint>
  <joint name="LH_roll" type="continuous">
    <origin xyz="0.09342 0.058744 -0.014" rpy="0 0 0"/>
    <parent link="LH_RMD-X8-Pro_MIR8_MIR1__1__1"/>
    <child link="LH_RMD-X8-Pro_MIR8_MIR1__3__1"/>
    <axis xyz="0.951057 0.309017 0.0"/>
  </joint>
  <joint name="LH_elbow_joint" type="revolute">
    <origin xyz="0.096532 0.031365 0.0095" rpy="0 0 0"/>
    <parent link="LH_RMD-X8-Pro_MIR8_MIR1__3__1"/>
    <child link="LH_bicep-motor-mate_1"/>
    <axis xyz="0.0 0.0 -1.0"/>
    <limit lower="-0.2617994166666667" upper="0.0" effort="0.0" velocity="0.0"/>
  </joint>
  <joint name="LH_Revolute 5" type="continuous">
    <mimic joint="LH_elbow_joint" multiplier="1.0"/>
    <origin xyz="0.011713 0.058846 -0.003" rpy="0 0 0"/>
    <parent link="LH_bicep-motor-mate_1"/>
    <child link="LH_bicep_1"/>
    <axis xyz="0.0 0.0 1.0"/>
  </joint>
  <joint name="LH_Revolute 6" type="continuous">
    <mimic joint="LH_elbow_joint" multiplier="-2.433"/>
    <origin xyz="0.04913 0.009283 -0.005" rpy="0 0 0"/>
    <parent link="LH_bicep_1"/>
    <child link="LH_straight-tendon_1"/>
    <axis xyz="-0.0 -0.0 1.0"/>
  </joint>
  <joint name="LH_Revolute 8" type="continuous">
    <mimic joint="LH_elbow_joint" multiplier="3.273"/>
    <origin xyz="0.167775 0.055948 -0.0275" rpy="0 0 0"/>
    <parent link="LH_RMD-X8-Pro_MIR8_MIR1__3__1"/>
    <child link="LH_elbow-rear-hanger_1"/>
    <axis xyz="0.0 0.0 -1.0"/>
  </joint>
  <joint name="LH_Revolute 9" type="continuous">
    <mimic joint="LH_elbow_joint" multiplier="2.304"/>
    <origin xyz="0.050222 -0.052218 0.005" rpy="0 0 0"/>
    <parent link="LH_straight-tendon_1"/>
    <child link="LH_RMD-X8-Pro_MIR8_MIR1__4__1"/>
    <axis xyz="0.0 0.0 -1.0"/>
  </joint>
  <joint name="LH_wrist_roll" type="revolute">
    <origin xyz="0.075374 0.044656 -0.0065" rpy="0 0 0"/>
    <parent link="LH_RMD-X8-Pro_MIR8_MIR1__4__1"/>
    <child link="LH_shoulder-ex-al-interface_1"/>
    <axis xyz="0.951057 0.309017 -0.0"/>
    <limit upper="3.141593" lower="-3.141593" velocity="10.0" effort="10.0"/>
  </joint>
  <!-- Right Leg -->
  <link name="RL_RMD-X10-S2_MIR4__3_Rotor_1">
    <inertial>
      <origin xyz="-4.2114800383186157e-07 1.6545859007732755e-05 0.011165715023864597" rpy="0 0 0"/>
      <mass value="0.030077996769097937"/>
      <inertia ixx="7e-06" iyy="7e-06" izz="1e-05" ixy="0.0" iyz="0.0" ixz="-0.0"/>
    </inertial>
    <visual>
      <origin xyz="0.191553 -0.380845 0.16988" rpy="0 0 0"/>
      <geometry>
        <mesh filename="package://dropbear_simplified_urdf/meshes/rightleg/RMD-X10-S2_MIR4__3_Rotor_1.stl" scale="0.001 0.001 0.001"/>
      </geometry>
      <material name="opaque727161"/>
    </visual>
    <collision>
      <origin xyz="0.191553 -0.380845 0.16988" rpy="0 0 0"/>
      <geometry>
        <mesh filename="package://dropbear_simplified_urdf/meshes/rightleg/RMD-X10-S2_MIR4__3_Rotor_1.stl" scale="0.001 0.001 0.001"/>
      </geometry>
    </collision>
  </link>
  <link name="RL_RMD-X10-S2_MIR4__3_Stator_1">
    <inertial>
      <origin xyz="-0.036718214168607155 -0.05423872836967342 0.033683692448425506" rpy="0 0 0"/>
      <mass value="0.5483656288061021"/>
      <inertia ixx="0.002044" iyy="0.001828" izz="0.002663" ixy="-0.000494" iyz="0.000171" ixz="0.000142"/>
    </inertial>
    <visual>
      <origin xyz="0.191553 -0.380845 0.16988" rpy="0 0 0"/>
      <geometry>
        <mesh filename="package://dropbear_simplified_urdf/meshes/rightleg/RMD-X10-S2_MIR4__3_Stator_1.stl" scale="0.001 0.001 0.001"/>
      </geometry>
      <material name="opaque727161"/>
    </visual>
    <collision>
      <origin xyz="0.191553 -0.380845 0.16988" rpy="0 0 0"/>
      <geometry>
        <mesh filename="package://dropbear_simplified_urdf/meshes/rightleg/RMD-X10-S2_MIR4__3_Stator_1.stl" scale="0.001 0.001 0.001"/>
      </geometry>
    </collision>
  </link>
  <link name="RL_RMD-X10-S2_MIR4Rotor_1">
    <inertial>
      <origin xyz="0.004336745411893661 -0.10083451364614476 0.02279900080800254" rpy="0 0 0"/>
      <mass value="0.618391872847042"/>
      <inertia ixx="0.006212" iyy="0.000506" izz="0.00633" ixy="0.000357" iyz="0.000167" ixz="-2e-05"/>
    </inertial>
    <visual>
      <origin xyz="0.263279 -0.282145 0.106399" rpy="0 0 0"/>
      <geometry>
        <mesh filename="package://dropbear_simplified_urdf/meshes/rightleg/RMD-X10-S2_MIR4Rotor_1.stl" scale="0.001 0.001 0.001"/>
      </geometry>
      <material name="opaque727161"/>
    </visual>
    <collision>
      <origin xyz="0.263279 -0.282145 0.106399" rpy="0 0 0"/>
      <geometry>
        <mesh filename="package://dropbear_simplified_urdf/meshes/rightleg/RMD-X10-S2_MIR4Rotor_1.stl" scale="0.001 0.001 0.001"/>
      </geometry>
    </collision>
  </link>
  <link name="RL_double-bracket_1">
    <inertial>
      <origin xyz="-0.0024174004635344193 -0.17065516771979955 -0.026188805978005034" rpy="0 0 0"/>
      <mass value="0.5941741295649757"/>
      <inertia ixx="0.006967" iyy="0.001718" izz="0.006134" ixy="-0.000485" iyz="0.001043" ixz="-4.1e-05"/>
    </inertial>
    <visual>
      <origin xyz="0.141302 -0.364392 0.089867" rpy="0 0 0"/>
      <geometry>
        <mesh filename="package://dropbear_simplified_urdf/meshes/rightleg/double-bracket_1.stl" scale="0.001 0.001 0.001"/>
      </geometry>
      <material name="opaque245245245"/>
    </visual>
    <collision>
      <origin xyz="0.141302 -0.364392 0.089867" rpy="0 0 0"/>
      <geometry>
        <mesh filename="package://dropbear_simplified_urdf/meshes/rightleg/double-bracket_1.stl" scale="0.001 0.001 0.001"/>
      </geometry>
    </collision>
  </link>
  <link name="RL_conjstraint-knee-test-oute_1">
    <inertial>
      <origin xyz="0.0388201387802167 0.0020245681514819616 -0.009921514877255011" rpy="0 0 0"/>
      <mass value="0.17273623323347898"/>
      <inertia ixx="0.000316" iyy="0.000318" izz="0.000394" ixy="-0.000137" iyz="0.0" ixz="-0.0"/>
    </inertial>
    <visual>
      <origin xyz="0.243318 0.012178 0.069894" rpy="0 0 0"/>
      <geometry>
        <mesh filename="package://dropbear_simplified_urdf/meshes/rightleg/conjstraint-knee-test-oute_1.stl" scale="0.001 0.001 0.001"/>
      </geometry>
      <material name="opaque191191191"/>
    </visual>
    <collision>
      <origin xyz="0.243318 0.012178 0.069894" rpy="0 0 0"/>
      <geometry>
        <mesh filename="package://dropbear_simplified_urdf/meshes/rightleg/conjstraint-knee-test-oute_1.stl" scale="0.001 0.001 0.001"/>
      </geometry>
    </collision>
  </link>
  <link name="RL_knee-strap-second-test_1">
    <inertial>
      <origin xyz="0.02289817601670563 -0.05000799500593258 -0.009994439699335583" rpy="0 0 0"/>
      <mass value="0.06382003552060014"/>
      <inertia ixx="9.8e-05" iyy="3.7e-05" izz="0.000101" ixy="3.6e-05" iyz="-2e-06" ixz="1e-06"/>
    </inertial>
    <visual>
      <origin xyz="0.20361 -0.034819 0.069883" rpy="0 0 0"/>
      <geometry>
        <mesh filename="package://dropbear_simplified_urdf/meshes/rightleg/knee-strap-second-test_1.stl" scale="0.001 0.001 0.001"/>
      </geometry>
      <material name="opaque245245245"/>
    </visual>
    <collision>
      <origin xyz="0.20361 -0.034819 0.069883" rpy="0 0 0"/>
      <geometry>
        <mesh filename="package://dropbear_simplified_urdf/meshes/rightleg/knee-strap-second-test_1.stl" scale="0.001 0.001 0.001"/>
      </geometry>
    </collision>
  </link>
  <link name="RL_double-bracket-10deg_MIR_MIR_MIR_1">
    <inertial>
      <origin xyz="-0.023030853980666094 -0.20870609984957944 0.04394857851730673" rpy="0 0 0"/>
      <mass value="0.972328284996074"/>
      <inertia ixx="0.01683" iyy="0.002068" izz="0.017418" ixy="0.001098" iyz="0.002791" ixz="-0.000198"/>
    </inertial>
    <visual>
      <origin xyz="0.157814 0.065197 0.089871" rpy="0 0 0"/>
      <geometry>
        <mesh filename="package://dropbear_simplified_urdf/meshes/rightleg/double-bracket-10deg_MIR_MIR_MIR_1.stl" scale="0.001 0.001 0.001"/>
      </geometry>
      <material name="opaque245245245"/>
    </visual>
    <collision>
      <origin xyz="0.157814 0.065197 0.089871" rpy="0 0 0"/>
      <geometry>
        <mesh filename="package://dropbear_simplified_urdf/meshes/rightleg/double-bracket-10deg_MIR_MIR_MIR_1.stl" scale="0.001 0.001 0.001"/>
      </geometry>
    </collision>
  </link>
  <link name="RL_calf-motor-driver-ext_1">
    <inertial>
      <origin xyz="0.01018087483375632 -0.006406414275960254 -0.010824350415873277" rpy="0 0 0"/>
      <mass value="0.03904654588774605"/>
      <inertia ixx="7e-06" iyy="1.4e-05" izz="1.8e-05" ixy="4e-06" iyz="-0.0" ixz="1e-06"/>
    </inertial>
    <visual>
      <origin xyz="0.212594 0.236458 0.073139" rpy="0 0 0"/>
      <geometry>
        <mesh filename="package://dropbear_simplified_urdf/meshes/rightleg/calf-motor-driver-ext_1.stl" scale="0.001 0.001 0.001"/>
      </geometry>
      <material name="opaque2552550"/>
    </visual>
    <collision>
      <origin xyz="0.212594 0.236458 0.073139" rpy="0 0 0"/>
      <geometry>
        <mesh filename="package://dropbear_simplified_urdf/meshes/rightleg/calf-motor-driver-ext_1.stl" scale="0.001 0.001 0.001"/>
      </geometry>
    </collision>
  </link>
  <link name="RL_290mm-tie-rod_v1_1">
    <inertial>
      <origin xyz="-0.008618850844608478 -0.1441043639671668 0.01627466914432321" rpy="0 0 0"/>
      <mass value="0.31671295572679664"/>
      <inertia ixx="0.00297" iyy="0.000108" izz="0.002894" ixy="-0.000175" iyz="0.000506" ixz="3.1e-05"/>
    </inertial>
    <visual>
      <origin xyz="0.175826 0.256902 0.096784" rpy="0 0 0"/>
      <geometry>
        <mesh filename="package://dropbear_simplified_urdf/meshes/rightleg/290mm-tie-rod_v1_1.stl" scale="0.001 0.001 0.001"/>
      </geometry>
      <material name="opaque191191191"/>
    </visual>
    <collision>
      <origin xyz="0.175826 0.256902 0.096784" rpy="0 0 0"/>
      <geometry>
        <mesh filename="package://dropbear_simplified_urdf/meshes/rightleg/290mm-tie-rod_v1_1.stl" scale="0.001 0.001 0.001"/>
      </geometry>
    </collision>
  </link>
  <link name="RL_calf-motor-driver-ext__1__1">
    <inertial>
      <origin xyz="0.010997941306614883 0.002322003619584123 0.011641556204172841" rpy="0 0 0"/>
      <mass value="0.03904654588774605"/>
      <inertia ixx="5e-06" iyy="1.6e-05" izz="1.8e-05" ixy="-1e-06" iyz="0.0" ixz="-2e-06"/>
    </inertial>
    <visual>
      <origin xyz="0.210465 0.325998 0.016729" rpy="0 0 0"/>
      <geometry>
        <mesh filename="package://dropbear_simplified_urdf/meshes/rightleg/calf-motor-driver-ext__1__1.stl" scale="0.001 0.001 0.001"/>
      </geometry>
      <material name="opaque2552550"/>
    </visual>
    <collision>
      <origin xyz="0.210465 0.325998 0.016729" rpy="0 0 0"/>
      <geometry>
        <mesh filename="package://dropbear_simplified_urdf/meshes/rightleg/calf-motor-driver-ext__1__1.stl" scale="0.001 0.001 0.001"/>
      </geometry>
    </collision>
  </link>
  <link name="RL_210mm-tie-rod_v1_1">
    <inertial>
      <origin xyz="-0.011696719594497779 -0.10121354316624126 0.026926339548267383" rpy="0 0 0"/>
      <mass value="0.24352587221730845"/>
      <inertia ixx="0.001287" iyy="6.1e-05" izz="0.001267" ixy="-0.000141" iyz="0.000219" ixz="2.5e-05"/>
    </inertial>
    <visual>
      <origin xyz="0.170599 0.320333 -0.009872" rpy="0 0 0"/>
      <geometry>
        <mesh filename="package://dropbear_simplified_urdf/meshes/rightleg/210mm-tie-rod_v1_1.stl" scale="0.001 0.001 0.001"/>
      </geometry>
      <material name="opaque191191191"/>
    </visual>
    <collision>
      <origin xyz="0.170599 0.320333 -0.009872" rpy="0 0 0"/>
      <geometry>
        <mesh filename="package://dropbear_simplified_urdf/meshes/rightleg/210mm-tie-rod_v1_1.stl" scale="0.001 0.001 0.001"/>
      </geometry>
    </collision>
  </link>
  <link name="RL_basis_left_1">
    <inertial>
      <origin xyz="-0.00029764813988561456 -0.020222597886624838 0.013552063748571314" rpy="0 0 0"/>
      <mass value="0.09371675054362279"/>
      <inertia ixx="6.4e-05" iyy="3.3e-05" izz="5.6e-05" ixy="-0.0" iyz="4e-06" ixz="0.0"/>
    </inertial>
    <visual>
      <origin xyz="0.146891 0.512935 0.013949" rpy="0 0 0"/>
      <geometry>
        <mesh filename="package://dropbear_simplified_urdf/meshes/rightleg/basis_left_1.stl" scale="0.001 0.001 0.001"/>
      </geometry>
      <material name="opaque245245245"/>
    </visual>
    <collision>
      <origin xyz="0.146891 0.512935 0.013949" rpy="0 0 0"/>
      <geometry>
        <mesh filename="package://dropbear_simplified_urdf/meshes/rightleg/basis_left_1.stl" scale="0.001 0.001 0.001"/>
      </geometry>
    </collision>
  </link>
  <link name="RL_heel-bracket_left_1">
    <inertial>
      <origin xyz="0.012688445147171948 -0.00771159949391742 0.0016067039154728817" rpy="0 0 0"/>
      <mass value="0.7069787408674384"/>
      <inertia ixx="0.000698" iyy="0.005471" izz="0.005014" ixy="0.000121" iyz="-8.5e-05" ixz="-4.2e-05"/>
    </inertial>
    <visual>
      <origin xyz="0.127372 0.550788 -0.002967" rpy="0 0 0"/>
      <geometry>
        <mesh filename="package://dropbear_simplified_urdf/meshes/rightleg/heel-bracket_left_1.stl" scale="0.001 0.001 0.001"/>
      </geometry>
      <material name="opaque245245245"/>
    </visual>
    <collision>
      <origin xyz="0.127372 0.550788 -0.002967" rpy="0 0 0"/>
      <geometry>
        <mesh filename="package://dropbear_simplified_urdf/meshes/rightleg/heel-bracket_left_1.stl" scale="0.001 0.001 0.001"/>
      </geometry>
    </collision>
  </link>
  <joint name="RL_leg_connection" type="fixed">
    <origin xyz="0.0 0.0 0.0" rpy="0.17453294444444445 0 0"/>
    <parent link="DumRightLeg_1"/>
    <child link="RL_RMD-X10-S2_MIR4__3_Rotor_1"/>
  </joint>
  <joint name="RL_hipjoint" type="revolute">
    <origin xyz="0.0 0.0 0.0" rpy="0 0 0"/>
    <parent link="RL_RMD-X10-S2_MIR4__3_Rotor_1"/>
    <child link="RL_RMD-X10-S2_MIR4__3_Stator_1"/>
    <axis xyz="0.000261 -0.0 -1.0"/>
    <limit upper="1.5707965" lower="-1.5707965" velocity="10.0" effort="10.0"/>
  </joint>
  <joint name="RL_kneejoint" type="revolute">
    <origin xyz="-0.071726 -0.0987 0.063481" rpy="0 0 0"/>
    <parent link="RL_RMD-X10-S2_MIR4__3_Stator_1"/>
    <child link="RL_RMD-X10-S2_MIR4Rotor_1"/>
    <axis xyz="-0.000261 0.0 1.0"/>
    <limit upper="0.78539825" lower="-0.78539825" velocity="10.0" effort="10.0"/>
  </joint>
  <joint name="RL_Revolute 4" type="continuous">
    <mimic joint="RL_kneejoint" multiplier="0.9062"/>
    <origin xyz="0.050251 -0.016453 0.080013" rpy="0 0 0"/>
    <parent link="RL_RMD-X10-S2_MIR4__3_Stator_1"/>
    <child link="RL_double-bracket_1"/>
    <axis xyz="-0.000261 0.0 1.0"/>
  </joint>
  <joint name="RL_Revolute 5" type="continuous">
    <mimic joint="RL_kneejoint" multiplier="-1.258"/>
    <origin xyz="0.019961 -0.294323 0.036505" rpy="0 0 0"/>
    <parent link="RL_RMD-X10-S2_MIR4Rotor_1"/>
    <child link="RL_conjstraint-knee-test-oute_1"/>
    <axis xyz="-0.000261 0.0 1.0"/>
  </joint>
  <joint name="RL_Revolute 7" type="continuous">
    <mimic joint="RL_kneejoint" multiplier="-1.5277"/>
    <origin xyz="-0.062308 -0.329573 0.019984" rpy="0 0 0"/>
    <parent link="RL_double-bracket_1"/>
    <child link="RL_knee-strap-second-test_1"/>
    <axis xyz="-0.000261 0.0 1.0"/>
  </joint>
  <joint name="RL_Revolute 8" type="continuous">
    <mimic joint="RL_kneejoint" multiplier="-1.0405"/>
    <origin xyz="0.045796 -0.100016 -0.019988" rpy="0 0 0"/>
    <parent link="RL_knee-strap-second-test_1"/>
    <child link="RL_double-bracket-10deg_MIR_MIR_MIR_1"/>
    <axis xyz="-0.000261 0.0 1.0"/>
  </joint>
  <joint name="RL_Revolute 10" type="continuous">
    <origin xyz="-0.05478 -0.171261 0.016732" rpy="0 0 0"/>
    <parent link="RL_double-bracket-10deg_MIR_MIR_MIR_1"/>
    <child link="RL_calf-motor-driver-ext_1"/>
    <axis xyz="0.004499 -0.173596 -0.984807"/>
  </joint>
  <joint name="RL_Revolute 11" type="continuous">
    <mimic joint="RL_Revolute 10" multiplier="-1.1418"/>
    <origin xyz="0.036768 -0.020444 -0.023645" rpy="0 0 0"/>
    <parent link="RL_calf-motor-driver-ext_1"/>
    <child link="RL_290mm-tie-rod_v1_1"/>
    <axis xyz="0.004499 -0.173596 -0.984807"/>
  </joint>
  <joint name="RL_Revolute 12" type="continuous">
    <mimic joint="RL_Revolute 10" multiplier="-0.8322"/>
    <origin xyz="-0.052651 -0.260801 0.073142" rpy="0 0 0"/>
    <parent link="RL_double-bracket-10deg_MIR_MIR_MIR_1"/>
    <child link="RL_calf-motor-driver-ext__1__1"/>
    <axis xyz="-0.004499 0.173596 0.984807"/>
  </joint>
  <joint name="RL_Revolute 13" type="continuous">
    <mimic joint="RL_Revolute 10" multiplier="0.9436"/>
    <origin xyz="0.039866 0.005665 0.026601" rpy="0 0 0"/>
    <parent link="RL_calf-motor-driver-ext__1__1"/>
    <child link="RL_210mm-tie-rod_v1_1"/>
    <axis xyz="-0.004499 0.173596 0.984807"/>
  </joint>
  <joint name="RL_Revolute 14" type="continuous">
    <mimic joint="RL_Revolute 10" multiplier="-0.7843"/>
    <origin xyz="0.010923 -0.447738 0.075922" rpy="0 0 0"/>
    <parent link="RL_double-bracket-10deg_MIR_MIR_MIR_1"/>
    <child link="RL_basis_left_1"/>
    <axis xyz="0.004499 -0.173596 -0.984807"/>
  </joint>
  <joint name="RL_Revolute 15" type="continuous">
    <origin xyz="0.019519 -0.037853 0.016916" rpy="0 0 0"/>
    <parent link="RL_basis_left_1"/>
    <child link="RL_heel-bracket_left_1"/>
    <axis xyz="0.999931 -0.00994 0.006321"/>
  </joint>
  <!-- Left Leg -->
  <link name="LL_RMD-X10-S2_MIR4__3_Rotor_1">
    <inertial>
      <origin xyz="-4.2114800383186157e-07 1.6545859007732755e-05 -0.011165715023864597" rpy="0 0 0"/>
      <mass value="0.030077996769097937"/>
      <inertia ixx="7e-06" iyy="7e-06" izz="1e-05" ixy="0.0" iyz="0.0" ixz="-0.0"/>
    </inertial>
    <visual>
      <origin xyz="0.191553 -0.380845 -0.16988" rpy="0 0 0"/>
      <geometry>
        <mesh filename="package://dropbear_simplified_urdf/meshes/leftleg/RMD-X10-S2_MIR4__3_Rotor_1.stl" scale="0.001 0.001 0.001"/>
      </geometry>
      <material name="opaque727161"/>
    </visual>
    <collision>
      <origin xyz="0.191553 -0.380845 -0.16988" rpy="0 0 0"/>
      <geometry>
        <mesh filename="package://dropbear_simplified_urdf/meshes/leftleg/RMD-X10-S2_MIR4__3_Rotor_1.stl" scale="0.001 0.001 0.001"/>
      </geometry>
    </collision>
  </link>
  <link name="LL_RMD-X10-S2_MIR4__3_Stator_1">
    <inertial>
      <origin xyz="-0.036718214168607155 -0.05423872836967342 -0.033683692448425506" rpy="0 0 0"/>
      <mass value="0.5483656288061021"/>
      <inertia ixx="0.002044" iyy="0.001828" izz="0.002663" ixy="-0.000494" iyz="0.000171" ixz="0.000142"/>
    </inertial>
    <visual>
      <origin xyz="0.191553 -0.380845 -0.16988" rpy="0 0 0"/>
      <geometry>
        <mesh filename="package://dropbear_simplified_urdf/meshes/leftleg/RMD-X10-S2_MIR4__3_Stator_1.stl" scale="0.001 0.001 0.001"/>
      </geometry>
      <material name="opaque727161"/>
    </visual>
    <collision>
      <origin xyz="0.191553 -0.380845 -0.16988" rpy="0 0 0"/>
      <geometry>
        <mesh filename="package://dropbear_simplified_urdf/meshes/leftleg/RMD-X10-S2_MIR4__3_Stator_1.stl" scale="0.001 0.001 0.001"/>
      </geometry>
    </collision>
  </link>
  <link name="LL_RMD-X10-S2_MIR4Rotor_1">
    <inertial>
      <origin xyz="0.004336745411893661 -0.10083451364614476 -0.02279900080800254" rpy="0 0 0"/>
      <mass value="0.618391872847042"/>
      <inertia ixx="0.006212" iyy="0.000506" izz="0.00633" ixy="0.000357" iyz="0.000167" ixz="-2e-05"/>
    </inertial>
    <visual>
      <origin xyz="0.263279 -0.282145 -0.106399" rpy="0 0 0"/>
      <geometry>
        <mesh filename="package://dropbear_simplified_urdf/meshes/leftleg/RMD-X10-S2_MIR4Rotor_1.stl" scale="0.001 0.001 0.001"/>
      </geometry>
      <material name="opaque727161"/>
    </visual>
    <collision>
      <origin xyz="0.263279 -0.282145 -0.106399" rpy="0 0 0"/>
      <geometry>
        <mesh filename="package://dropbear_simplified_urdf/meshes/leftleg/RMD-X10-S2_MIR4Rotor_1.stl" scale="0.001 0.001 0.001"/>
      </geometry>
    </collision>
  </link>
  <link name="LL_double-bracket_1">
    <inertial>
      <origin xyz="-0.0024174004635344193 -0.17065516771979955 0.026188805978005034" rpy="0 0 0"/>
      <mass value="0.5941741295649757"/>
      <inertia ixx="0.006967" iyy="0.001718" izz="0.006134" ixy="-0.000485" iyz="0.001043" ixz="-4.1e-05"/>
    </inertial>
    <visual>
      <origin xyz="0.141302 -0.364392 -0.089867" rpy="0 0 0"/>
      <geometry>
        <mesh filename="package://dropbear_simplified_urdf/meshes/leftleg/double-bracket_1.stl" scale="0.001 0.001 0.001"/>
      </geometry>
      <material name="opaque245245245"/>
    </visual>
    <collision>
      <origin xyz="0.141302 -0.364392 -0.089867" rpy="0 0 0"/>
      <geometry>
        <mesh filename="package://dropbear_simplified_urdf/meshes/leftleg/double-bracket_1.stl" scale="0.001 0.001 0.001"/>
      </geometry>
    </collision>
  </link>
  <link name="LL_conjstraint-knee-test-oute_1">
    <inertial>
      <origin xyz="0.0388201387802167 0.0020245681514819616 0.009921514877255011" rpy="0 0 0"/>
      <mass value="0.17273623323347898"/>
      <inertia ixx="0.000316" iyy="0.000318" izz="0.000394" ixy="-0.000137" iyz="0.0" ixz="-0.0"/>
    </inertial>
    <visual>
      <origin xyz="0.243318 0.012178 -0.069894" rpy="0 0 0"/>
      <geometry>
        <mesh filename="package://dropbear_simplified_urdf/meshes/leftleg/conjstraint-knee-test-oute_1.stl" scale="0.001 0.001 0.001"/>
      </geometry>
      <material name="opaque191191191"/>
    </visual>
    <collision>
      <origin xyz="0.243318 0.012178 -0.069894" rpy="0 0 0"/>
      <geometry>
        <mesh filename="package://dropbear_simplified_urdf/meshes/leftleg/conjstraint-knee-test-oute_1.stl" scale="0.001 0.001 0.001"/>
      </geometry>
    </collision>
  </link>
  <link name="LL_knee-strap-second-test_1">
    <inertial>
      <origin xyz="0.02289817601670563 -0.05000799500593258 0.009994439699335583" rpy="0 0 0"/>
      <mass value="0.06382003552060014"/>
      <inertia ixx="9.8e-05" iyy="3.7e-05" izz="0.000101" ixy="3.6e-05" iyz="-2e-06" ixz="1e-06"/>
    </inertial>
    <visual>
      <origin xyz="0.20361 -0.034819 -0.069883" rpy="0 0 0"/>
      <geometry>
        <mesh filename="package://dropbear_simplified_urdf/meshes/leftleg/knee-strap-second-test_1.stl" scale="0.001 0.001 0.001"/>
      </geometry>
      <material name="opaque245245245"/>
    </visual>
    <collision>
      <origin xyz="0.20361 -0.034819 -0.069883" rpy="0 0 0"/>
      <geometry>
        <mesh filename="package://dropbear_simplified_urdf/meshes/leftleg/knee-strap-second-test_1.stl" scale="0.001 0.001 0.001"/>
      </geometry>
    </collision>
  </link>
  <link name="LL_double-bracket-10deg_MIR_MIR_MIR_1">
    <inertial>
      <origin xyz="-0.023030853980666094 -0.20870609984957944 -0.04394857851730673" rpy="0 0 0"/>
      <mass value="0.972328284996074"/>
      <inertia ixx="0.01683" iyy="0.002068" izz="0.017418" ixy="0.001098" iyz="0.002791" ixz="-0.000198"/>
    </inertial>
    <visual>
      <origin xyz="0.157814 0.065197 -0.089871" rpy="0 0 0"/>
      <geometry>
        <mesh filename="package://dropbear_simplified_urdf/meshes/leftleg/double-bracket-10deg_MIR_MIR_MIR_1.stl" scale="0.001 0.001 0.001"/>
      </geometry>
      <material name="opaque245245245"/>
    </visual>
    <collision>
      <origin xyz="0.157814 0.065197 -0.089871" rpy="0 0 0"/>
      <geometry>
        <mesh filename="package://dropbear_simplified_urdf/meshes/leftleg/double-bracket-10deg_MIR_MIR_MIR_1.stl" scale="0.001 0.001 0.001"/>
      </geometry>
    </collision>
  </link>
  <link name="LL_calf-motor-driver-ext_1">
    <inertial>
      <origin xyz="0.01018087483375632 -0.006406414275960254 0.010824350415873277" rpy="0 0 0"/>
      <mass value="0.03904654588774605"/>
      <inertia ixx="7e-06" iyy="1.4e-05" izz="1.8e-05" ixy="4e-06" iyz="-0.0" ixz="1e-06"/>
    </inertial>
    <visual>
      <origin xyz="0.212594 0.236458 -0.073139" rpy="0 0 0"/>
      <geometry>
        <mesh filename="package://dropbear_simplified_urdf/meshes/leftleg/calf-motor-driver-ext_1.stl" scale="0.001 0.001 0.001"/>
      </geometry>
      <material name="opaque2552550"/>
    </visual>
    <collision>
      <origin xyz="0.212594 0.236458 -0.073139" rpy="0 0 0"/>
      <geometry>
        <mesh filename="package://dropbear_simplified_urdf/meshes/leftleg/calf-motor-driver-ext_1.stl" scale="0.001 0.001 0.001"/>
      </geometry>
    </collision>
  </link>
  <link name="LL_290mm-tie-rod_v1_1">
    <inertial>
      <origin xyz="-0.008618850844608478 -0.1441043639671668 -0.01627466914432321" rpy="0 0 0"/>
      <mass value="0.31671295572679664"/>
      <inertia ixx="0.00297" iyy="0.000108" izz="0.002894" ixy="-0.000175" iyz="0.000506" ixz="3.1e-05"/>
    </inertial>
    <visual>
      <origin xyz="0.175826 0.256902 -0.096784" rpy="0 0 0"/>
      <geometry>
        <mesh filename="package://dropbear_simplified_urdf/meshes/leftleg/290mm-tie-rod_v1_1.stl" scale="0.001 0.001 0.001"/>
      </geometry>
      <material name="opaque191191191"/>
    </visual>
    <collision>
      <origin xyz="0.175826 0.256902 -0.096784" rpy="0 0 0"/>
      <geometry>
        <mesh filename="package://dropbear_simplified_urdf/meshes/leftleg/290mm-tie-rod_v1_1.stl" scale="0.001 0.001 0.001"/>
      </geometry>
    </collision>
  </link>
  <link name="LL_calf-motor-driver-ext__1__1">
    <inertial>
      <origin xyz="0.010997941306614883 0.002322003619584123 -0.011641556204172841" rpy="0 0 0"/>
      <mass value="0.03904654588774605"/>
      <inertia ixx="5e-06" iyy="1.6e-05" izz="1.8e-05" ixy="-1e-06" iyz="0.0" ixz="-2e-06"/>
    </inertial>
    <visual>
      <origin xyz="0.210465 0.325998 -0.016729" rpy="0 0 0"/>
      <geometry>
        <mesh filename="package://dropbear_simplified_urdf/meshes/leftleg/calf-motor-driver-ext__1__1.stl" scale="0.001 0.001 0.001"/>
      </geometry>
      <material name="opaque2552550"/>
    </visual>
    <collision>
      <origin xyz="0.210465 0.325998 -0.016729" rpy="0 0 0"/>
      <geometry>
        <mesh filename="package://dropbear_simplified_urdf/meshes/leftleg/calf-motor-driver-ext__1__1.stl" scale="0.001 0.001 0.001"/>
      </geometry>
    </collision>
  </link>
  <link name="LL_210mm-tie-rod_v1_1">
    <inertial>
      <origin xyz="-0.011696719594497779 -0.10121354316624126 -0.026926339548267383" rpy="0 0 0"/>
      <mass value="0.24352587221730845"/>
      <inertia ixx="0.001287" iyy="6.1e-05" izz="0.001267" ixy="-0.000141" iyz="0.000219" ixz="2.5e-05"/>
    </inertial>
    <visual>
      <origin xyz="0.170599 0.320333 0.009872" rpy="0 0 0"/>
      <geometry>
        <mesh filename="package://dropbear_simplified_urdf/meshes/leftleg/210mm-tie-rod_v1_1.stl" scale="0.001 0.001 0.001"/>
      </geometry>
      <material name="opaque191191191"/>
    </visual>
    <collision>
      <origin xyz="0.170599 0.320333 0.009872" rpy="0 0 0"/>
      <geometry>
        <mesh filename="package://dropbear_simplified_urdf/meshes/leftleg/210mm-tie-rod_v1_1.stl" scale="0.001 0.001 0.001"/>
      </geometry>
    </collision>
  </link>
  <link name="LL_basis_left_1">
    <inertial>
      <origin xyz="-0.00029764813988561456 -0.020222597886624838 -0.013552063748571314" rpy="0 0 0"/>
      <mass value="0.09371675054362279"/>
      <inertia ixx="6.4e-05" iyy="3.3e-05" izz="5.6e-05" ixy="-0.0" iyz="4e-06" ixz="0.0"/>
    </inertial>
    <visual>
      <origin xyz="0.146891 0.512935 -0.013949" rpy="0 0 0"/>
      <geometry>
        <mesh filename="package://dropbear_simplified_urdf/meshes/leftleg/basis_left_1.stl" scale="0.001 0.001 0.001"/>
      </geometry>
      <material name="opaque245245245"/>
    </visual>
    <collision>
      <origin xyz="0.146891 0.512935 -0.013949" rpy="0 0 0"/>
      <geometry>
        <mesh filename="package://dropbear_simplified_urdf/meshes/leftleg/basis_left_1.stl" scale="0.001 0.001 0.001"/>
      </geometry>
    </collision>
  </link>
  <link name="LL_heel-bracket_left_1">
    <inertial>
      <origin xyz="0.012688445147171948 -0.00771159949391742 -0.0016067039154728817" rpy="0 0 0"/>
      <mass value="0.7069787408674384"/>
      <inertia ixx="0.000698" iyy="0.005471" izz="0.005014" ixy="0.000121" iyz="-8.5e-05" ixz="-4.2e-05"/>
    </inertial>
    <visual>
      <origin xyz="0.127372 0.550788 0.002967" rpy="0 0 0"/>
      <geometry>
        <mesh filename="package://dropbear_simplified_urdf/meshes/leftleg/heel-bracket_left_1.stl" scale="0.001 0.001 0.001"/>
      </geometry>
      <material name="opaque245245245"/>
    </visual>
    <collision>
      <origin xyz="0.127372 0.550788 0.002967" rpy="0 0 0"/>
      <geometry>
        <mesh filename="package://dropbear_simplified_urdf/meshes/leftleg/heel-bracket_left_1.stl" scale="0.001 0.001 0.001"/>
      </geometry>
    </collision>
  </link>
  <joint name="LL_leg_connection" type="fixed">
    <origin xyz="0.0 0.0 0.0" rpy="-0.17453294444444445 0 0"/>
    <parent link="DumLeftLeg_1"/>
    <child link="LL_RMD-X10-S2_MIR4__3_Rotor_1"/>
  </joint>
  <joint name="LL_hipjoint" type="revolute">
    <origin xyz="0.0 0.0 -0.0" rpy="0 0 0"/>
    <parent link="LL_RMD-X10-S2_MIR4__3_Rotor_1"/>
    <child link="LL_RMD-X10-S2_MIR4__3_Stator_1"/>
    <axis xyz="0.000261 -0.0 -1.0"/>
    <limit upper="1.5707965" lower="-1.5707965" velocity="10.0" effort="10.0"/>
  </joint>
  <joint name="LL_kneejoint" type="revolute">
    <origin xyz="-0.071726 -0.0987 -0.063481" rpy="0 0 0"/>
    <parent link="LL_RMD-X10-S2_MIR4__3_Stator_1"/>
    <child link="LL_RMD-X10-S2_MIR4Rotor_1"/>
    <axis xyz="-0.000261 0.0 1.0"/>
    <limit upper="0.78539825" lower="-0.78539825" velocity="10.0" effort="10.0"/>
  </joint>
  <joint name="LL_Revolute 4" type="continuous">
    <mimic joint="LL_kneejoint" multiplier="0.9062"/>
    <origin xyz="0.050251 -0.016453 -0.080013" rpy="0 0 0"/>
    <parent link="LL_RMD-X10-S2_MIR4__3_Stator_1"/>
    <child link="LL_double-bracket_1"/>
    <axis xyz="-0.000261 0.0 1.0"/>
  </joint>
  <joint name="LL_Revolute 5" type="continuous">
    <mimic joint="LL_kneejoint" multiplier="-1.258"/>
    <origin xyz="0.019961 -0.294323 -0.036505" rpy="0 0 0"/>
    <parent link="LL_RMD-X10-S2_MIR4Rotor_1"/>
    <child link="LL_conjstraint-knee-test-oute_1"/>
    <axis xyz="-0.000261 0.0 1.0"/>
  </joint>
  <joint name="LL_Revolute 7" type="continuous">
    <mimic joint="LL_kneejoint" multiplier="-1.5277"/>
    <origin xyz="-0.062308 -0.329573 -0.019984" rpy="0 0 0"/>
    <parent link="LL_double-bracket_1"/>
    <child link="LL_knee-strap-second-test_1"/>
    <axis xyz="-0.000261 0.0 1.0"/>
  </joint>
  <joint name="LL_Revolute 8" type="continuous">
    <mimic joint="LL_kneejoint" multiplier="-1.0405"/>
    <origin xyz="0.045796 -0.100016 0.019988" rpy="0 0 0"/>
    <parent link="LL_knee-strap-second-test_1"/>
    <child link="LL_double-bracket-10deg_MIR_MIR_MIR_1"/>
    <axis xyz="-0.000261 0.0 1.0"/>
  </joint>
  <joint name="LL_Revolute 10" type="continuous">
    <origin xyz="-0.05478 -0.171261 -0.016732" rpy="0 0 0"/>
    <parent link="LL_double-bracket-10deg_MIR_MIR_MIR_1"/>
    <child link="LL_calf-motor-driver-ext_1"/>
    <axis xyz="0.004499 -0.173596 -0.984807"/>
  </joint>
  <joint name="LL_Revolute 11" type="continuous">
    <mimic joint="LL_Revolute 10" multiplier="-1.1418"/>
    <origin xyz="0.036768 -0.020444 0.023645" rpy="0 0 0"/>
    <parent link="LL_calf-motor-driver-ext_1"/>
    <child link="LL_290mm-tie-rod_v1_1"/>
    <axis xyz="0.004499 -0.173596 -0.984807"/>
  </joint>
  <joint name="LL_Revolute 12" type="continuous">
    <mimic joint="LL_Revolute 10" multiplier="-0.8322"/>
    <origin xyz="-0.052651 -0.260801 -0.073142" rpy="0 0 0"/>
    <parent link="LL_double-bracket-10deg_MIR_MIR_MIR_1"/>
    <child link="LL_calf-motor-driver-ext__1__1"/>
    <axis xyz="-0.004499 0.173596 0.984807"/>
  </joint>
  <joint name="LL_Revolute 13" type="continuous">
    <mimic joint="LL_Revolute 10" multiplier="0.9436"/>
    <origin xyz="0.039866 0.005665 -0.026601" rpy="0 0 0"/>
    <parent link="LL_calf-motor-driver-ext__1__1"/>
    <child link="LL_210mm-tie-rod_v1_1"/>
    <axis xyz="-0.004499 0.173596 0.984807"/>
  </joint>
  <joint name="LL_Revolute 14" type="continuous">
    <mimic joint="LL_Revolute 10" multiplier="-0.7843"/>
    <origin xyz="0.010923 -0.447738 -0.075922" rpy="0 0 0"/>
    <parent link="LL_double-bracket-10deg_MIR_MIR_MIR_1"/>
    <child link="LL_basis_left_1"/>
    <axis xyz="0.004499 -0.173596 -0.984807"/>
  </joint>
  <joint name="LL_Revolute 15" type="continuous">
    <origin xyz="0.019519 -0.037853 -0.016916" rpy="0 0 0"/>
    <parent link="LL_basis_left_1"/>
    <child link="LL_heel-bracket_left_1"/>
    <axis xyz="0.999931 -0.00994 0.006321"/>
  </joint>
</robot>
